Workbook

Sheet board
A1: name | B1: position | C1: school | D1: Grade | E1: age | F1: height (in) | G1: wingspan (in) | H1: reach (in) | I1: Ape | J1: me | K1: grade | L1: link | M1: espn | N1: Dean | O1: zamir | P1: birthday | Q1: height | R1: wingspan | S1: reach
A2: Zion Williamson | B2: PF | C2: Duke | D2: Freshman | E2: =YEARFRAC(P2, TODAY(), 1) -> 18.951403 | F2: =IFERROR(LEFT(Q2,FIND("'",Q2)-1)*12+SUBSTITUTE(MID(Q2,FIND("'",Q2)+1,LEN(Q2)),"''",""), "") | G2: =IFERROR(LEFT(R2,FIND("'",R2)-1)*12+SUBSTITUTE(MID(R2,FIND("'",R2)+1,LEN(R2)),"''",""), "") | H2: =IFERROR(LEFT(S2,FIND("'",S2)-1)*12+SUBSTITUTE(MID(S2,FIND("'",S2)+1,LEN(S2)),"''",""), "") | I2: =IFERROR(IF(G2-F2>= 0, "+" & G2-F2, ""),"") | J2: 1 | K2: 65 | L2: https://www.sports-reference.com/cbb/players/zion-williamson-1.html | M2: 1 | N2: 1 | O2: 1 | P2: 36713 | Q2: =IFERROR(INDEX('nba.com measureables'!$A:$J,MATCH($A2,'nba.com measureables'!$A:$A,FALSE),7), "") -> 0 | R2: =IFERROR(INDEX('nba.com measureables'!$A:$J,MATCH($A2,'nba.com measureables'!$A:$A,FALSE),10), "") -> 0 | S2: =IFERROR(INDEX('nba.com measureables'!$A:$J,MATCH($A2,'nba.com measureables'!$A:$A,FALSE),8), "") -> 0 | T2: =" <li><b><a target='_blank' href='" & L2 & "'>" & A2 & "</a></b> - <i>" & B2 & " - " & C2 & "</i></li> <ul style='list-style-type:none'>" & IF(D2 <> "", " <li>Grade: " & D2 & " </li>", "") & IF(E2 <> "", " <li>Age: " & ROUND(E2,2) & " </li>", "") & IF(F2 <> "", " <li>Height: " & F2 & " </li>", "") & IF(G2 <> "", " <li>Wingspan: " & G2 & " </li>", "") & IF(H2 <> "", " <li>Reach: " & H2 & " </li>", "") & IF(I2 <> "", " <li>Ape: " & I2 & " </li>", "") & " </ul> <br>" -> <li><b><a _x000D_ target='_blank' _x000D_ href='https://www.sports-reference.com/cbb/players/zion-williamson-1.html'>Zion Williamson</a></b> - <i>PF - Duke</i></li>_x000D_ <ul style='list-style-type:none'>_x000D_ <li>Grade: Freshman </li>_x000D_ <li>Age: 18.95 </li>_x000D_ </ul>_x000D_<br>
A3: Ja Morant | B3: PG | C3: Murray State | D3: Sophomore | E3: =YEARFRAC(P3, TODAY(), 1) -> 19.858279 | F3: =IFERROR(LEFT(Q3,FIND("'",Q3)-1)*12+SUBSTITUTE(MID(Q3,FIND("'",Q3)+1,LEN(Q3)),"''",""), "") | G3: =IFERROR(LEFT(R3,FIND("'",R3)-1)*12+SUBSTITUTE(MID(R3,FIND("'",R3)+1,LEN(R3)),"''",""), "") | H3: =IFERROR(LEFT(S3,FIND("'",S3)-1)*12+SUBSTITUTE(MID(S3,FIND("'",S3)+1,LEN(S3)),"''",""), "") | I3: =IFERROR(IF(G3-F3>= 0, "+" & G3-F3, ""),"") | J3: 2 | K3: 60 | L3: https://www.sports-reference.com/cbb/players/temetrius-morant-1.html | M3: 2 | N3: 2 | O3: 5 | P3: 36382 | Q3: =IFERROR(INDEX('nba.com measureables'!$A:$J,MATCH($A3,'nba.com measureables'!$A:$A,FALSE),7), "") -> 0 | R3: =IFERROR(INDEX('nba.com measureables'!$A:$J,MATCH($A3,'nba.com measureables'!$A:$A,FALSE),10), "") -> 0 | S3: =IFERROR(INDEX('nba.com measureables'!$A:$J,MATCH($A3,'nba.com measureables'!$A:$A,FALSE),8), "") -> 0 | T3: =" <li><b><a target='_blank' href='" & L3 & "'>" & A3 & "</a></b> - <i>" & B3 & " - " & C3 & "</i></li> <ul style='list-style-type:none'>" & IF(D3 <> "", " <li>Grade: " & D3 & " </li>", "") & IF(E3 <> "", " <li>Age: " & ROUND(E3,2) & " </li>", "") & IF(F3 <> "", " <li>Height: " & F3 & " </li>", "") & IF(G3 <> "", " <li>Wingspan: " & G3 & " </li>", "") & IF(H3 <> "", " <li>Reach: " & H3 & " </li>", "") & IF(I3 <> "", " <li>Ape: " & I3 & " </li>", "") & " </ul> <br>" -> <li><b><a _x000D_ target='_blank' _x000D_ href='https://www.sports-reference.com/cbb/players/temetrius-morant-1.html'>Ja Morant</a></b> - <i>PG - Murray State</i></li>_x000D_ <ul style='list-style-type:none'>_x000D_ <li>Grade: Sophomore </li>_x000D_ <li>Age: 19.86 </li>_x000D_ </ul>_x000D_<br>
A4: RJ Barrett | B4: SG | C4: Duke | D4: Freshman | E4: =YEARFRAC(P4, TODAY(), 1) -> 19.011636 | F4: =IFERROR(LEFT(Q4,FIND("'",Q4)-1)*12+SUBSTITUTE(MID(Q4,FIND("'",Q4)+1,LEN(Q4)),"''",""), "") | G4: =IFERROR(LEFT(R4,FIND("'",R4)-1)*12+SUBSTITUTE(MID(R4,FIND("'",R4)+1,LEN(R4)),"''",""), "") | H4: =IFERROR(LEFT(S4,FIND("'",S4)-1)*12+SUBSTITUTE(MID(S4,FIND("'",S4)+1,LEN(S4)),"''",""), "") | I4: =IFERROR(IF(G4-F4>= 0, "+" & G4-F4, ""),"") | J4: 3 | K4: 60 | L4: https://www.sports-reference.com/cbb/players/rj-barrett-1.html | M4: 3 | N4: 3 | O4: 2 | P4: 36691 | Q4: =IFERROR(INDEX('nba.com measureables'!$A:$J,MATCH($A4,'nba.com measureables'!$A:$A,FALSE),7), "") -> 0 | R4: =IFERROR(INDEX('nba.com measureables'!$A:$J,MATCH($A4,'nba.com measureables'!$A:$A,FALSE),10), "") -> 0 | S4: =IFERROR(INDEX('nba.com measureables'!$A:$J,MATCH($A4,'nba.com measureables'!$A:$A,FALSE),8), "") -> 0 | T4: =" <li><b><a target='_blank' href='" & L4 & "'>" & A4 & "</a></b> - <i>" & B4 & " - " & C4 & "</i></li> <ul style='list-style-type:none'>" & IF(D4 <> "", " <li>Grade: " & D4 & " </li>", "") & IF(E4 <> "", " <li>Age: " & ROUND(E4,2) & " </li>", "") & IF(F4 <> "", " <li>Height: " & F4 & " </li>", "") & IF(G4 <> "", " <li>Wingspan: " & G4 & " </li>", "") & IF(H4 <> "", " <li>Reach: " & H4 & " </li>", "") & IF(I4 <> "", " <li>Ape: " & I4 & " </li>", "") & " </ul> <br>" -> <li><b><a _x000D_ target='_blank' _x000D_ href='https://www.sports-reference.com/cbb/players/rj-barrett-1.html'>RJ Barrett</a></b> - <i>SG - Duke</i></li>_x000D_ <ul style='list-style-type:none'>_x000D_ <li>Grade: Freshman </li>_x000D_ <li>Age: 19.01 </li>_x000D_ </ul>_x000D_<br>
A5: Jaxson Hayes | B5: C | C5: Texas | D5: Freshman | E5: =YEARFRAC(P5, TODAY(), 1) -> 19.071869 | F5: =IFERROR(LEFT(Q5,FIND("'",Q5)-1)*12+SUBSTITUTE(MID(Q5,FIND("'",Q5)+1,LEN(Q5)),"''",""), "") -> 83.5 | G5: =IFERROR(LEFT(R5,FIND("'",R5)-1)*12+SUBSTITUTE(MID(R5,FIND("'",R5)+1,LEN(R5)),"''",""), "") -> 87.5 | H5: =IFERROR(LEFT(S5,FIND("'",S5)-1)*12+SUBSTITUTE(MID(S5,FIND("'",S5)+1,LEN(S5)),"''",""), "") -> 110.5 | I5: =IFERROR(IF(G5-F5>= 0, "+" & G5-F5, ""),"") -> +4 | J5: 4 | K5: 55 | L5: https://www.sports-reference.com/cbb/players/jaxson-hayes-1.html | M5: 11 | N5: 7 | O5: 10 | P5: 36669 | Q5: =IFERROR(INDEX('nba.com measureables'!$A:$J,MATCH($A5,'nba.com measureables'!$A:$A,FALSE),7), "") -> 6' 11.5'' | R5: =IFERROR(INDEX('nba.com measureables'!$A:$J,MATCH($A5,'nba.com measureables'!$A:$A,FALSE),10), "") -> 7' 3.5'' | S5: =IFERROR(INDEX('nba.com measureables'!$A:$J,MATCH($A5,'nba.com measureables'!$A:$A,FALSE),8), "") -> 9' 2.5'' | T5: =" <li><b><a target='_blank' href='" & L5 & "'>" & A5 & "</a></b> - <i>" & B5 & " - " & C5 & "</i></li> <ul style='list-style-type:none'>" & IF(D5 <> "", " <li>Grade: " & D5 & " </li>", "") & IF(E5 <> "", " <li>Age: " & ROUND(E5,2) & " </li>", "") & IF(F5 <> "", " <li>Height: " & F5 & " </li>", "") & IF(G5 <> "", " <li>Wingspan: " & G5 & " </li>", "") & IF(H5 <> "", " <li>Reach: " & H5 & " </li>", "") & IF(I5 <> "", " <li>Ape: " & I5 & " </li>", "") & " </ul> <br>" -> <li><b><a _x000D_ target='_blank' _x000D_ href='https://www.sports-reference.com/cbb/players/jaxson-hayes-1.html'>Jaxson Hayes</a></b> - <i>C - Texas</i></li>_x000D_ <ul style='list-style-type:none'>_x000D_ <li>Grade: Freshman </li>_x000D_ <li>Age: 19.07 </li>_x000D_ <li>Height: 83.5 </li>_x000D_ <li>Wingspan: 87.5 </li>_x000D_ <li>Reach: 110.5 </li>_x000D_ <li>Ape: +4 </li>_x000D_ </ul>_x000D_<br>
A6: Jarrett Culver | B6: SG | C6: Texas Tech | D6: Sophomore | E6: =YEARFRAC(P6, TODAY(), 1) -> 20.326467 | F6: =IFERROR(LEFT(Q6,FIND("'",Q6)-1)*12+SUBSTITUTE(MID(Q6,FIND("'",Q6)+1,LEN(Q6)),"''",""), "") -> 78.75 | G6: =IFERROR(LEFT(R6,FIND("'",R6)-1)*12+SUBSTITUTE(MID(R6,FIND("'",R6)+1,LEN(R6)),"''",""), "") -> 81.5 | H6: =IFERROR(LEFT(S6,FIND("'",S6)-1)*12+SUBSTITUTE(MID(S6,FIND("'",S6)+1,LEN(S6)),"''",""), "") -> 100.5 | I6: =IFERROR(IF(G6-F6>= 0, "+" & G6-F6, ""),"") -> +2.75 | J6: 5 | K6: 55 | L6: https://www.sports-reference.com/cbb/players/jarrett-culver-1.html | M6: 6 | N6: 5 | O6: 3 | P6: 36211 | Q6: =IFERROR(INDEX('nba.com measureables'!$A:$J,MATCH($A6,'nba.com measureables'!$A:$A,FALSE),7), "") -> 6' 6.75'' | R6: =IFERROR(INDEX('nba.com measureables'!$A:$J,MATCH($A6,'nba.com measureables'!$A:$A,FALSE),10), "") -> 6' 9.5'' | S6: =IFERROR(INDEX('nba.com measureables'!$A:$J,MATCH($A6,'nba.com measureables'!$A:$A,FALSE),8), "") -> 8' 4.5'' | T6: =" <li><b><a target='_blank' href='" & L6 & "'>" & A6 & "</a></b> - <i>" & B6 & " - " & C6 & "</i></li> <ul style='list-style-type:none'>" & IF(D6 <> "", " <li>Grade: " & D6 & " </li>", "") & IF(E6 <> "", " <li>Age: " & ROUND(E6,2) & " </li>", "") & IF(F6 <> "", " <li>Height: " & F6 & " </li>", "") & IF(G6 <> "", " <li>Wingspan: " & G6 & " </li>", "") & IF(H6 <> "", " <li>Reach: " & H6 & " </li>", "") & IF(I6 <> "", " <li>Ape: " & I6 & " </li>", "") & " </ul> <br>" -> <li><b><a _x000D_ target='_blank' _x000D_ href='https://www.sports-reference.com/cbb/players/jarrett-culver-1.html'>Jarrett Culver</a></b> - <i>SG - Texas Tech</i></li>_x000D_ <ul style='list-style-type:none'>_x000D_ <li>Grade: Sophomore </li>_x000D_ <li>Age: 20.33 </li>_x000D_ <li>Height: 78.75 </li>_x000D_ <li>Wingspan: 81.5 </li>_x000D_ <li>Reach: 100.5 </li>_x000D_ <li>Ape: +2.75 </li>_x000D_ </ul>_x000D_<br>
A7: Talen Horton-Tucker | B7: SF | C7: Iowa State | D7: Freshman | E7: =YEARFRAC(P7, TODAY(), 1) -> 18.562628 | F7: =IFERROR(LEFT(Q7,FIND("'",Q7)-1)*12+SUBSTITUTE(MID(Q7,FIND("'",Q7)+1,LEN(Q7)),"''",""), "") -> 76 | G7: =IFERROR(LEFT(R7,FIND("'",R7)-1)*12+SUBSTITUTE(MID(R7,FIND("'",R7)+1,LEN(R7)),"''",""), "") -> 85.25 | H7: =IFERROR(LEFT(S7,FIND("'",S7)-1)*12+SUBSTITUTE(MID(S7,FIND("'",S7)+1,LEN(S7)),"''",""), "") -> 103 | I7: =IFERROR(IF(G7-F7>= 0, "+" & G7-F7, ""),"") -> +9.25 | J7: 6 | K7: 55 | L7: https://www.sports-reference.com/cbb/players/talen-horton-tucker-1.html | M7: 34 | N7: 9 | P7: 36855 | Q7: =IFERROR(INDEX('nba.com measureables'!$A:$J,MATCH($A7,'nba.com measureables'!$A:$A,FALSE),7), "") -> 6' 4'' | R7: =IFERROR(INDEX('nba.com measureables'!$A:$J,MATCH($A7,'nba.com measureables'!$A:$A,FALSE),10), "") -> 7' 1.25'' | S7: =IFERROR(INDEX('nba.com measureables'!$A:$J,MATCH($A7,'nba.com measureables'!$A:$A,FALSE),8), "") -> 8' 7'' | T7: =" <li><b><a target='_blank' href='" & L7 & "'>" & A7 & "</a></b> - <i>" & B7 & " - " & C7 & "</i></li> <ul style='list-style-type:none'>" & IF(D7 <> "", " <li>Grade: " & D7 & " </li>", "") & IF(E7 <> "", " <li>Age: " & ROUND(E7,2) & " </li>", "") & IF(F7 <> "", " <li>Height: " & F7 & " </li>", "") & IF(G7 <> "", " <li>Wingspan: " & G7 & " </li>", "") & IF(H7 <> "", " <li>Reach: " & H7 & " </li>", "") & IF(I7 <> "", " <li>Ape: " & I7 & " </li>", "") & " </ul> <br>" -> <li><b><a _x000D_ target='_blank' _x000D_ href='https://www.sports-reference.com/cbb/players/talen-horton-tucker-1.html'>Talen Horton-Tucker</a></b> - <i>SF - Iowa State</i></li>_x000D_ <ul style='list-style-type:none'>_x000D_ <li>Grade: Freshman </li>_x000D_ <li>Age: 18.56 </li>_x000D_ <li>Height: 76 </li>_x000D_ <li>Wingspan: 85.25 </li>_x000D_ <li>Reach: 103 </li>_x000D_ <li>Ape: +9.25 </li>_x000D_ </ul>_x000D_<br>
A8: Darius Garland | B8: PG | C8: Vanderbilt | D8: Freshman | E8: =YEARFRAC(P8, TODAY(), 1) -> 19.394935 | F8: =IFERROR(LEFT(Q8,FIND("'",Q8)-1)*12+SUBSTITUTE(MID(Q8,FIND("'",Q8)+1,LEN(Q8)),"''",""), "") | G8: =IFERROR(LEFT(R8,FIND("'",R8)-1)*12+SUBSTITUTE(MID(R8,FIND("'",R8)+1,LEN(R8)),"''",""), "") | H8: =IFERROR(LEFT(S8,FIND("'",S8)-1)*12+SUBSTITUTE(MID(S8,FIND("'",S8)+1,LEN(S8)),"''",""), "") | I8: =IFERROR(IF(G8-F8>= 0, "+" & G8-F8, ""),"") | J8: 7 | K8: 55 | L8: https://www.sports-reference.com/cbb/players/darius-garland-1.html | M8: 4 | N8: 19 | O8: 4 | P8: 36551 | Q8: =IFERROR(INDEX('nba.com measureables'!$A:$J,MATCH($A8,'nba.com measureables'!$A:$A,FALSE),7), "") -> 0 | R8: =IFERROR(INDEX('nba.com measureables'!$A:$J,MATCH($A8,'nba.com measureables'!$A:$A,FALSE),10), "") -> 0 | S8: =IFERROR(INDEX('nba.com measureables'!$A:$J,MATCH($A8,'nba.com measureables'!$A:$A,FALSE),8), "") -> 0 | T8: =" <li><b><a target='_blank' href='" & L8 & "'>" & A8 & "</a></b> - <i>" & B8 & " - " & C8 & "</i></li> <ul style='list-style-type:none'>" & IF(D8 <> "", " <li>Grade: " & D8 & " </li>", "") & IF(E8 <> "", " <li>Age: " & ROUND(E8,2) & " </li>", "") & IF(F8 <> "", " <li>Height: " & F8 & " </li>", "") & IF(G8 <> "", " <li>Wingspan: " & G8 & " </li>", "") & IF(H8 <> "", " <li>Reach: " & H8 & " </li>", "") & IF(I8 <> "", " <li>Ape: " & I8 & " </li>", "") & " </ul> <br>" -> <li><b><a _x000D_ target='_blank' _x000D_ href='https://www.sports-reference.com/cbb/players/darius-garland-1.html'>Darius Garland</a></b> - <i>PG - Vanderbilt</i></li>_x000D_ <ul style='list-style-type:none'>_x000D_ <li>Grade: Freshman </li>_x000D_ <li>Age: 19.39 </li>_x000D_ </ul>_x000D_<br>
A9: PJ Washington | B9: PF | C9: Kentucky | D9: Sophomore | E9: =YEARFRAC(P9, TODAY(), 1) -> 20.822651 | F9: =IFERROR(LEFT(Q9,FIND("'",Q9)-1)*12+SUBSTITUTE(MID(Q9,FIND("'",Q9)+1,LEN(Q9)),"''",""), "") -> 80 | G9: =IFERROR(LEFT(R9,FIND("'",R9)-1)*12+SUBSTITUTE(MID(R9,FIND("'",R9)+1,LEN(R9)),"''",""), "") -> 86.25 | H9: =IFERROR(LEFT(S9,FIND("'",S9)-1)*12+SUBSTITUTE(MID(S9,FIND("'",S9)+1,LEN(S9)),"''",""), "") -> 106.5 | I9: =IFERROR(IF(G9-F9>= 0, "+" & G9-F9, ""),"") -> +6.25 | J9: 8 | K9: 55 | L9: https://www.sports-reference.com/cbb/players/pj-washington-1.html | M9: 16 | N9: 4 | P9: 36030 | Q9: =IFERROR(INDEX('nba.com measureables'!$A:$J,MATCH($A9,'nba.com measureables'!$A:$A,FALSE),7), "") -> 6' 8'' | R9: =IFERROR(INDEX('nba.com measureables'!$A:$J,MATCH($A9,'nba.com measureables'!$A:$A,FALSE),10), "") -> 7' 2.25'' | S9: =IFERROR(INDEX('nba.com measureables'!$A:$J,MATCH($A9,'nba.com measureables'!$A:$A,FALSE),8), "") -> 8' 10.5'' | T9: =" <li><b><a target='_blank' href='" & L9 & "'>" & A9 & "</a></b> - <i>" & B9 & " - " & C9 & "</i></li> <ul style='list-style-type:none'>" & IF(D9 <> "", " <li>Grade: " & D9 & " </li>", "") & IF(E9 <> "", " <li>Age: " & ROUND(E9,2) & " </li>", "") & IF(F9 <> "", " <li>Height: " & F9 & " </li>", "") & IF(G9 <> "", " <li>Wingspan: " & G9 & " </li>", "") & IF(H9 <> "", " <li>Reach: " & H9 & " </li>", "") & IF(I9 <> "", " <li>Ape: " & I9 & " </li>", "") & " </ul> <br>" -> <li><b><a _x000D_ target='_blank' _x000D_ href='https://www.sports-reference.com/cbb/players/pj-washington-1.html'>PJ Washington</a></b> - <i>PF - Kentucky</i></li>_x000D_ <ul style='list-style-type:none'>_x000D_ <li>Grade: Sophomore </li>_x000D_ <li>Age: 20.82 </li>_x000D_ <li>Height: 80 </li>_x000D_ <li>Wingspan: 86.25 </li>_x000D_ <li>Reach: 106.5 </li>_x000D_ <li>Ape: +6.25 </li>_x000D_ </ul>_x000D_<br>
A10: Jontay Porter | B10: C | C10: Missouri | D10: Sophomore | E10: =YEARFRAC(P10, TODAY(), 1) -> 19.592699 | F10: =IFERROR(LEFT(Q10,FIND("'",Q10)-1)*12+SUBSTITUTE(MID(Q10,FIND("'",Q10)+1,LEN(Q10)),"''",""), "") -> 83 | G10: =IFERROR(LEFT(R10,FIND("'",R10)-1)*12+SUBSTITUTE(MID(R10,FIND("'",R10)+1,LEN(R10)),"''",""), "") -> 84 | H10: =IFERROR(LEFT(S10,FIND("'",S10)-1)*12+SUBSTITUTE(MID(S10,FIND("'",S10)+1,LEN(S10)),"''",""), "") -> 109.5 | I10: =IFERROR(IF(G10-F10>= 0, "+" & G10-F10, ""),"") -> +1 | J10: 9 | K10: 50 | L10: https://www.sports-reference.com/cbb/players/jontay-porter-1.html | M10: 42 | N10: 15 | O10: 6 | P10: 36479 | Q10: =IFERROR(INDEX('nba.com measureables'!$A:$J,MATCH($A10,'nba.com measureables'!$A:$A,FALSE),7), "") -> 6' 11'' | R10: =IFERROR(INDEX('nba.com measureables'!$A:$J,MATCH($A10,'nba.com measureables'!$A:$A,FALSE),10), "") -> 7' 0'' | S10: =IFERROR(INDEX('nba.com measureables'!$A:$J,MATCH($A10,'nba.com measureables'!$A:$A,FALSE),8), "") -> 9' 1.5'' | T10: =" <li><b><a target='_blank' href='" & L10 & "'>" & A10 & "</a></b> - <i>" & B10 & " - " & C10 & "</i></li> <ul style='list-style-type:none'>" & IF(D10 <> "", " <li>Grade: " & D10 & " </li>", "") & IF(E10 <> "", " <li>Age: " & ROUND(E10,2) & " </li>", "") & IF(F10 <> "", " <li>Height: " & F10 & " </li>", "") & IF(G10 <> "", " <li>Wingspan: " & G10 & " </li>", "") & IF(H10 <> "", " <li>Reach: " & H10 & " </li>", "") & IF(I10 <> "", " <li>Ape: " & I10 & " </li>", "") & " </ul> <br>" -> <li><b><a _x000D_ target='_blank' _x000D_ href='https://www.sports-reference.com/cbb/players/jontay-porter-1.html'>Jontay Porter</a></b> - <i>C - Missouri</i></li>_x000D_ <ul style='list-style-type:none'>_x000D_ <li>Grade: Sophomore </li>_x000D_ <li>Age: 19.59 </li>_x000D_ <li>Height: 83 </li>_x000D_ <li>Wingspan: 84 </li>_x000D_ <li>Reach: 109.5 </li>_x000D_ <li>Ape: +1 </li>_x000D_ </ul>_x000D_<br>
A11: Grant Williams | B11: PF | C11: Tennessee | D11: Junior | E11: =YEARFRAC(P11, TODAY(), 1) -> 20.551587 | F11: =IFERROR(LEFT(Q11,FIND("'",Q11)-1)*12+SUBSTITUTE(MID(Q11,FIND("'",Q11)+1,LEN(Q11)),"''",""), "") -> 79.5 | G11: =IFERROR(LEFT(R11,FIND("'",R11)-1)*12+SUBSTITUTE(MID(R11,FIND("'",R11)+1,LEN(R11)),"''",""), "") -> 81.75 | H11: =IFERROR(LEFT(S11,FIND("'",S11)-1)*12+SUBSTITUTE(MID(S11,FIND("'",S11)+1,LEN(S11)),"''",""), "") -> 104.5 | I11: =IFERROR(IF(G11-F11>= 0, "+" & G11-F11, ""),"") -> +2.25 | J11: 10 | K11: 50 | L11: https://www.sports-reference.com/cbb/players/grant-williams-1.html | M11: 27 | N11: 12 | O11: 7 | P11: 36129 | Q11: =IFERROR(INDEX('nba.com measureables'!$A:$J,MATCH($A11,'nba.com measureables'!$A:$A,FALSE),7), "") -> 6' 7.5'' | R11: =IFERROR(INDEX('nba.com measureables'!$A:$J,MATCH($A11,'nba.com measureables'!$A:$A,FALSE),10), "") -> 6' 9.75'' | S11: =IFERROR(INDEX('nba.com measureables'!$A:$J,MATCH($A11,'nba.com measureables'!$A:$A,FALSE),8), "") -> 8' 8.5'' | T11: =" <li><b><a target='_blank' href='" & L11 & "'>" & A11 & "</a></b> - <i>" & B11 & " - " & C11 & "</i></li> <ul style='list-style-type:none'>" & IF(D11 <> "", " <li>Grade: " & D11 & " </li>", "") & IF(E11 <> "", " <li>Age: " & ROUND(E11,2) & " </li>", "") & IF(F11 <> "", " <li>Height: " & F11 & " </li>", "") & IF(G11 <> "", " <li>Wingspan: " & G11 & " </li>", "") & IF(H11 <> "", " <li>Reach: " & H11 & " </li>", "") & IF(I11 <> "", " <li>Ape: " & I11 & " </li>", "") & " </ul> <br>" -> <li><b><a _x000D_ target='_blank' _x000D_ href='https://www.sports-reference.com/cbb/players/grant-williams-1.html'>Grant Williams</a></b> - <i>PF - Tennessee</i></li>_x000D_ <ul style='list-style-type:none'>_x000D_ <li>Grade: Junior </li>_x000D_ <li>Age: 20.55 </li>_x000D_ <li>Height: 79.5 </li>_x000D_ <li>Wingspan: 81.75 </li>_x000D_ <li>Reach: 104.5 </li>_x000D_ <li>Ape: +2.25 </li>_x000D_ </ul>_x000D_<br>
A12: Cam Reddish | B12: SF | C12: Duke | D12: Freshman | E12: =YEARFRAC(P12, TODAY(), 1) -> 19.798044 | F12: =IFERROR(LEFT(Q12,FIND("'",Q12)-1)*12+SUBSTITUTE(MID(Q12,FIND("'",Q12)+1,LEN(Q12)),"''",""), "") -> 80 | G12: =IFERROR(LEFT(R12,FIND("'",R12)-1)*12+SUBSTITUTE(MID(R12,FIND("'",R12)+1,LEN(R12)),"''",""), "") -> 84.5 | H12: =IFERROR(LEFT(S12,FIND("'",S12)-1)*12+SUBSTITUTE(MID(S12,FIND("'",S12)+1,LEN(S12)),"''",""), "") -> 105.5 | I12: =IFERROR(IF(G12-F12>= 0, "+" & G12-F12, ""),"") -> +4.5 | J12: 11 | K12: 50 | L12: https://www.sports-reference.com/cbb/players/cam-reddish-1.html | M12: 7 | N12: 6 | P12: 36404 | Q12: =IFERROR(INDEX('nba.com measureables'!$A:$J,MATCH($A12,'nba.com measureables'!$A:$A,FALSE),7), "") -> 6' 8'' | R12: =IFERROR(INDEX('nba.com measureables'!$A:$J,MATCH($A12,'nba.com measureables'!$A:$A,FALSE),10), "") -> 7' 0.5'' | S12: =IFERROR(INDEX('nba.com measureables'!$A:$J,MATCH($A12,'nba.com measureables'!$A:$A,FALSE),8), "") -> 8' 9.5'' | T12: =" <li><b><a target='_blank' href='" & L12 & "'>" & A12 & "</a></b> - <i>" & B12 & " - " & C12 & "</i></li> <ul style='list-style-type:none'>" & IF(D12 <> "", " <li>Grade: " & D12 & " </li>", "") & IF(E12 <> "", " <li>Age: " & ROUND(E12,2) & " </li>", "") & IF(F12 <> "", " <li>Height: " & F12 & " </li>", "") & IF(G12 <> "", " <li>Wingspan: " & G12 & " </li>", "") & IF(H12 <> "", " <li>Reach: " & H12 & " </li>", "") & IF(I12 <> "", " <li>Ape: " & I12 & " </li>", "") & " </ul> <br>" -> <li><b><a _x000D_ target='_blank' _x000D_ href='https://www.sports-reference.com/cbb/players/cam-reddish-1.html'>Cam Reddish</a></b> - <i>SF - Duke</i></li>_x000D_ <ul style='list-style-type:none'>_x000D_ <li>Grade: Freshman </li>_x000D_ <li>Age: 19.8 </li>_x000D_ <li>Height: 80 </li>_x000D_ <li>Wingspan: 84.5 </li>_x000D_ <li>Reach: 105.5 </li>_x000D_ <li>Ape: +4.5 </li>_x000D_ </ul>_x000D_<br>
A13: Nicolas Claxton | B13: C | C13: Georgia | D13: Sophomore | E13: =YEARFRAC(P13, TODAY(), 1) -> 20.173142 | F13: =IFERROR(LEFT(Q13,FIND("'",Q13)-1)*12+SUBSTITUTE(MID(Q13,FIND("'",Q13)+1,LEN(Q13)),"''",""), "") -> 83.75 | G13: =IFERROR(LEFT(R13,FIND("'",R13)-1)*12+SUBSTITUTE(MID(R13,FIND("'",R13)+1,LEN(R13)),"''",""), "") -> 86.5 | H13: =IFERROR(LEFT(S13,FIND("'",S13)-1)*12+SUBSTITUTE(MID(S13,FIND("'",S13)+1,LEN(S13)),"''",""), "") -> 110 | I13: =IFERROR(IF(G13-F13>= 0, "+" & G13-F13, ""),"") -> +2.75 | J13: 12 | K13: 50 | L13: https://www.sports-reference.com/cbb/players/nicolas-claxton-1.html | M13: 30 | N13: 13 | O13: 11 | P13: 36267 | Q13: =IFERROR(INDEX('nba.com measureables'!$A:$J,MATCH($A13,'nba.com measureables'!$A:$A,FALSE),7), "") -> 6' 11.75'' | R13: =IFERROR(INDEX('nba.com measureables'!$A:$J,MATCH($A13,'nba.com measureables'!$A:$A,FALSE),10), "") -> 7' 2.5'' | S13: =IFERROR(INDEX('nba.com measureables'!$A:$J,MATCH($A13,'nba.com measureables'!$A:$A,FALSE),8), "") -> 9' 2'' | T13: =" <li><b><a target='_blank' href='" & L13 & "'>" & A13 & "</a></b> - <i>" & B13 & " - " & C13 & "</i></li> <ul style='list-style-type:none'>" & IF(D13 <> "", " <li>Grade: " & D13 & " </li>", "") & IF(E13 <> "", " <li>Age: " & ROUND(E13,2) & " </li>", "") & IF(F13 <> "", " <li>Height: " & F13 & " </li>", "") & IF(G13 <> "", " <li>Wingspan: " & G13 & " </li>", "") & IF(H13 <> "", " <li>Reach: " & H13 & " </li>", "") & IF(I13 <> "", " <li>Ape: " & I13 & " </li>", "") & " </ul> <br>" -> <li><b><a _x000D_ target='_blank' _x000D_ href='https://www.sports-reference.com/cbb/players/nicolas-claxton-1.html'>Nicolas Claxton</a></b> - <i>C - Georgia</i></li>_x000D_ <ul style='list-style-type:none'>_x000D_ <li>Grade: Sophomore </li>_x000D_ <li>Age: 20.17 </li>_x000D_ <li>Height: 83.75 </li>_x000D_ <li>Wingspan: 86.5 </li>_x000D_ <li>Reach: 110 </li>_x000D_ <li>Ape: +2.75 </li>_x000D_ </ul>_x000D_<br>
A14: Chuma Okeke | B14: PF | C14: Auburn | D14: Sophomore | E14: =YEARFRAC(P14, TODAY(), 1) -> 20.836341 | F14: =IFERROR(LEFT(Q14,FIND("'",Q14)-1)*12+SUBSTITUTE(MID(Q14,FIND("'",Q14)+1,LEN(Q14)),"''",""), "") | G14: =IFERROR(LEFT(R14,FIND("'",R14)-1)*12+SUBSTITUTE(MID(R14,FIND("'",R14)+1,LEN(R14)),"''",""), "") | H14: =IFERROR(LEFT(S14,FIND("'",S14)-1)*12+SUBSTITUTE(MID(S14,FIND("'",S14)+1,LEN(S14)),"''",""), "") | I14: =IFERROR(IF(G14-F14>= 0, "+" & G14-F14, ""),"") | J14: 13 | K14: 50 | L14: https://www.sports-reference.com/cbb/players/chuma-okeke-1.html | M14: 33 | N14: 28 | O14: 9 | P14: 36025 | Q14: =IFERROR(INDEX('nba.com measureables'!$A:$J,MATCH($A14,'nba.com measureables'!$A:$A,FALSE),7), "") -> 0 | R14: =IFERROR(INDEX('nba.com measureables'!$A:$J,MATCH($A14,'nba.com measureables'!$A:$A,FALSE),10), "") -> 0 | S14: =IFERROR(INDEX('nba.com measureables'!$A:$J,MATCH($A14,'nba.com measureables'!$A:$A,FALSE),8), "") -> 0 | T14: =" <li><b><a target='_blank' href='" & L14 & "'>" & A14 & "</a></b> - <i>" & B14 & " - " & C14 & "</i></li> <ul style='list-style-type:none'>" & IF(D14 <> "", " <li>Grade: " & D14 & " </li>", "") & IF(E14 <> "", " <li>Age: " & ROUND(E14,2) & " </li>", "") & IF(F14 <> "", " <li>Height: " & F14 & " </li>", "") & IF(G14 <> "", " <li>Wingspan: " & G14 & " </li>", "") & IF(H14 <> "", " <li>Reach: " & H14 & " </li>", "") & IF(I14 <> "", " <li>Ape: " & I14 & " </li>", "") & " </ul> <br>" -> <li><b><a _x000D_ target='_blank' _x000D_ href='https://www.sports-reference.com/cbb/players/chuma-okeke-1.html'>Chuma Okeke</a></b> - <i>PF - Auburn</i></li>_x000D_ <ul style='list-style-type:none'>_x000D_ <li>Grade: Sophomore </li>_x000D_ <li>Age: 20.84 </li>_x000D_ </ul>_x000D_<br>
A15: Goga Bitadze | B15: C | C15: Buducnost VOLI (Montenegrin Basketball League) | E15: =YEARFRAC(P15, TODAY(), 1) -> 19.915776 | F15: =IFERROR(LEFT(Q15,FIND("'",Q15)-1)*12+SUBSTITUTE(MID(Q15,FIND("'",Q15)+1,LEN(Q15)),"''",""), "") | G15: =IFERROR(LEFT(R15,FIND("'",R15)-1)*12+SUBSTITUTE(MID(R15,FIND("'",R15)+1,LEN(R15)),"''",""), "") | H15: =IFERROR(LEFT(S15,FIND("'",S15)-1)*12+SUBSTITUTE(MID(S15,FIND("'",S15)+1,LEN(S15)),"''",""), "") | I15: =IFERROR(IF(G15-F15>= 0, "+" & G15-F15, ""),"") | J15: 14 | K15: 50 | L15: https://www.basketball-reference.com/international/players/goga-bitadze-1.html | M15: 17 | N15: 11 | O15: 8 | P15: 36361 | Q15: =IFERROR(INDEX('nba.com measureables'!$A:$J,MATCH($A15,'nba.com measureables'!$A:$A,FALSE),7), "") | R15: =IFERROR(INDEX('nba.com measureables'!$A:$J,MATCH($A15,'nba.com measureables'!$A:$A,FALSE),10), "") | S15: =IFERROR(INDEX('nba.com measureables'!$A:$J,MATCH($A15,'nba.com measureables'!$A:$A,FALSE),8), "") | T15: =" <li><b><a target='_blank' href='" & L15 & "'>" & A15 & "</a></b> - <i>" & B15 & " - " & C15 & "</i></li> <ul style='list-style-type:none'>" & IF(D15 <> "", " <li>Grade: " & D15 & " </li>", "") & IF(E15 <> "", " <li>Age: " & ROUND(E15,2) & " </li>", "") & IF(F15 <> "", " <li>Height: " & F15 & " </li>", "") & IF(G15 <> "", " <li>Wingspan: " & G15 & " </li>", "") & IF(H15 <> "", " <li>Reach: " & H15 & " </li>", "") & IF(I15 <> "", " <li>Ape: " & I15 & " </li>", "") & " </ul> <br>" -> <li><b><a _x000D_ target='_blank' _x000D_ href='https://www.basketball-reference.com/international/players/goga-bitadze-1.html'>Goga Bitadze</a></b> - <i>C - Buducnost VOLI (Montenegrin Basketball League)</i></li>_x000D_ <ul style='list-style-type:none'>_x000D_ <li>Age: 19.92 </li>_x000D_ </ul>_x000D_<br>
A16: Bol Bol | B16: C | C16: Oregon | D16: Freshman | E16: =YEARFRAC(P16, TODAY(), 1) -> 19.589961 | F16: =IFERROR(LEFT(Q16,FIND("'",Q16)-1)*12+SUBSTITUTE(MID(Q16,FIND("'",Q16)+1,LEN(Q16)),"''",""), "") -> 86.5 | G16: =IFERROR(LEFT(R16,FIND("'",R16)-1)*12+SUBSTITUTE(MID(R16,FIND("'",R16)+1,LEN(R16)),"''",""), "") -> 91 | H16: =IFERROR(LEFT(S16,FIND("'",S16)-1)*12+SUBSTITUTE(MID(S16,FIND("'",S16)+1,LEN(S16)),"''",""), "") -> 115.5 | I16: =IFERROR(IF(G16-F16>= 0, "+" & G16-F16, ""),"") -> +4.5 | J16: 15 | K16: 50 | L16: https://www.sports-reference.com/cbb/players/bol-bol-1.html | M16: 14 | N16: 10 | P16: 36480 | Q16: =IFERROR(INDEX('nba.com measureables'!$A:$J,MATCH($A16,'nba.com measureables'!$A:$A,FALSE),7), "") -> 7' 2.5'' | R16: =IFERROR(INDEX('nba.com measureables'!$A:$J,MATCH($A16,'nba.com measureables'!$A:$A,FALSE),10), "") -> 7' 7'' | S16: =IFERROR(INDEX('nba.com measureables'!$A:$J,MATCH($A16,'nba.com measureables'!$A:$A,FALSE),8), "") -> 9' 7.5'' | T16: =" <li><b><a target='_blank' href='" & L16 & "'>" & A16 & "</a></b> - <i>" & B16 & " - " & C16 & "</i></li> <ul style='list-style-type:none'>" & IF(D16 <> "", " <li>Grade: " & D16 & " </li>", "") & IF(E16 <> "", " <li>Age: " & ROUND(E16,2) & " </li>", "") & IF(F16 <> "", " <li>Height: " & F16 & " </li>", "") & IF(G16 <> "", " <li>Wingspan: " & G16 & " </li>", "") & IF(H16 <> "", " <li>Reach: " & H16 & " </li>", "") & IF(I16 <> "", " <li>Ape: " & I16 & " </li>", "") & " </ul> <br>" -> <li><b><a _x000D_ target='_blank' _x000D_ href='https://www.sports-reference.com/cbb/players/bol-bol-1.html'>Bol Bol</a></b> - <i>C - Oregon</i></li>_x000D_ <ul style='list-style-type:none'>_x000D_ <li>Grade: Freshman </li>_x000D_ <li>Age: 19.59 </li>_x000D_ <li>Height: 86.5 </li>_x000D_ <li>Wingspan: 91 </li>_x000D_ <li>Reach: 115.5 </li>_x000D_ <li>Ape: +4.5 </li>_x000D_ </ul>_x000D_<br>
A17: Coby White | B17: SG | C17: North Carolina | D17: Freshman | E17: =YEARFRAC(P17, TODAY(), 1) -> 19.33744 | F17: =IFERROR(LEFT(Q17,FIND("'",Q17)-1)*12+SUBSTITUTE(MID(Q17,FIND("'",Q17)+1,LEN(Q17)),"''",""), "") -> 76.75 | G17: =IFERROR(LEFT(R17,FIND("'",R17)-1)*12+SUBSTITUTE(MID(R17,FIND("'",R17)+1,LEN(R17)),"''",""), "") -> 77 | H17: =IFERROR(LEFT(S17,FIND("'",S17)-1)*12+SUBSTITUTE(MID(S17,FIND("'",S17)+1,LEN(S17)),"''",""), "") -> 97.5 | I17: =IFERROR(IF(G17-F17>= 0, "+" & G17-F17, ""),"") -> +0.25 | J17: 16 | K17: 45 | L17: https://www.sports-reference.com/cbb/players/coby-white-1.html | M17: 9 | N17: 14 | P17: 36572 | Q17: =IFERROR(INDEX('nba.com measureables'!$A:$J,MATCH($A17,'nba.com measureables'!$A:$A,FALSE),7), "") -> 6' 4.75'' | R17: =IFERROR(INDEX('nba.com measureables'!$A:$J,MATCH($A17,'nba.com measureables'!$A:$A,FALSE),10), "") -> 6' 5'' | S17: =IFERROR(INDEX('nba.com measureables'!$A:$J,MATCH($A17,'nba.com measureables'!$A:$A,FALSE),8), "") -> 8' 1.5'' | T17: =" <li><b><a target='_blank' href='" & L17 & "'>" & A17 & "</a></b> - <i>" & B17 & " - " & C17 & "</i></li> <ul style='list-style-type:none'>" & IF(D17 <> "", " <li>Grade: " & D17 & " </li>", "") & IF(E17 <> "", " <li>Age: " & ROUND(E17,2) & " </li>", "") & IF(F17 <> "", " <li>Height: " & F17 & " </li>", "") & IF(G17 <> "", " <li>Wingspan: " & G17 & " </li>", "") & IF(H17 <> "", " <li>Reach: " & H17 & " </li>", "") & IF(I17 <> "", " <li>Ape: " & I17 & " </li>", "") & " </ul> <br>" -> <li><b><a _x000D_ target='_blank' _x000D_ href='https://www.sports-reference.com/cbb/players/coby-white-1.html'>Coby White</a></b> - <i>SG - North Carolina</i></li>_x000D_ <ul style='list-style-type:none'>_x000D_ <li>Grade: Freshman </li>_x000D_ <li>Age: 19.34 </li>_x000D_ <li>Height: 76.75 </li>_x000D_ <li>Wingspan: 77 </li>_x000D_ <li>Reach: 97.5 </li>_x000D_ <li>Ape: +0.25 </li>_x000D_ </ul>_x000D_<br>
A18: Brandon Clarke | B18: PF | C18: Gonzaga | D18: Junior | E18: =YEARFRAC(P18, TODAY(), 1) -> 22.746064 | F18: =IFERROR(LEFT(Q18,FIND("'",Q18)-1)*12+SUBSTITUTE(MID(Q18,FIND("'",Q18)+1,LEN(Q18)),"''",""), "") -> 80.25 | G18: =IFERROR(LEFT(R18,FIND("'",R18)-1)*12+SUBSTITUTE(MID(R18,FIND("'",R18)+1,LEN(R18)),"''",""), "") -> 80.25 | H18: =IFERROR(LEFT(S18,FIND("'",S18)-1)*12+SUBSTITUTE(MID(S18,FIND("'",S18)+1,LEN(S18)),"''",""), "") -> 102 | I18: =IFERROR(IF(G18-F18>= 0, "+" & G18-F18, ""),"") -> +0 | J18: 17 | K18: 45 | L18: https://www.sports-reference.com/cbb/players/brandon-clarke-1.html | M18: 12 | N18: 8 | P18: 35327 | Q18: =IFERROR(INDEX('nba.com measureables'!$A:$J,MATCH($A18,'nba.com measureables'!$A:$A,FALSE),7), "") -> 6' 8.25'' | R18: =IFERROR(INDEX('nba.com measureables'!$A:$J,MATCH($A18,'nba.com measureables'!$A:$A,FALSE),10), "") -> 6' 8.25'' | S18: =IFERROR(INDEX('nba.com measureables'!$A:$J,MATCH($A18,'nba.com measureables'!$A:$A,FALSE),8), "") -> 8' 6'' | T18: =" <li><b><a target='_blank' href='" & L18 & "'>" & A18 & "</a></b> - <i>" & B18 & " - " & C18 & "</i></li> <ul style='list-style-type:none'>" & IF(D18 <> "", " <li>Grade: " & D18 & " </li>", "") & IF(E18 <> "", " <li>Age: " & ROUND(E18,2) & " </li>", "") & IF(F18 <> "", " <li>Height: " & F18 & " </li>", "") & IF(G18 <> "", " <li>Wingspan: " & G18 & " </li>", "") & IF(H18 <> "", " <li>Reach: " & H18 & " </li>", "") & IF(I18 <> "", " <li>Ape: " & I18 & " </li>", "") & " </ul> <br>" -> <li><b><a _x000D_ target='_blank' _x000D_ href='https://www.sports-reference.com/cbb/players/brandon-clarke-1.html'>Brandon Clarke</a></b> - <i>PF - Gonzaga</i></li>_x000D_ <ul style='list-style-type:none'>_x000D_ <li>Grade: Junior </li>_x000D_ <li>Age: 22.75 </li>_x000D_ <li>Height: 80.25 </li>_x000D_ <li>Wingspan: 80.25 </li>_x000D_ <li>Reach: 102 </li>_x000D_ <li>Ape: +0 </li>_x000D_ </ul>_x000D_<br>
A19: Tyler Herro | B19: SG | C19: Kentucky | D19: Freshman | E19: =YEARFRAC(P19, TODAY(), 1) -> 19.411362 | F19: =IFERROR(LEFT(Q19,FIND("'",Q19)-1)*12+SUBSTITUTE(MID(Q19,FIND("'",Q19)+1,LEN(Q19)),"''",""), "") -> 78 | G19: =IFERROR(LEFT(R19,FIND("'",R19)-1)*12+SUBSTITUTE(MID(R19,FIND("'",R19)+1,LEN(R19)),"''",""), "") -> 75.25 | H19: =IFERROR(LEFT(S19,FIND("'",S19)-1)*12+SUBSTITUTE(MID(S19,FIND("'",S19)+1,LEN(S19)),"''",""), "") -> 100.5 | I19: =IFERROR(IF(G19-F19>= 0, "+" & G19-F19, ""),"") | J19: 18 | K19: 45 | L19: https://www.sports-reference.com/cbb/players/tyler-herro-1.html | M19: 15 | N19: 16 | P19: 36545 | Q19: =IFERROR(INDEX('nba.com measureables'!$A:$J,MATCH($A19,'nba.com measureables'!$A:$A,FALSE),7), "") -> 6' 6'' | R19: =IFERROR(INDEX('nba.com measureables'!$A:$J,MATCH($A19,'nba.com measureables'!$A:$A,FALSE),10), "") -> 6' 3.25'' | S19: =IFERROR(INDEX('nba.com measureables'!$A:$J,MATCH($A19,'nba.com measureables'!$A:$A,FALSE),8), "") -> 8' 4.5'' | T19: =" <li><b><a target='_blank' href='" & L19 & "'>" & A19 & "</a></b> - <i>" & B19 & " - " & C19 & "</i></li> <ul style='list-style-type:none'>" & IF(D19 <> "", " <li>Grade: " & D19 & " </li>", "") & IF(E19 <> "", " <li>Age: " & ROUND(E19,2) & " </li>", "") & IF(F19 <> "", " <li>Height: " & F19 & " </li>", "") & IF(G19 <> "", " <li>Wingspan: " & G19 & " </li>", "") & IF(H19 <> "", " <li>Reach: " & H19 & " </li>", "") & IF(I19 <> "", " <li>Ape: " & I19 & " </li>", "") & " </ul> <br>" -> <li><b><a _x000D_ target='_blank' _x000D_ href='https://www.sports-reference.com/cbb/players/tyler-herro-1.html'>Tyler Herro</a></b> - <i>SG - Kentucky</i></li>_x000D_ <ul style='list-style-type:none'>_x000D_ <li>Grade: Freshman </li>_x000D_ <li>Age: 19.41 </li>_x000D_ <li>Height: 78 </li>_x000D_ <li>Wingspan: 75.25 </li>_x000D_ <li>Reach: 100.5 </li>_x000D_ </ul>_x000D_<br>
A20: Nickeil Alexander-Walker | B20: SG | C20: Virginia Tech | D20: Sophomore | E20: =YEARFRAC(P20, TODAY(), 1) -> 20.795271 | F20: =IFERROR(LEFT(Q20,FIND("'",Q20)-1)*12+SUBSTITUTE(MID(Q20,FIND("'",Q20)+1,LEN(Q20)),"''",""), "") -> 77.5 | G20: =IFERROR(LEFT(R20,FIND("'",R20)-1)*12+SUBSTITUTE(MID(R20,FIND("'",R20)+1,LEN(R20)),"''",""), "") -> 81.5 | H20: =IFERROR(LEFT(S20,FIND("'",S20)-1)*12+SUBSTITUTE(MID(S20,FIND("'",S20)+1,LEN(S20)),"''",""), "") -> 102 | I20: =IFERROR(IF(G20-F20>= 0, "+" & G20-F20, ""),"") -> +4 | J20: 19 | K20: 45 | L20: https://www.sports-reference.com/cbb/players/nickeil-alexander-walker-1.html | M20: 18 | N20: 17 | P20: 36040 | Q20: =IFERROR(INDEX('nba.com measureables'!$A:$J,MATCH($A20,'nba.com measureables'!$A:$A,FALSE),7), "") -> 6' 5.5'' | R20: =IFERROR(INDEX('nba.com measureables'!$A:$J,MATCH($A20,'nba.com measureables'!$A:$A,FALSE),10), "") -> 6' 9.5'' | S20: =IFERROR(INDEX('nba.com measureables'!$A:$J,MATCH($A20,'nba.com measureables'!$A:$A,FALSE),8), "") -> 8' 6'' | T20: =" <li><b><a target='_blank' href='" & L20 & "'>" & A20 & "</a></b> - <i>" & B20 & " - " & C20 & "</i></li> <ul style='list-style-type:none'>" & IF(D20 <> "", " <li>Grade: " & D20 & " </li>", "") & IF(E20 <> "", " <li>Age: " & ROUND(E20,2) & " </li>", "") & IF(F20 <> "", " <li>Height: " & F20 & " </li>", "") & IF(G20 <> "", " <li>Wingspan: " & G20 & " </li>", "") & IF(H20 <> "", " <li>Reach: " & H20 & " </li>", "") & IF(I20 <> "", " <li>Ape: " & I20 & " </li>", "") & " </ul> <br>" -> <li><b><a _x000D_ target='_blank' _x000D_ href='https://www.sports-reference.com/cbb/players/nickeil-alexander-walker-1.html'>Nickeil Alexander-Walker</a></b> - <i>SG - Virginia Tech</i></li>_x000D_ <ul style='list-style-type:none'>_x000D_ <li>Grade: Sophomore </li>_x000D_ <li>Age: 20.8 </li>_x000D_ <li>Height: 77.5 </li>_x000D_ <li>Wingspan: 81.5 </li>_x000D_ <li>Reach: 102 </li>_x000D_ <li>Ape: +4 </li>_x000D_ </ul>_x000D_<br>
A21: Nassir Little | B21: SF | C21: North Carolina | D21: Freshman | E21: =YEARFRAC(P21, TODAY(), 1) -> 19.351129 | F21: =IFERROR(LEFT(Q21,FIND("'",Q21)-1)*12+SUBSTITUTE(MID(Q21,FIND("'",Q21)+1,LEN(Q21)),"''",""), "") -> 78 | G21: =IFERROR(LEFT(R21,FIND("'",R21)-1)*12+SUBSTITUTE(MID(R21,FIND("'",R21)+1,LEN(R21)),"''",""), "") -> 85.25 | H21: =IFERROR(LEFT(S21,FIND("'",S21)-1)*12+SUBSTITUTE(MID(S21,FIND("'",S21)+1,LEN(S21)),"''",""), "") -> 104.5 | I21: =IFERROR(IF(G21-F21>= 0, "+" & G21-F21, ""),"") -> +7.25 | J21: 20 | K21: 45 | L21: https://www.sports-reference.com/cbb/players/nassir-little-1.html | M21: 10 | N21: 22 | P21: 36567 | Q21: =IFERROR(INDEX('nba.com measureables'!$A:$J,MATCH($A21,'nba.com measureables'!$A:$A,FALSE),7), "") -> 6' 6'' | R21: =IFERROR(INDEX('nba.com measureables'!$A:$J,MATCH($A21,'nba.com measureables'!$A:$A,FALSE),10), "") -> 7' 1.25'' | S21: =IFERROR(INDEX('nba.com measureables'!$A:$J,MATCH($A21,'nba.com measureables'!$A:$A,FALSE),8), "") -> 8' 8.5'' | T21: =" <li><b><a target='_blank' href='" & L21 & "'>" & A21 & "</a></b> - <i>" & B21 & " - " & C21 & "</i></li> <ul style='list-style-type:none'>" & IF(D21 <> "", " <li>Grade: " & D21 & " </li>", "") & IF(E21 <> "", " <li>Age: " & ROUND(E21,2) & " </li>", "") & IF(F21 <> "", " <li>Height: " & F21 & " </li>", "") & IF(G21 <> "", " <li>Wingspan: " & G21 & " </li>", "") & IF(H21 <> "", " <li>Reach: " & H21 & " </li>", "") & IF(I21 <> "", " <li>Ape: " & I21 & " </li>", "") & " </ul> <br>" -> <li><b><a _x000D_ target='_blank' _x000D_ href='https://www.sports-reference.com/cbb/players/nassir-little-1.html'>Nassir Little</a></b> - <i>SF - North Carolina</i></li>_x000D_ <ul style='list-style-type:none'>_x000D_ <li>Grade: Freshman </li>_x000D_ <li>Age: 19.35 </li>_x000D_ <li>Height: 78 </li>_x000D_ <li>Wingspan: 85.25 </li>_x000D_ <li>Reach: 104.5 </li>_x000D_ <li>Ape: +7.25 </li>_x000D_ </ul>_x000D_<br>
A22: Romeo Langford | B22: SF | C22: Indiana | D22: Freshman | E22: =YEARFRAC(P22, TODAY(), 1) -> 19.650196 | F22: =IFERROR(LEFT(Q22,FIND("'",Q22)-1)*12+SUBSTITUTE(MID(Q22,FIND("'",Q22)+1,LEN(Q22)),"''",""), "") -> 78 | G22: =IFERROR(LEFT(R22,FIND("'",R22)-1)*12+SUBSTITUTE(MID(R22,FIND("'",R22)+1,LEN(R22)),"''",""), "") -> 83 | H22: =IFERROR(LEFT(S22,FIND("'",S22)-1)*12+SUBSTITUTE(MID(S22,FIND("'",S22)+1,LEN(S22)),"''",""), "") -> 103 | I22: =IFERROR(IF(G22-F22>= 0, "+" & G22-F22, ""),"") -> +5 | J22: 21 | K22: 45 | L22: https://www.sports-reference.com/cbb/players/romeo-langford-1.html | M22: 13 | N22: 20 | P22: 36458 | Q22: =IFERROR(INDEX('nba.com measureables'!$A:$J,MATCH($A22,'nba.com measureables'!$A:$A,FALSE),7), "") -> 6' 6'' | R22: =IFERROR(INDEX('nba.com measureables'!$A:$J,MATCH($A22,'nba.com measureables'!$A:$A,FALSE),10), "") -> 6' 11'' | S22: =IFERROR(INDEX('nba.com measureables'!$A:$J,MATCH($A22,'nba.com measureables'!$A:$A,FALSE),8), "") -> 8' 7'' | T22: =" <li><b><a target='_blank' href='" & L22 & "'>" & A22 & "</a></b> - <i>" & B22 & " - " & C22 & "</i></li> <ul style='list-style-type:none'>" & IF(D22 <> "", " <li>Grade: " & D22 & " </li>", "") & IF(E22 <> "", " <li>Age: " & ROUND(E22,2) & " </li>", "") & IF(F22 <> "", " <li>Height: " & F22 & " </li>", "") & IF(G22 <> "", " <li>Wingspan: " & G22 & " </li>", "") & IF(H22 <> "", " <li>Reach: " & H22 & " </li>", "") & IF(I22 <> "", " <li>Ape: " & I22 & " </li>", "") & " </ul> <br>" -> <li><b><a _x000D_ target='_blank' _x000D_ href='https://www.sports-reference.com/cbb/players/romeo-langford-1.html'>Romeo Langford</a></b> - <i>SF - Indiana</i></li>_x000D_ <ul style='list-style-type:none'>_x000D_ <li>Grade: Freshman </li>_x000D_ <li>Age: 19.65 </li>_x000D_ <li>Height: 78 </li>_x000D_ <li>Wingspan: 83 </li>_x000D_ <li>Reach: 103 </li>_x000D_ <li>Ape: +5 </li>_x000D_ </ul>_x000D_<br>
A23: DeAndre Hunter | B23: PF | C23: Virginia | D23: Sophomore | E23: =YEARFRAC(P23, TODAY(), 1) -> 21.54881 | F23: =IFERROR(LEFT(Q23,FIND("'",Q23)-1)*12+SUBSTITUTE(MID(Q23,FIND("'",Q23)+1,LEN(Q23)),"''",""), "") | G23: =IFERROR(LEFT(R23,FIND("'",R23)-1)*12+SUBSTITUTE(MID(R23,FIND("'",R23)+1,LEN(R23)),"''",""), "") | H23: =IFERROR(LEFT(S23,FIND("'",S23)-1)*12+SUBSTITUTE(MID(S23,FIND("'",S23)+1,LEN(S23)),"''",""), "") | I23: =IFERROR(IF(G23-F23>= 0, "+" & G23-F23, ""),"") | J23: 22 | K23: 45 | L23: https://www.sports-reference.com/cbb/players/deandre-hunter-1.html | M23: 5 | N23: 29 | P23: 35765 | Q23: =IFERROR(INDEX('nba.com measureables'!$A:$J,MATCH($A23,'nba.com measureables'!$A:$A,FALSE),7), "") -> 0 | R23: =IFERROR(INDEX('nba.com measureables'!$A:$J,MATCH($A23,'nba.com measureables'!$A:$A,FALSE),10), "") -> 0 | S23: =IFERROR(INDEX('nba.com measureables'!$A:$J,MATCH($A23,'nba.com measureables'!$A:$A,FALSE),8), "") -> 0 | T23: =" <li><b><a target='_blank' href='" & L23 & "'>" & A23 & "</a></b> - <i>" & B23 & " - " & C23 & "</i></li> <ul style='list-style-type:none'>" & IF(D23 <> "", " <li>Grade: " & D23 & " </li>", "") & IF(E23 <> "", " <li>Age: " & ROUND(E23,2) & " </li>", "") & IF(F23 <> "", " <li>Height: " & F23 & " </li>", "") & IF(G23 <> "", " <li>Wingspan: " & G23 & " </li>", "") & IF(H23 <> "", " <li>Reach: " & H23 & " </li>", "") & IF(I23 <> "", " <li>Ape: " & I23 & " </li>", "") & " </ul> <br>" -> <li><b><a _x000D_ target='_blank' _x000D_ href='https://www.sports-reference.com/cbb/players/deandre-hunter-1.html'>DeAndre Hunter</a></b> - <i>PF - Virginia</i></li>_x000D_ <ul style='list-style-type:none'>_x000D_ <li>Grade: Sophomore </li>_x000D_ <li>Age: 21.55 </li>_x000D_ </ul>_x000D_<br>
A24: Ty Jerome | B24: SG | C24: Virginia | D24: Junior | E24: =YEARFRAC(P24, TODAY(), 1) -> 21.948571 | F24: =IFERROR(LEFT(Q24,FIND("'",Q24)-1)*12+SUBSTITUTE(MID(Q24,FIND("'",Q24)+1,LEN(Q24)),"''",""), "") -> 77.5 | G24: =IFERROR(LEFT(R24,FIND("'",R24)-1)*12+SUBSTITUTE(MID(R24,FIND("'",R24)+1,LEN(R24)),"''",""), "") -> 76 | H24: =IFERROR(LEFT(S24,FIND("'",S24)-1)*12+SUBSTITUTE(MID(S24,FIND("'",S24)+1,LEN(S24)),"''",""), "") -> 98 | I24: =IFERROR(IF(G24-F24>= 0, "+" & G24-F24, ""),"") | J24: 23 | K24: 45 | L24: https://www.sports-reference.com/cbb/players/ty-jerome-1.html | M24: 25 | N24: 30 | P24: 35619 | Q24: =IFERROR(INDEX('nba.com measureables'!$A:$J,MATCH($A24,'nba.com measureables'!$A:$A,FALSE),7), "") -> 6' 5.5'' | R24: =IFERROR(INDEX('nba.com measureables'!$A:$J,MATCH($A24,'nba.com measureables'!$A:$A,FALSE),10), "") -> 6' 4'' | S24: =IFERROR(INDEX('nba.com measureables'!$A:$J,MATCH($A24,'nba.com measureables'!$A:$A,FALSE),8), "") -> 8' 2'' | T24: =" <li><b><a target='_blank' href='" & L24 & "'>" & A24 & "</a></b> - <i>" & B24 & " - " & C24 & "</i></li> <ul style='list-style-type:none'>" & IF(D24 <> "", " <li>Grade: " & D24 & " </li>", "") & IF(E24 <> "", " <li>Age: " & ROUND(E24,2) & " </li>", "") & IF(F24 <> "", " <li>Height: " & F24 & " </li>", "") & IF(G24 <> "", " <li>Wingspan: " & G24 & " </li>", "") & IF(H24 <> "", " <li>Reach: " & H24 & " </li>", "") & IF(I24 <> "", " <li>Ape: " & I24 & " </li>", "") & " </ul> <br>" -> <li><b><a _x000D_ target='_blank' _x000D_ href='https://www.sports-reference.com/cbb/players/ty-jerome-1.html'>Ty Jerome</a></b> - <i>SG - Virginia</i></li>_x000D_ <ul style='list-style-type:none'>_x000D_ <li>Grade: Junior </li>_x000D_ <li>Age: 21.95 </li>_x000D_ <li>Height: 77.5 </li>_x000D_ <li>Wingspan: 76 </li>_x000D_ <li>Reach: 98 </li>_x000D_ </ul>_x000D_<br>
A25: Sekou Doumbouya | B25: PF | C25: Guinea | E25: =YEARFRAC(P25, TODAY(), 1) -> 18.485969 | F25: =IFERROR(LEFT(Q25,FIND("'",Q25)-1)*12+SUBSTITUTE(MID(Q25,FIND("'",Q25)+1,LEN(Q25)),"''",""), "") | G25: =IFERROR(LEFT(R25,FIND("'",R25)-1)*12+SUBSTITUTE(MID(R25,FIND("'",R25)+1,LEN(R25)),"''",""), "") | H25: =IFERROR(LEFT(S25,FIND("'",S25)-1)*12+SUBSTITUTE(MID(S25,FIND("'",S25)+1,LEN(S25)),"''",""), "") | I25: =IFERROR(IF(G25-F25>= 0, "+" & G25-F25, ""),"") | J25: 24 | K25: 45 | L25: https://www.basketball-reference.com/international/players/sekou-omar-doumbouya-1.html | M25: 8 | N25: 18 | P25: 36883 | Q25: =IFERROR(INDEX('nba.com measureables'!$A:$J,MATCH($A25,'nba.com measureables'!$A:$A,FALSE),7), "") | R25: =IFERROR(INDEX('nba.com measureables'!$A:$J,MATCH($A25,'nba.com measureables'!$A:$A,FALSE),10), "") | S25: =IFERROR(INDEX('nba.com measureables'!$A:$J,MATCH($A25,'nba.com measureables'!$A:$A,FALSE),8), "") | T25: =" <li><b><a target='_blank' href='" & L25 & "'>" & A25 & "</a></b> - <i>" & B25 & " - " & C25 & "</i></li> <ul style='list-style-type:none'>" & IF(D25 <> "", " <li>Grade: " & D25 & " </li>", "") & IF(E25 <> "", " <li>Age: " & ROUND(E25,2) & " </li>", "") & IF(F25 <> "", " <li>Height: " & F25 & " </li>", "") & IF(G25 <> "", " <li>Wingspan: " & G25 & " </li>", "") & IF(H25 <> "", " <li>Reach: " & H25 & " </li>", "") & IF(I25 <> "", " <li>Ape: " & I25 & " </li>", "") & " </ul> <br>" -> <li><b><a _x000D_ target='_blank' _x000D_ href='https://www.basketball-reference.com/international/players/sekou-omar-doumbouya-1.html'>Sekou Doumbouya</a></b> - <i>PF - Guinea</i></li>_x000D_ <ul style='list-style-type:none'>_x000D_ <li>Age: 18.49 </li>_x000D_ </ul>_x000D_<br>
A26: KZ Okpala | B26: SF | C26: Stanford | D26: Sophomore | E26: =YEARFRAC(P26, TODAY(), 1) -> 20.143025 | F26: =IFERROR(LEFT(Q26,FIND("'",Q26)-1)*12+SUBSTITUTE(MID(Q26,FIND("'",Q26)+1,LEN(Q26)),"''",""), "") -> 81.5 | G26: =IFERROR(LEFT(R26,FIND("'",R26)-1)*12+SUBSTITUTE(MID(R26,FIND("'",R26)+1,LEN(R26)),"''",""), "") -> 85.75 | H26: =IFERROR(LEFT(S26,FIND("'",S26)-1)*12+SUBSTITUTE(MID(S26,FIND("'",S26)+1,LEN(S26)),"''",""), "") -> 106.5 | I26: =IFERROR(IF(G26-F26>= 0, "+" & G26-F26, ""),"") -> +4.25 | J26: 25 | K26: 45 | L26: https://www.sports-reference.com/cbb/players/kezie-okpala-1.html | M26: 24 | N26: 23 | P26: 36278 | Q26: =IFERROR(INDEX('nba.com measureables'!$A:$J,MATCH($A26,'nba.com measureables'!$A:$A,FALSE),7), "") -> 6' 9.5'' | R26: =IFERROR(INDEX('nba.com measureables'!$A:$J,MATCH($A26,'nba.com measureables'!$A:$A,FALSE),10), "") -> 7' 1.75'' | S26: =IFERROR(INDEX('nba.com measureables'!$A:$J,MATCH($A26,'nba.com measureables'!$A:$A,FALSE),8), "") -> 8' 10.5'' | T26: =" <li><b><a target='_blank' href='" & L26 & "'>" & A26 & "</a></b> - <i>" & B26 & " - " & C26 & "</i></li> <ul style='list-style-type:none'>" & IF(D26 <> "", " <li>Grade: " & D26 & " </li>", "") & IF(E26 <> "", " <li>Age: " & ROUND(E26,2) & " </li>", "") & IF(F26 <> "", " <li>Height: " & F26 & " </li>", "") & IF(G26 <> "", " <li>Wingspan: " & G26 & " </li>", "") & IF(H26 <> "", " <li>Reach: " & H26 & " </li>", "") & IF(I26 <> "", " <li>Ape: " & I26 & " </li>", "") & " </ul> <br>" -> <li><b><a _x000D_ target='_blank' _x000D_ href='https://www.sports-reference.com/cbb/players/kezie-okpala-1.html'>KZ Okpala</a></b> - <i>SF - Stanford</i></li>_x000D_ <ul style='list-style-type:none'>_x000D_ <li>Grade: Sophomore </li>_x000D_ <li>Age: 20.14 </li>_x000D_ <li>Height: 81.5 </li>_x000D_ <li>Wingspan: 85.75 </li>_x000D_ <li>Reach: 106.5 </li>_x000D_ <li>Ape: +4.25 </li>_x000D_ </ul>_x000D_<br>
A27: Rui Hachimura | B27: PF | C27: Gonzaga | D27: Junior | E27: =YEARFRAC(P27, TODAY(), 1) -> 21.359303 | F27: =IFERROR(LEFT(Q27,FIND("'",Q27)-1)*12+SUBSTITUTE(MID(Q27,FIND("'",Q27)+1,LEN(Q27)),"''",""), "") | G27: =IFERROR(LEFT(R27,FIND("'",R27)-1)*12+SUBSTITUTE(MID(R27,FIND("'",R27)+1,LEN(R27)),"''",""), "") | H27: =IFERROR(LEFT(S27,FIND("'",S27)-1)*12+SUBSTITUTE(MID(S27,FIND("'",S27)+1,LEN(S27)),"''",""), "") | I27: =IFERROR(IF(G27-F27>= 0, "+" & G27-F27, ""),"") | J27: 26 | K27: 45 | L27: https://www.sports-reference.com/cbb/players/rui-hachimura-1.html | M27: 20 | N27: 34 | P27: 35834 | Q27: =IFERROR(INDEX('nba.com measureables'!$A:$J,MATCH($A27,'nba.com measureables'!$A:$A,FALSE),7), "") | R27: =IFERROR(INDEX('nba.com measureables'!$A:$J,MATCH($A27,'nba.com measureables'!$A:$A,FALSE),10), "") | S27: =IFERROR(INDEX('nba.com measureables'!$A:$J,MATCH($A27,'nba.com measureables'!$A:$A,FALSE),8), "") | T27: =" <li><b><a target='_blank' href='" & L27 & "'>" & A27 & "</a></b> - <i>" & B27 & " - " & C27 & "</i></li> <ul style='list-style-type:none'>" & IF(D27 <> "", " <li>Grade: " & D27 & " </li>", "") & IF(E27 <> "", " <li>Age: " & ROUND(E27,2) & " </li>", "") & IF(F27 <> "", " <li>Height: " & F27 & " </li>", "") & IF(G27 <> "", " <li>Wingspan: " & G27 & " </li>", "") & IF(H27 <> "", " <li>Reach: " & H27 & " </li>", "") & IF(I27 <> "", " <li>Ape: " & I27 & " </li>", "") & " </ul> <br>" -> <li><b><a _x000D_ target='_blank' _x000D_ href='https://www.sports-reference.com/cbb/players/rui-hachimura-1.html'>Rui Hachimura</a></b> - <i>PF - Gonzaga</i></li>_x000D_ <ul style='list-style-type:none'>_x000D_ <li>Grade: Junior </li>_x000D_ <li>Age: 21.36 </li>_x000D_ </ul>_x000D_<br>
A28: Carsen Edwards | B28: PG | C28: Purdue | D28: Junior | E28: =YEARFRAC(P28, TODAY(), 1) -> 21.271686 | F28: =IFERROR(LEFT(Q28,FIND("'",Q28)-1)*12+SUBSTITUTE(MID(Q28,FIND("'",Q28)+1,LEN(Q28)),"''",""), "") -> 72.25 | G28: =IFERROR(LEFT(R28,FIND("'",R28)-1)*12+SUBSTITUTE(MID(R28,FIND("'",R28)+1,LEN(R28)),"''",""), "") -> 78 | H28: =IFERROR(LEFT(S28,FIND("'",S28)-1)*12+SUBSTITUTE(MID(S28,FIND("'",S28)+1,LEN(S28)),"''",""), "") -> 94.5 | I28: =IFERROR(IF(G28-F28>= 0, "+" & G28-F28, ""),"") -> +5.75 | J28: 27 | K28: 45 | L28: https://www.sports-reference.com/cbb/players/carsen-edwards-1.html | M28: 36 | P28: 35866 | Q28: =IFERROR(INDEX('nba.com measureables'!$A:$J,MATCH($A28,'nba.com measureables'!$A:$A,FALSE),7), "") -> 6' 0.25'' | R28: =IFERROR(INDEX('nba.com measureables'!$A:$J,MATCH($A28,'nba.com measureables'!$A:$A,FALSE),10), "") -> 6' 6'' | S28: =IFERROR(INDEX('nba.com measureables'!$A:$J,MATCH($A28,'nba.com measureables'!$A:$A,FALSE),8), "") -> 7' 10.5'' | T28: =" <li><b><a target='_blank' href='" & L28 & "'>" & A28 & "</a></b> - <i>" & B28 & " - " & C28 & "</i></li> <ul style='list-style-type:none'>" & IF(D28 <> "", " <li>Grade: " & D28 & " </li>", "") & IF(E28 <> "", " <li>Age: " & ROUND(E28,2) & " </li>", "") & IF(F28 <> "", " <li>Height: " & F28 & " </li>", "") & IF(G28 <> "", " <li>Wingspan: " & G28 & " </li>", "") & IF(H28 <> "", " <li>Reach: " & H28 & " </li>", "") & IF(I28 <> "", " <li>Ape: " & I28 & " </li>", "") & " </ul> <br>" -> <li><b><a _x000D_ target='_blank' _x000D_ href='https://www.sports-reference.com/cbb/players/carsen-edwards-1.html'>Carsen Edwards</a></b> - <i>PG - Purdue</i></li>_x000D_ <ul style='list-style-type:none'>_x000D_ <li>Grade: Junior </li>_x000D_ <li>Age: 21.27 </li>_x000D_ <li>Height: 72.25 </li>_x000D_ <li>Wingspan: 78 </li>_x000D_ <li>Reach: 94.5 </li>_x000D_ <li>Ape: +5.75 </li>_x000D_ </ul>_x000D_<br>
A29: Admiral Schofield | B29: SF | C29: Tennessee | D29: Senior | E29: =YEARFRAC(P29, TODAY(), 1) -> 22.222381 | F29: =IFERROR(LEFT(Q29,FIND("'",Q29)-1)*12+SUBSTITUTE(MID(Q29,FIND("'",Q29)+1,LEN(Q29)),"''",""), "") -> 77.25 | G29: =IFERROR(LEFT(R29,FIND("'",R29)-1)*12+SUBSTITUTE(MID(R29,FIND("'",R29)+1,LEN(R29)),"''",""), "") -> 81.75 | H29: =IFERROR(LEFT(S29,FIND("'",S29)-1)*12+SUBSTITUTE(MID(S29,FIND("'",S29)+1,LEN(S29)),"''",""), "") -> 102.5 | I29: =IFERROR(IF(G29-F29>= 0, "+" & G29-F29, ""),"") -> +4.5 | J29: HM | K29: 40 | L29: https://www.sports-reference.com/cbb/players/admiral-schofield-1.html | M29: 37 | P29: 35519 | Q29: =IFERROR(INDEX('nba.com measureables'!$A:$J,MATCH($A29,'nba.com measureables'!$A:$A,FALSE),7), "") -> 6' 5.25'' | R29: =IFERROR(INDEX('nba.com measureables'!$A:$J,MATCH($A29,'nba.com measureables'!$A:$A,FALSE),10), "") -> 6' 9.75'' | S29: =IFERROR(INDEX('nba.com measureables'!$A:$J,MATCH($A29,'nba.com measureables'!$A:$A,FALSE),8), "") -> 8' 6.5'' | T29: =" <li><b><a target='_blank' href='" & L29 & "'>" & A29 & "</a></b> - <i>" & B29 & " - " & C29 & "</i></li> <ul style='list-style-type:none'>" & IF(D29 <> "", " <li>Grade: " & D29 & " </li>", "") & IF(E29 <> "", " <li>Age: " & ROUND(E29,2) & " </li>", "") & IF(F29 <> "", " <li>Height: " & F29 & " </li>", "") & IF(G29 <> "", " <li>Wingspan: " & G29 & " </li>", "") & IF(H29 <> "", " <li>Reach: " & H29 & " </li>", "") & IF(I29 <> "", " <li>Ape: " & I29 & " </li>", "") & " </ul> <br>" -> <li><b><a _x000D_ target='_blank' _x000D_ href='https://www.sports-reference.com/cbb/players/admiral-schofield-1.html'>Admiral Schofield</a></b> - <i>SF - Tennessee</i></li>_x000D_ <ul style='list-style-type:none'>_x000D_ <li>Grade: Senior </li>_x000D_ <li>Age: 22.22 </li>_x000D_ <li>Height: 77.25 </li>_x000D_ <li>Wingspan: 81.75 </li>_x000D_ <li>Reach: 102.5 </li>_x000D_ <li>Ape: +4.5 </li>_x000D_ </ul>_x000D_<br>
A30: Bruno Fernando | B30: C | C30: Maryland | D30: Sophomore | E30: =YEARFRAC(P30, TODAY(), 1) -> 20.844555 | F30: =IFERROR(LEFT(Q30,FIND("'",Q30)-1)*12+SUBSTITUTE(MID(Q30,FIND("'",Q30)+1,LEN(Q30)),"''",""), "") -> 82.25 | G30: =IFERROR(LEFT(R30,FIND("'",R30)-1)*12+SUBSTITUTE(MID(R30,FIND("'",R30)+1,LEN(R30)),"''",""), "") -> 87.25 | H30: =IFERROR(LEFT(S30,FIND("'",S30)-1)*12+SUBSTITUTE(MID(S30,FIND("'",S30)+1,LEN(S30)),"''",""), "") -> 110 | I30: =IFERROR(IF(G30-F30>= 0, "+" & G30-F30, ""),"") -> +5 | J30: HM | K30: 40 | L30: https://www.sports-reference.com/cbb/players/bruno-fernando-1.html | M30: 35 | N30: 21 | P30: 36022 | Q30: =IFERROR(INDEX('nba.com measureables'!$A:$J,MATCH($A30,'nba.com measureables'!$A:$A,FALSE),7), "") -> 6' 10.25'' | R30: =IFERROR(INDEX('nba.com measureables'!$A:$J,MATCH($A30,'nba.com measureables'!$A:$A,FALSE),10), "") -> 7' 3.25'' | S30: =IFERROR(INDEX('nba.com measureables'!$A:$J,MATCH($A30,'nba.com measureables'!$A:$A,FALSE),8), "") -> 9' 2'' | T30: =" <li><b><a target='_blank' href='" & L30 & "'>" & A30 & "</a></b> - <i>" & B30 & " - " & C30 & "</i></li> <ul style='list-style-type:none'>" & IF(D30 <> "", " <li>Grade: " & D30 & " </li>", "") & IF(E30 <> "", " <li>Age: " & ROUND(E30,2) & " </li>", "") & IF(F30 <> "", " <li>Height: " & F30 & " </li>", "") & IF(G30 <> "", " <li>Wingspan: " & G30 & " </li>", "") & IF(H30 <> "", " <li>Reach: " & H30 & " </li>", "") & IF(I30 <> "", " <li>Ape: " & I30 & " </li>", "") & " </ul> <br>" -> <li><b><a _x000D_ target='_blank' _x000D_ href='https://www.sports-reference.com/cbb/players/bruno-fernando-1.html'>Bruno Fernando</a></b> - <i>C - Maryland</i></li>_x000D_ <ul style='list-style-type:none'>_x000D_ <li>Grade: Sophomore </li>_x000D_ <li>Age: 20.84 </li>_x000D_ <li>Height: 82.25 </li>_x000D_ <li>Wingspan: 87.25 </li>_x000D_ <li>Reach: 110 </li>_x000D_ <li>Ape: +5 </li>_x000D_ </ul>_x000D_<br>
A31: Cameron Johnson | B31: PF | C31: North Carolina | D31: Senior | E31: =YEARFRAC(P31, TODAY(), 1) -> 23.293634 | F31: =IFERROR(LEFT(Q31,FIND("'",Q31)-1)*12+SUBSTITUTE(MID(Q31,FIND("'",Q31)+1,LEN(Q31)),"''",""), "") -> 80.5 | G31: =IFERROR(LEFT(R31,FIND("'",R31)-1)*12+SUBSTITUTE(MID(R31,FIND("'",R31)+1,LEN(R31)),"''",""), "") -> 82 | H31: =IFERROR(LEFT(S31,FIND("'",S31)-1)*12+SUBSTITUTE(MID(S31,FIND("'",S31)+1,LEN(S31)),"''",""), "") -> 103 | I31: =IFERROR(IF(G31-F31>= 0, "+" & G31-F31, ""),"") -> +1.5 | J31: HM | K31: 40 | L31: https://www.sports-reference.com/cbb/players/cameron-johnson-4.html | M31: 19 | N31: 38 | P31: 35127 | Q31: =IFERROR(INDEX('nba.com measureables'!$A:$J,MATCH($A31,'nba.com measureables'!$A:$A,FALSE),7), "") -> 6' 8.5'' | R31: =IFERROR(INDEX('nba.com measureables'!$A:$J,MATCH($A31,'nba.com measureables'!$A:$A,FALSE),10), "") -> 6' 10'' | S31: =IFERROR(INDEX('nba.com measureables'!$A:$J,MATCH($A31,'nba.com measureables'!$A:$A,FALSE),8), "") -> 8' 7'' | T31: =" <li><b><a target='_blank' href='" & L31 & "'>" & A31 & "</a></b> - <i>" & B31 & " - " & C31 & "</i></li> <ul style='list-style-type:none'>" & IF(D31 <> "", " <li>Grade: " & D31 & " </li>", "") & IF(E31 <> "", " <li>Age: " & ROUND(E31,2) & " </li>", "") & IF(F31 <> "", " <li>Height: " & F31 & " </li>", "") & IF(G31 <> "", " <li>Wingspan: " & G31 & " </li>", "") & IF(H31 <> "", " <li>Reach: " & H31 & " </li>", "") & IF(I31 <> "", " <li>Ape: " & I31 & " </li>", "") & " </ul> <br>" -> <li><b><a _x000D_ target='_blank' _x000D_ href='https://www.sports-reference.com/cbb/players/cameron-johnson-4.html'>Cameron Johnson</a></b> - <i>PF - North Carolina</i></li>_x000D_ <ul style='list-style-type:none'>_x000D_ <li>Grade: Senior </li>_x000D_ <li>Age: 23.29 </li>_x000D_ <li>Height: 80.5 </li>_x000D_ <li>Wingspan: 82 </li>_x000D_ <li>Reach: 103 </li>_x000D_ <li>Ape: +1.5 </li>_x000D_ </ul>_x000D_<br>
A32: Daniel Gafford | B32: C | C32: Arkansas | D32: Sophomore | E32: =YEARFRAC(P32, TODAY(), 1) -> 20.715868 | F32: =IFERROR(LEFT(Q32,FIND("'",Q32)-1)*12+SUBSTITUTE(MID(Q32,FIND("'",Q32)+1,LEN(Q32)),"''",""), "") -> 82.5 | G32: =IFERROR(LEFT(R32,FIND("'",R32)-1)*12+SUBSTITUTE(MID(R32,FIND("'",R32)+1,LEN(R32)),"''",""), "") -> 86.25 | H32: =IFERROR(LEFT(S32,FIND("'",S32)-1)*12+SUBSTITUTE(MID(S32,FIND("'",S32)+1,LEN(S32)),"''",""), "") -> 110 | I32: =IFERROR(IF(G32-F32>= 0, "+" & G32-F32, ""),"") -> +3.75 | J32: HM | K32: 40 | L32: https://www.sports-reference.com/cbb/players/daniel-gafford-1.html | M32: 41 | N32: 26 | P32: 36069 | Q32: =IFERROR(INDEX('nba.com measureables'!$A:$J,MATCH($A32,'nba.com measureables'!$A:$A,FALSE),7), "") -> 6' 10.5'' | R32: =IFERROR(INDEX('nba.com measureables'!$A:$J,MATCH($A32,'nba.com measureables'!$A:$A,FALSE),10), "") -> 7' 2.25'' | S32: =IFERROR(INDEX('nba.com measureables'!$A:$J,MATCH($A32,'nba.com measureables'!$A:$A,FALSE),8), "") -> 9' 2'' | T32: =" <li><b><a target='_blank' href='" & L32 & "'>" & A32 & "</a></b> - <i>" & B32 & " - " & C32 & "</i></li> <ul style='list-style-type:none'>" & IF(D32 <> "", " <li>Grade: " & D32 & " </li>", "") & IF(E32 <> "", " <li>Age: " & ROUND(E32,2) & " </li>", "") & IF(F32 <> "", " <li>Height: " & F32 & " </li>", "") & IF(G32 <> "", " <li>Wingspan: " & G32 & " </li>", "") & IF(H32 <> "", " <li>Reach: " & H32 & " </li>", "") & IF(I32 <> "", " <li>Ape: " & I32 & " </li>", "") & " </ul> <br>" -> <li><b><a _x000D_ target='_blank' _x000D_ href='https://www.sports-reference.com/cbb/players/daniel-gafford-1.html'>Daniel Gafford</a></b> - <i>C - Arkansas</i></li>_x000D_ <ul style='list-style-type:none'>_x000D_ <li>Grade: Sophomore </li>_x000D_ <li>Age: 20.72 </li>_x000D_ <li>Height: 82.5 </li>_x000D_ <li>Wingspan: 86.25 </li>_x000D_ <li>Reach: 110 </li>_x000D_ <li>Ape: +3.75 </li>_x000D_ </ul>_x000D_<br>
A33: Darius Bazley | B33: SF | C33: New Balance | D33: Freshman | E33: =YEARFRAC(P33, TODAY(), 1) -> 19.017112 | F33: =IFERROR(LEFT(Q33,FIND("'",Q33)-1)*12+SUBSTITUTE(MID(Q33,FIND("'",Q33)+1,LEN(Q33)),"''",""), "") -> 81 | G33: =IFERROR(LEFT(R33,FIND("'",R33)-1)*12+SUBSTITUTE(MID(R33,FIND("'",R33)+1,LEN(R33)),"''",""), "") -> 84 | H33: =IFERROR(LEFT(S33,FIND("'",S33)-1)*12+SUBSTITUTE(MID(S33,FIND("'",S33)+1,LEN(S33)),"''",""), "") -> 107 | I33: =IFERROR(IF(G33-F33>= 0, "+" & G33-F33, ""),"") -> +3 | J33: HM | K33: 40 | L33: https://en.wikipedia.org/wiki/Darius_Bazley | M33: 26 | P33: 36689 | Q33: =IFERROR(INDEX('nba.com measureables'!$A:$J,MATCH($A33,'nba.com measureables'!$A:$A,FALSE),7), "") -> 6' 9'' | R33: =IFERROR(INDEX('nba.com measureables'!$A:$J,MATCH($A33,'nba.com measureables'!$A:$A,FALSE),10), "") -> 7' 0'' | S33: =IFERROR(INDEX('nba.com measureables'!$A:$J,MATCH($A33,'nba.com measureables'!$A:$A,FALSE),8), "") -> 8' 11'' | T33: =" <li><b><a target='_blank' href='" & L33 & "'>" & A33 & "</a></b> - <i>" & B33 & " - " & C33 & "</i></li> <ul style='list-style-type:none'>" & IF(D33 <> "", " <li>Grade: " & D33 & " </li>", "") & IF(E33 <> "", " <li>Age: " & ROUND(E33,2) & " </li>", "") & IF(F33 <> "", " <li>Height: " & F33 & " </li>", "") & IF(G33 <> "", " <li>Wingspan: " & G33 & " </li>", "") & IF(H33 <> "", " <li>Reach: " & H33 & " </li>", "") & IF(I33 <> "", " <li>Ape: " & I33 & " </li>", "") & " </ul> <br>" -> <li><b><a _x000D_ target='_blank' _x000D_ href='https://en.wikipedia.org/wiki/Darius_Bazley'>Darius Bazley</a></b> - <i>SF - New Balance</i></li>_x000D_ <ul style='list-style-type:none'>_x000D_ <li>Grade: Freshman </li>_x000D_ <li>Age: 19.02 </li>_x000D_ <li>Height: 81 </li>_x000D_ <li>Wingspan: 84 </li>_x000D_ <li>Reach: 107 </li>_x000D_ <li>Ape: +3 </li>_x000D_ </ul>_x000D_<br>
