Workbook

Sheet board
A1: name | B1: position | C1: pick | D1: team | E1: school | F1: Grade | G1: 44153 | H1: height (in) | I1: weight | J1: wingspan (in) | K1: reach (in) | L1: Ape | M1: Ape Formula | N1: ++ | O1: + | P1: - | Q1: -- | R1: grade | S1: me | U1: ref_link | V1: nba_link | W1: birthday | X1: zamir | Y1: ringer | Z1: Dean | AA1: vecenie | AB1: espn | AC1: height | AD1: weight | AE1: wingspan | AF1: reach
A2: Onyeka Okongwu | B2: PF | C2: =IFERROR(INDEX(actual!A:A,MATCH(A2,actual!B:B,FALSE)), "") -> 6 | D2: =IFERROR(INDEX(actual!C:C,MATCH(A2,actual!B:B,FALSE)), "") -> ATL | E2: USC | F2: Freshman | G2: =YEARFRAC(W2, $G$1, 1) -> 19.93508 | H2: =IFERROR(LEFT(AC2,FIND("'",AC2)-1)*12+SUBSTITUTE(MID(AC2,FIND("'",AC2)+1,LEN(AC2)),"''",""), "") -> 81 | I2: =AD2 -> 245 | J2: =IFERROR(LEFT(AE2,FIND("'",AE2)-1)*12+SUBSTITUTE(MID(AE2,FIND("'",AE2)+1,LEN(AE2)),"''",""), "") -> 85 | K2: =IFERROR(LEFT(AF2,FIND("'",AF2)-1)*12+SUBSTITUTE(MID(AF2,FIND("'",AF2)+1,LEN(AF2)),"''",""), "") | L2: =IFERROR(IF(AND(J2-H2>= 0, J2 > 0), "+", ""),"") & IFERROR(IF(AND(J2-H2>= -5, J2 > 0), J2-H2, ""),"") -> +4 | M2: =IF(H2>0, IFERROR((J2-60)/(H2-60),""), "") -> 1.1904762 | N2: defensive versatility | O2: finishing, playmaking as a big, motor, shooting | P2: may not be quite big enough to hang with elite Centers | R2: 57 | S2: 1 | T2: =IF(R2=R1,T1, MAX(T$1:T1)+1) -> 1 | U2: https://www.sports-reference.com/cbb/players/onyeka-okongwu-1.html | V2: https://www.nba.com/draft/2020/prospects/onyeka-okongwu#/ | W2: 36871 | X2: 3 | Y2: 5 | Z2: 1 | AA2: 5 | AB2: 5 | AC2: =IFERROR(INDEX('ringer measureables'!$A:$J,MATCH($A2,'ringer measureables'!$A:$A,FALSE),7), "") -> 6'9 | AD2: =IFERROR(INDEX('ringer measureables'!$A:$J,MATCH($A2,'ringer measureables'!$A:$A,FALSE),9), "") -> 245 | AE2: =IFERROR(INDEX('ringer measureables'!$A:$J,MATCH($A2,'ringer measureables'!$A:$A,FALSE),10), "") -> 7'1 | AF2: =IFERROR(INDEX('ringer measureables'!$A:$J,MATCH($A2,'ringer measureables'!$A:$A,FALSE),8), "") -> 0 | AG2: =AG1 & IF(T2=T1, "", IF(T2=1, " <!-- rankings --> ", " </ol> " ) & "<h2> Tier " & T2 & " (~" & IF(MOD(R2, 5)=0, R2, FLOOR(R2, 5) & "+") & " FV)</h2> <ol start='" & S2 & " '> " ) & " <li><b><a target='_blank' href='" & V2 & "'>" & A2 & "</a></b> - <i>" & B2 & " - <a target='_blank' href='" & U2 & "'>" & E2 & "</a></b> </i></li> <ul style='list-style-type:none'>" & IF(F2 <> "", " <li>Grade: " & F2 & " </li>", "") & IF(G2 <> "", " <li>Age: " & ROUND(G2,1) & " </li>", "") & IF(H2 <> "", " <li>Height: " & H2 & " in </li>", "") & IF(I2 <> "", " <li>Weight: " & I2 & " lbs </li>", "") & IF(J2 <> "", " <li>Wingspan: " & J2 & " in </li>", "") & IF(K2 <> "", " <li>Reach: " & K2 & " in </li>", "") & IF(L2 <> "", " <li>Ape: " & L2 & " </li>", "") & IF(N2 <> "", " <li>++: " & N2 & " </li>", "") & IF(O2 <> "", " <li>+: " & O2 & " </li>", "") & IF(P2 <> "", " <li>-: " & P2 & " </li>", "") & IF(Q2 <> "", " <li>--: " & Q2 & " </li>", "") & " </ul> <br>" & IF(T3="", " </ol> <!-- # end of rankings --> ", "") -> <!-- rankings --> <h2> Tier 1 (~55+ FV)</h2> <ol start='1 '> <li><b><a target='_blank' href='https://www.nba.com/draft/2020/prospects/onyeka-okongwu#/'>Onyeka Okongwu</a></b> - <i>PF - <a target='_blank' href='https://www.sports-reference.com/cbb/players/onyeka-okongwu-1.html'>USC</a></b> </i></li> <ul style='list-style-type:none'> <li>Grade: Freshman </li> <li>Age: 19.9 </li> <li>Height: 81 in </li> <li>Weight: 245 lbs </li> <li>Wingspan: 85 in </li> <li>Ape: +4 </li> <li>++: defensive versatility </li> <li>+: finishing, playmaking as a big, motor, shooting </li> <li>-: may not be quite big enough to hang with elite Centers </li> </ul> <br>
A3: LaMelo Ball | B3: PG | C3: =IFERROR(INDEX(actual!A:A,MATCH(A3,actual!B:B,FALSE)), "") -> 3 | D3: =IFERROR(INDEX(actual!C:C,MATCH(A3,actual!B:B,FALSE)), "") -> CHA | E3: Illawarra Hawks (Australia) | G3: =YEARFRAC(W3, $G$1, 1) -> 19.241615 | H3: =IFERROR(LEFT(AC3,FIND("'",AC3)-1)*12+SUBSTITUTE(MID(AC3,FIND("'",AC3)+1,LEN(AC3)),"''",""), "") -> 79 | I3: =AD3 -> 190 | J3: =IFERROR(LEFT(AE3,FIND("'",AE3)-1)*12+SUBSTITUTE(MID(AE3,FIND("'",AE3)+1,LEN(AE3)),"''",""), "") -> 82 | K3: =IFERROR(LEFT(AF3,FIND("'",AF3)-1)*12+SUBSTITUTE(MID(AF3,FIND("'",AF3)+1,LEN(AF3)),"''",""), "") | L3: =IFERROR(IF(AND(J3-H3>= 0, J3 > 0), "+", ""),"") & IFERROR(IF(AND(J3-H3>= -5, J3 > 0), J3-H3, ""),"") -> +3 | M3: =IF(H3>0, IFERROR((J3-60)/(H3-60),""), "") -> 1.1578947 | N3: age, primary ball handling, passing | O3: size, rebounding | P3: effort, decision making | Q3: finishing, shot selection | R3: 57 | S3: 2 | T3: =IF(R3=R2,T2, MAX(T$1:T2)+1) -> 1 | U3: https://www.basketball-reference.com/international/players/lamelo-ball-1.html | V3: https://www.nba.com/draft/2020/prospects/lamelo-ball#/ | W3: 37125 | X3: 2 | Y3: 3 | Z3: 4 | AA3: 1 | AB3: 1 | AC3: =IFERROR(INDEX('ringer measureables'!$A:$J,MATCH($A3,'ringer measureables'!$A:$A,FALSE),7), "") -> 6'7 | AD3: =IFERROR(INDEX('ringer measureables'!$A:$J,MATCH($A3,'ringer measureables'!$A:$A,FALSE),9), "") -> 190 | AE3: =IFERROR(INDEX('ringer measureables'!$A:$J,MATCH($A3,'ringer measureables'!$A:$A,FALSE),10), "") -> 6'10 | AF3: =IFERROR(INDEX('ringer measureables'!$A:$J,MATCH($A3,'ringer measureables'!$A:$A,FALSE),8), "") -> 0 | AG3: =AG2 & IF(T3=T2, "", IF(T3=1, " <!-- rankings --> ", " </ol> " ) & "<h2> Tier " & T3 & " (~" & IF(MOD(R3, 5)=0, R3, FLOOR(R3, 5) & "+") & " FV)</h2> <ol start='" & S3 & " '> " ) & " <li><b><a target='_blank' href='" & V3 & "'>" & A3 & "</a></b> - <i>" & B3 & " - <a target='_blank' href='" & U3 & "'>" & E3 & "</a></b> </i></li> <ul style='list-style-type:none'>" & IF(F3 <> "", " <li>Grade: " & F3 & " </li>", "") & IF(G3 <> "", " <li>Age: " & ROUND(G3,1) & " </li>", "") & IF(H3 <> "", " <li>Height: " & H3 & " in </li>", "") & IF(I3 <> "", " <li>Weight: " & I3 & " lbs </li>", "") & IF(J3 <> "", " <li>Wingspan: " & J3 & " in </li>", "") & IF(K3 <> "", " <li>Reach: " & K3 & " in </li>", "") & IF(L3 <> "", " <li>Ape: " & L3 & " </li>", "") & IF(N3 <> "", " <li>++: " & N3 & " </li>", "") & IF(O3 <> "", " <li>+: " & O3 & " </li>", "") & IF(P3 <> "", " <li>-: " & P3 & " </li>", "") & IF(Q3 <> "", " <li>--: " & Q3 & " </li>", "") & " </ul> <br>" & IF(T4="", " </ol> <!-- # end of rankings --> ", "") -> <!-- rankings --> <h2> Tier 1 (~55+ FV)</h2> <ol start='1 '> <li><b><a target='_blank' href='https://www.nba.com/draft/2020/prospects/onyeka-okongwu#/'>Onyeka Okongwu</a></b> - <i>PF - <a target='_blank' href='https://www.sports-reference.com/cbb/players/onyeka-okongwu-1.html'>USC</a></b> </i></li> <ul style='list-style-type:none'> <li>Grade: Freshman </li> <li>Age: 19.9 </li> <li>Height: 81 in </li> <li>Weight: 245 lbs </li> <li>Wingspan: 85 in </li> <li>Ape: +4 </li> <li>++: defensive versatility </li> <li>+: finishing, playmaking as a big, motor, shooting </li> <li>-: may not be quite big enough to hang with elite Centers </li> </ul> <br> <li><b><a target='_blank' href='https://www.nba.com/draft/2020/prospects/lamelo-ball#/'>LaMelo Ball</a></b> - <i>PG - <a target='_blank' href='https://www.basketball-reference.com/international/players/lamelo-ball-1.html'>Illawarra Hawks (Australia)</a></b> </i></li> <ul style='list-style-type:none'> <li>Age: 19.2 </li> <li>Height: 79 in </li> <li>Weight: 190 lbs </li> <li>Wingspan: 82 in </li> <li>Ape: +3 </li> <li>++: age, primary ball handling, passing </li> <li>+: size, rebounding </li> <li>-: effort, decision making </li> <li>--: finishing, shot selection </li> </ul> <br>
A4: Anthony Edwards | B4: SG | C4: =IFERROR(INDEX(actual!A:A,MATCH(A4,actual!B:B,FALSE)), "") -> 1 | D4: =IFERROR(INDEX(actual!C:C,MATCH(A4,actual!B:B,FALSE)), "") -> MIN | E4: Georgia | F4: Freshman | G4: =YEARFRAC(W4, $G$1, 1) -> 19.288159 | H4: =IFERROR(LEFT(AC4,FIND("'",AC4)-1)*12+SUBSTITUTE(MID(AC4,FIND("'",AC4)+1,LEN(AC4)),"''",""), "") -> 77 | I4: =AD4 -> 225 | J4: =IFERROR(LEFT(AE4,FIND("'",AE4)-1)*12+SUBSTITUTE(MID(AE4,FIND("'",AE4)+1,LEN(AE4)),"''",""), "") -> 81 | K4: =IFERROR(LEFT(AF4,FIND("'",AF4)-1)*12+SUBSTITUTE(MID(AF4,FIND("'",AF4)+1,LEN(AF4)),"''",""), "") | L4: =IFERROR(IF(AND(J4-H4>= 0, J4 > 0), "+", ""),"") & IFERROR(IF(AND(J4-H4>= -5, J4 > 0), J4-H4, ""),"") -> +4 | M4: =IF(H4>0, IFERROR((J4-60)/(H4-60),""), "") -> 1.2352941 | N4: age, strength, athleticism, frame | O4: ape, shot creation | P4: playmaking, effort, basketball IQ | Q4: shot selection | R4: 57 | S4: 3 | T4: =IF(R4=R3,T3, MAX(T$1:T3)+1) -> 1 | U4: https://www.sports-reference.com/cbb/players/anthony-edwards-2.html | V4: https://www.nba.com/draft/2020/prospects/atnhony-edwards#/ | W4: 37108 | X4: 2 | Y4: 2 | Z4: 3 | AA4: 3 | AB4: 2 | AC4: =IFERROR(INDEX('ringer measureables'!$A:$J,MATCH($A4,'ringer measureables'!$A:$A,FALSE),7), "") -> 6'5 | AD4: =IFERROR(INDEX('ringer measureables'!$A:$J,MATCH($A4,'ringer measureables'!$A:$A,FALSE),9), "") -> 225 | AE4: =IFERROR(INDEX('ringer measureables'!$A:$J,MATCH($A4,'ringer measureables'!$A:$A,FALSE),10), "") -> 6'9 | AF4: =IFERROR(INDEX('ringer measureables'!$A:$J,MATCH($A4,'ringer measureables'!$A:$A,FALSE),8), "") -> 0 | AG4: =AG3 & IF(T4=T3, "", IF(T4=1, " <!-- rankings --> ", " </ol> " ) & "<h2> Tier " & T4 & " (~" & IF(MOD(R4, 5)=0, R4, FLOOR(R4, 5) & "+") & " FV)</h2> <ol start='" & S4 & " '> " ) & " <li><b><a target='_blank' href='" & V4 & "'>" & A4 & "</a></b> - <i>" & B4 & " - <a target='_blank' href='" & U4 & "'>" & E4 & "</a></b> </i></li> <ul style='list-style-type:none'>" & IF(F4 <> "", " <li>Grade: " & F4 & " </li>", "") & IF(G4 <> "", " <li>Age: " & ROUND(G4,1) & " </li>", "") & IF(H4 <> "", " <li>Height: " & H4 & " in </li>", "") & IF(I4 <> "", " <li>Weight: " & I4 & " lbs </li>", "") & IF(J4 <> "", " <li>Wingspan: " & J4 & " in </li>", "") & IF(K4 <> "", " <li>Reach: " & K4 & " in </li>", "") & IF(L4 <> "", " <li>Ape: " & L4 & " </li>", "") & IF(N4 <> "", " <li>++: " & N4 & " </li>", "") & IF(O4 <> "", " <li>+: " & O4 & " </li>", "") & IF(P4 <> "", " <li>-: " & P4 & " </li>", "") & IF(Q4 <> "", " <li>--: " & Q4 & " </li>", "") & " </ul> <br>" & IF(T5="", " </ol> <!-- # end of rankings --> ", "") -> <!-- rankings --> <h2> Tier 1 (~55+ FV)</h2> <ol start='1 '> <li><b><a target='_blank' href='https://www.nba.com/draft/2020/prospects/onyeka-okongwu#/'>Onyeka Okongwu</a></b> - <i>PF - <a target='_blank' href='https://www.sports-reference.com/cbb/players/onyeka-okongwu-1.html'>USC</a></b> </i></li> <ul style='list-style-type:none'> <li>Grade: Freshman </li> <li>Age: 19.9 </li> <li>Height: 81 in </li> <li>Weight: 245 lbs </li> <li>Wingspan: 85 in </li> <li>Ape: +4 </li> <li>++: defensive versatility </li> <li>+: finishing, playmaking as a big, motor, shooting </li> <li>-: may not be quite big enough to hang with elite Centers </li> </ul> <br> <li><b><a target='_blank' href='https://www.nba.com/draft/2020/prospects/lamelo-ball#/'>LaMelo Ball</a></b> - <i>PG - <a target='_blank' href='https://www.basketball-reference.com/international/players/lamelo-ball-1.html'>Illawarra Hawks (Australia)</a></b> </i></li> <ul style='list-style-type:none'> <li>Age: 19.2 </li> <li>Height: 79 in </li> <li>Weight: 190 lbs </li> <li>Wingspan: 82 in </li> <li>Ape: +3 </li> <li>++: age, primary ball handling, passing </li> <li>+: size, rebounding </li> <li>-: effort, decision making </li> <li>--: finishing, shot selection </li> </ul> <br> <li><b><a target='_blank' href='https://www.nba.com/draft/2020/prospects/atnhony-edwards#/'>Anthony Edwards</a></b> - <i>SG - <a target='_blank' href='https://www.sports-reference.com/cbb/players/anthony-edwards-2.html'>Georgia</a></b> </i></li> <ul style='list-style-type:none'> <li>Grade: Freshman </li> <li>Age: 19.3 </li> <li>Height: 77 in </li> <li>Weight: 225 lbs </li> <li>Wingspan: 81 in </li> <li>Ape: +4 </li> <li>++: age, strength, athleticism, frame </li> <li>+: ape, shot creation </li> <li>-: playmaking, effort, basketball IQ </li> <li>--: shot selection </li> </ul> <br>
A5: James Wiseman | B5: C | C5: =IFERROR(INDEX(actual!A:A,MATCH(A5,actual!B:B,FALSE)), "") -> 2 | D5: =IFERROR(INDEX(actual!C:C,MATCH(A5,actual!B:B,FALSE)), "") -> GSW | E5: Memphis | F5: Freshman | G5: =YEARFRAC(W5, $G$1, 1) -> 19.635866 | H5: =IFERROR(LEFT(AC5,FIND("'",AC5)-1)*12+SUBSTITUTE(MID(AC5,FIND("'",AC5)+1,LEN(AC5)),"''",""), "") -> 85 | I5: =AD5 -> 237 | J5: =IFERROR(LEFT(AE5,FIND("'",AE5)-1)*12+SUBSTITUTE(MID(AE5,FIND("'",AE5)+1,LEN(AE5)),"''",""), "") -> 90 | K5: =IFERROR(LEFT(AF5,FIND("'",AF5)-1)*12+SUBSTITUTE(MID(AF5,FIND("'",AF5)+1,LEN(AF5)),"''",""), "") | L5: =IFERROR(IF(AND(J5-H5>= 0, J5 > 0), "+", ""),"") & IFERROR(IF(AND(J5-H5>= -5, J5 > 0), J5-H5, ""),"") -> +5 | M5: =IF(H5>0, IFERROR((J5-60)/(H5-60),""), "") -> 1.2 | N5: frame, athleticism | O5: age, rim running, rim protection | P5: shot selection, decision making | Q5: lack of data, competition, defensive reps | R5: 57 | S5: 4 | T5: =IF(R5=R4,T4, MAX(T$1:T4)+1) -> 1 | U5: https://www.sports-reference.com/cbb/players/james-wiseman-1.html | V5: https://www.nba.com/draft/2020/prospects/james-wiseman#/ | W5: 36981 | X5: 3 | Y5: 6 | Z5: 2 | AA5: 2 | AB5: 3 | AC5: =IFERROR(INDEX('ringer measureables'!$A:$J,MATCH($A5,'ringer measureables'!$A:$A,FALSE),7), "") -> 7'1 | AD5: =IFERROR(INDEX('ringer measureables'!$A:$J,MATCH($A5,'ringer measureables'!$A:$A,FALSE),9), "") -> 237 | AE5: =IFERROR(INDEX('ringer measureables'!$A:$J,MATCH($A5,'ringer measureables'!$A:$A,FALSE),10), "") -> 7'6 | AF5: =IFERROR(INDEX('ringer measureables'!$A:$J,MATCH($A5,'ringer measureables'!$A:$A,FALSE),8), "") -> 0 | AG5: =AG4 & IF(T5=T4, "", IF(T5=1, " <!-- rankings --> ", " </ol> " ) & "<h2> Tier " & T5 & " (~" & IF(MOD(R5, 5)=0, R5, FLOOR(R5, 5) & "+") & " FV)</h2> <ol start='" & S5 & " '> " ) & " <li><b><a target='_blank' href='" & V5 & "'>" & A5 & "</a></b> - <i>" & B5 & " - <a target='_blank' href='" & U5 & "'>" & E5 & "</a></b> </i></li> <ul style='list-style-type:none'>" & IF(F5 <> "", " <li>Grade: " & F5 & " </li>", "") & IF(G5 <> "", " <li>Age: " & ROUND(G5,1) & " </li>", "") & IF(H5 <> "", " <li>Height: " & H5 & " in </li>", "") & IF(I5 <> "", " <li>Weight: " & I5 & " lbs </li>", "") & IF(J5 <> "", " <li>Wingspan: " & J5 & " in </li>", "") & IF(K5 <> "", " <li>Reach: " & K5 & " in </li>", "") & IF(L5 <> "", " <li>Ape: " & L5 & " </li>", "") & IF(N5 <> "", " <li>++: " & N5 & " </li>", "") & IF(O5 <> "", " <li>+: " & O5 & " </li>", "") & IF(P5 <> "", " <li>-: " & P5 & " </li>", "") & IF(Q5 <> "", " <li>--: " & Q5 & " </li>", "") & " </ul> <br>" & IF(T6="", " </ol> <!-- # end of rankings --> ", "") -> <!-- rankings --> <h2> Tier 1 (~55+ FV)</h2> <ol start='1 '> <li><b><a target='_blank' href='https://www.nba.com/draft/2020/prospects/onyeka-okongwu#/'>Onyeka Okongwu</a></b> - <i>PF - <a target='_blank' href='https://www.sports-reference.com/cbb/players/onyeka-okongwu-1.html'>USC</a></b> </i></li> <ul style='list-style-type:none'> <li>Grade: Freshman </li> <li>Age: 19.9 </li> <li>Height: 81 in </li> <li>Weight: 245 lbs </li> <li>Wingspan: 85 in </li> <li>Ape: +4 </li> <li>++: defensive versatility </li> <li>+: finishing, playmaking as a big, motor, shooting </li> <li>-: may not be quite big enough to hang with elite Centers </li> </ul> <br> <li><b><a target='_blank' href='https://www.nba.com/draft/2020/prospects/lamelo-ball#/'>LaMelo Ball</a></b> - <i>PG - <a target='_blank' href='https://www.basketball-reference.com/international/players/lamelo-ball-1.html'>Illawarra Hawks (Australia)</a></b> </i></li> <ul style='list-style-type:none'> <li>Age: 19.2 </li> <li>Height: 79 in </li> <li>Weight: 190 lbs </li> <li>Wingspan: 82 in </li> <li>Ape: +3 </li> <li>++: age, primary ball handling, passing </li> <li>+: size, rebounding </li> <li>-: effort, decision making </li> <li>--: finishing, shot selection </li> </ul> <br> <li><b><a target='_blank' href='https://www.nba.com/draft/2020/prospects/atnhony-edwards#/'>Anthony Edwards</a></b> - <i>SG - <a target='_blank' href='https://www.sports-reference.com/cbb/players/anthony-edwards-2.html'>Georgia</a></b> </i></li> <ul style='list-style-type:none'> <li>Grade: Freshman </li> <li>Age: 19.3 </li> <li>Height: 77 in </li> <li>Weight: 225 lbs </li> <li>Wingspan: 81 in </li> <li>Ape: +4 </li> <li>++: age, strength, athleticism, frame </li> <li>+: ape, shot creation </li> <li>-: playmaking, effort, basketball IQ </li> <li>--: shot selection </li> </ul> <br> <li><b><a target='_blank' href='https://www.nba.com/draft/2020/prospects/james-wiseman#/'>James Wiseman</a></b> - <i>C - <a target='_blank' href='https://www.sports-reference.com/cbb/players/james-wiseman-1.html'>Memphis</a></b> </i></li> <ul style='list-style-type:none'> <li>Grade: Freshman </li> <li>Age: 19.6 </li> <li>Height: 85 in </li> <li>Weight: 237 lbs </li> <li>Wingspan: 90 in </li> <li>Ape: +5 </li> <li>++: frame, athleticism </li> <li>+: age, rim running, rim protection </li> <li>-: shot selection, decision making </li> <li>--: lack of data, competition, defensive reps </li> </ul> <br>
A6: Patrick Williams | B6: SF | C6: =IFERROR(INDEX(actual!A:A,MATCH(A6,actual!B:B,FALSE)), "") -> 4 | D6: =IFERROR(INDEX(actual!C:C,MATCH(A6,actual!B:B,FALSE)), "") -> CHI | E6: Florida State | F6: Freshman | G6: =YEARFRAC(W6, $G$1, 1) -> 19.285421 | H6: =IFERROR(LEFT(AC6,FIND("'",AC6)-1)*12+SUBSTITUTE(MID(AC6,FIND("'",AC6)+1,LEN(AC6)),"''",""), "") -> 80 | I6: =AD6 -> 225 | J6: =IFERROR(LEFT(AE6,FIND("'",AE6)-1)*12+SUBSTITUTE(MID(AE6,FIND("'",AE6)+1,LEN(AE6)),"''",""), "") -> 83 | K6: =IFERROR(LEFT(AF6,FIND("'",AF6)-1)*12+SUBSTITUTE(MID(AF6,FIND("'",AF6)+1,LEN(AF6)),"''",""), "") | L6: =IFERROR(IF(AND(J6-H6>= 0, J6 > 0), "+", ""),"") & IFERROR(IF(AND(J6-H6>= -5, J6 > 0), J6-H6, ""),"") -> +3 | M6: =IF(H6>0, IFERROR((J6-60)/(H6-60),""), "") -> 1.15 | N6: age | O6: off ball defense, free throw shooting, off ball offense | P6: turnover prone, horizontal athleticism | R6: 55 | S6: 5 | T6: =IF(R6=R5,T5, MAX(T$1:T5)+1) -> 2 | U6: https://www.sports-reference.com/cbb/players/patrick-williams-2.html | V6: https://www.nba.com/draft/2020/prospects/patrick-williams#/ | W6: 37109 | X6: 3 | Y6: 16 | AA6: 14 | AB6: 9 | AC6: =IFERROR(INDEX('ringer measureables'!$A:$J,MATCH($A6,'ringer measureables'!$A:$A,FALSE),7), "") -> 6'8 | AD6: =IFERROR(INDEX('ringer measureables'!$A:$J,MATCH($A6,'ringer measureables'!$A:$A,FALSE),9), "") -> 225 | AE6: =IFERROR(INDEX('ringer measureables'!$A:$J,MATCH($A6,'ringer measureables'!$A:$A,FALSE),10), "") -> 6'11 | AF6: =IFERROR(INDEX('ringer measureables'!$A:$J,MATCH($A6,'ringer measureables'!$A:$A,FALSE),8), "") -> 0 | AG6: =AG5 & IF(T6=T5, "", IF(T6=1, " <!-- rankings --> ", " </ol> " ) & "<h2> Tier " & T6 & " (~" & IF(MOD(R6, 5)=0, R6, FLOOR(R6, 5) & "+") & " FV)</h2> <ol start='" & S6 & " '> " ) & " <li><b><a target='_blank' href='" & V6 & "'>" & A6 & "</a></b> - <i>" & B6 & " - <a target='_blank' href='" & U6 & "'>" & E6 & "</a></b> </i></li> <ul style='list-style-type:none'>" & IF(F6 <> "", " <li>Grade: " & F6 & " </li>", "") & IF(G6 <> "", " <li>Age: " & ROUND(G6,1) & " </li>", "") & IF(H6 <> "", " <li>Height: " & H6 & " in </li>", "") & IF(I6 <> "", " <li>Weight: " & I6 & " lbs </li>", "") & IF(J6 <> "", " <li>Wingspan: " & J6 & " in </li>", "") & IF(K6 <> "", " <li>Reach: " & K6 & " in </li>", "") & IF(L6 <> "", " <li>Ape: " & L6 & " </li>", "") & IF(N6 <> "", " <li>++: " & N6 & " </li>", "") & IF(O6 <> "", " <li>+: " & O6 & " </li>", "") & IF(P6 <> "", " <li>-: " & P6 & " </li>", "") & IF(Q6 <> "", " <li>--: " & Q6 & " </li>", "") & " </ul> <br>" & IF(T7="", " </ol> <!-- # end of rankings --> ", "") -> <!-- rankings --> <h2> Tier 1 (~55+ FV)</h2> <ol start='1 '> <li><b><a target='_blank' href='https://www.nba.com/draft/2020/prospects/onyeka-okongwu#/'>Onyeka Okongwu</a></b> - <i>PF - <a target='_blank' href='https://www.sports-reference.com/cbb/players/onyeka-okongwu-1.html'>USC</a></b> </i></li> <ul style='list-style-type:none'> <li>Grade: Freshman </li> <li>Age: 19.9 </li> <li>Height: 81 in </li> <li>Weight: 245 lbs </li> <li>Wingspan: 85 in </li> <li>Ape: +4 </li> <li>++: defensive versatility </li> <li>+: finishing, playmaking as a big, motor, shooting </li> <li>-: may not be quite big enough to hang with elite Centers </li> </ul> <br> <li><b><a target='_blank' href='https://www.nba.com/draft/2020/prospects/lamelo-ball#/'>LaMelo Ball</a></b> - <i>PG - <a target='_blank' href='https://www.basketball-reference.com/international/players/lamelo-ball-1.html'>Illawarra Hawks (Australia)</a></b> </i></li> <ul style='list-style-type:none'> <li>Age: 19.2 </li> <li>Height: 79 in </li> <li>Weight: 190 lbs </li> <li>Wingspan: 82 in </li> <li>Ape: +3 </li> <li>++: age, primary ball handling, passing </li> <li>+: size, rebounding </li> <li>-: effort, decision making </li> <li>--: finishing, shot selection </li> </ul> <br> <li><b><a target='_blank' href='https://www.nba.com/draft/2020/prospects/atnhony-edwards#/'>Anthony Edwards</a></b> - <i>SG - <a target='_blank' href='https://www.sports-reference.com/cbb/players/anthony-edwards-2.html'>Georgia</a></b> </i></li> <ul style='list-style-type:none'> <li>Grade: Freshman </li> <li>Age: 19.3 </li> <li>Height: 77 in </li> <li>Weight: 225 lbs </li> <li>Wingspan: 81 in </li> <li>Ape: +4 </li> <li>++: age, strength, athleticism, frame </li> <li>+: ape, shot creation </li> <li>-: playmaking, effort, basketball IQ </li> <li>--: shot selection </li> </ul> <br> <li><b><a target='_blank' href='https://www.nba.com/draft/2020/prospects/james-wiseman#/'>James Wiseman</a></b> - <i>C - <a target='_blank' href='https://www.sports-reference.com/cbb/players/james-wiseman-1.html'>Memphis</a></b> </i></li> <ul style='list-style-type:none'> <li>Grade: Freshman </li> <li>Age: 19.6 </li> <li>Height: 85 in </li> <li>Weight: 237 lbs </li> <li>Wingspan: 90 in </li> <li>Ape: +5 </li> <li>++: frame, athleticism </li> <li>+: age, rim running, rim protection </li> <li>-: shot selection, decision making </li> <li>--: lack of data, competition, defensive reps </li> </ul> <br> </ol> <h2> Tier 2 (~55 FV)</h2> <ol start='5 '> <li><b><a target='_blank' href='https://www.nba.com/draft/2020/prospects/patrick-williams#/'>Patrick Williams</a></b> - <i>SF - <a target='_blank' href='https://www.sports-reference.com/cbb/players/patrick-williams-2.html'>Florida State</a></b> </i></li> <ul style='list-style-type:none'> <li>Grade: Freshman </li> <li>Age: 19.3 </li> <li>Height: 80 in </li> <li>Weight: 225 lbs </li> <li>Wingspan: 83 in </li> <li>Ape: +3 </li> <li>++: age </li> <li>+: off ball defense, free throw shooting, off ball offense </li> <li>-: turnover prone, horizontal athleticism </li> </ul> <br>
A7: Devin Vassell | B7: SF | C7: =IFERROR(INDEX(actual!A:A,MATCH(A7,actual!B:B,FALSE)), "") -> 11 | D7: =IFERROR(INDEX(actual!C:C,MATCH(A7,actual!B:B,FALSE)), "") -> SAS | E7: Florida State | F7: Sophomore | G7: =YEARFRAC(W7, $G$1, 1) -> 20.236214 | H7: =IFERROR(LEFT(AC7,FIND("'",AC7)-1)*12+SUBSTITUTE(MID(AC7,FIND("'",AC7)+1,LEN(AC7)),"''",""), "") -> 79 | I7: =AD7 -> 194 | J7: =IFERROR(LEFT(AE7,FIND("'",AE7)-1)*12+SUBSTITUTE(MID(AE7,FIND("'",AE7)+1,LEN(AE7)),"''",""), "") -> 82 | K7: =IFERROR(LEFT(AF7,FIND("'",AF7)-1)*12+SUBSTITUTE(MID(AF7,FIND("'",AF7)+1,LEN(AF7)),"''",""), "") | L7: =IFERROR(IF(AND(J7-H7>= 0, J7 > 0), "+", ""),"") & IFERROR(IF(AND(J7-H7>= -5, J7 > 0), J7-H7, ""),"") -> +3 | M7: =IF(H7>0, IFERROR((J7-60)/(H7-60),""), "") -> 1.1578947 | N7: age | O7: defensive motor, on ball defense, shot selection | P7: finishing, strength | R7: 55 | S7: 6 | T7: =IF(R7=R6,T6, MAX(T$1:T6)+1) -> 2 | U7: https://www.sports-reference.com/cbb/players/devin-vassell-1.html | V7: https://www.nba.com/draft/2020/prospects/devin-vassell#/ | W7: 36761 | X7: 3 | Y7: 7 | AA7: 11 | AB7: 11 | AC7: =IFERROR(INDEX('ringer measureables'!$A:$J,MATCH($A7,'ringer measureables'!$A:$A,FALSE),7), "") -> 6'7 | AD7: =IFERROR(INDEX('ringer measureables'!$A:$J,MATCH($A7,'ringer measureables'!$A:$A,FALSE),9), "") -> 194 | AE7: =IFERROR(INDEX('ringer measureables'!$A:$J,MATCH($A7,'ringer measureables'!$A:$A,FALSE),10), "") -> 6'10 | AF7: =IFERROR(INDEX('ringer measureables'!$A:$J,MATCH($A7,'ringer measureables'!$A:$A,FALSE),8), "") -> 0 | AG7: =AG6 & IF(T7=T6, "", IF(T7=1, " <!-- rankings --> ", " </ol> " ) & "<h2> Tier " & T7 & " (~" & IF(MOD(R7, 5)=0, R7, FLOOR(R7, 5) & "+") & " FV)</h2> <ol start='" & S7 & " '> " ) & " <li><b><a target='_blank' href='" & V7 & "'>" & A7 & "</a></b> - <i>" & B7 & " - <a target='_blank' href='" & U7 & "'>" & E7 & "</a></b> </i></li> <ul style='list-style-type:none'>" & IF(F7 <> "", " <li>Grade: " & F7 & " </li>", "") & IF(G7 <> "", " <li>Age: " & ROUND(G7,1) & " </li>", "") & IF(H7 <> "", " <li>Height: " & H7 & " in </li>", "") & IF(I7 <> "", " <li>Weight: " & I7 & " lbs </li>", "") & IF(J7 <> "", " <li>Wingspan: " & J7 & " in </li>", "") & IF(K7 <> "", " <li>Reach: " & K7 & " in </li>", "") & IF(L7 <> "", " <li>Ape: " & L7 & " </li>", "") & IF(N7 <> "", " <li>++: " & N7 & " </li>", "") & IF(O7 <> "", " <li>+: " & O7 & " </li>", "") & IF(P7 <> "", " <li>-: " & P7 & " </li>", "") & IF(Q7 <> "", " <li>--: " & Q7 & " </li>", "") & " </ul> <br>" & IF(T8="", " </ol> <!-- # end of rankings --> ", "") -> <!-- rankings --> <h2> Tier 1 (~55+ FV)</h2> <ol start='1 '> <li><b><a target='_blank' href='https://www.nba.com/draft/2020/prospects/onyeka-okongwu#/'>Onyeka Okongwu</a></b> - <i>PF - <a target='_blank' href='https://www.sports-reference.com/cbb/players/onyeka-okongwu-1.html'>USC</a></b> </i></li> <ul style='list-style-type:none'> <li>Grade: Freshman </li> <li>Age: 19.9 </li> <li>Height: 81 in </li> <li>Weight: 245 lbs </li> <li>Wingspan: 85 in </li> <li>Ape: +4 </li> <li>++: defensive versatility </li> <li>+: finishing, playmaking as a big, motor, shooting </li> <li>-: may not be quite big enough to hang with elite Centers </li> </ul> <br> <li><b><a target='_blank' href='https://www.nba.com/draft/2020/prospects/lamelo-ball#/'>LaMelo Ball</a></b> - <i>PG - <a target='_blank' href='https://www.basketball-reference.com/international/players/lamelo-ball-1.html'>Illawarra Hawks (Australia)</a></b> </i></li> <ul style='list-style-type:none'> <li>Age: 19.2 </li> <li>Height: 79 in </li> <li>Weight: 190 lbs </li> <li>Wingspan: 82 in </li> <li>Ape: +3 </li> <li>++: age, primary ball handling, passing </li> <li>+: size, rebounding </li> <li>-: effort, decision making </li> <li>--: finishing, shot selection </li> </ul> <br> <li><b><a target='_blank' href='https://www.nba.com/draft/2020/prospects/atnhony-edwards#/'>Anthony Edwards</a></b> - <i>SG - <a target='_blank' href='https://www.sports-reference.com/cbb/players/anthony-edwards-2.html'>Georgia</a></b> </i></li> <ul style='list-style-type:none'> <li>Grade: Freshman </li> <li>Age: 19.3 </li> <li>Height: 77 in </li> <li>Weight: 225 lbs </li> <li>Wingspan: 81 in </li> <li>Ape: +4 </li> <li>++: age, strength, athleticism, frame </li> <li>+: ape, shot creation </li> <li>-: playmaking, effort, basketball IQ </li> <li>--: shot selection </li> </ul> <br> <li><b><a target='_blank' href='https://www.nba.com/draft/2020/prospects/james-wiseman#/'>James Wiseman</a></b> - <i>C - <a target='_blank' href='https://www.sports-reference.com/cbb/players/james-wiseman-1.html'>Memphis</a></b> </i></li> <ul style='list-style-type:none'> <li>Grade: Freshman </li> <li>Age: 19.6 </li> <li>Height: 85 in </li> <li>Weight: 237 lbs </li> <li>Wingspan: 90 in </li> <li>Ape: +5 </li> <li>++: frame, athleticism </li> <li>+: age, rim running, rim protection </li> <li>-: shot selection, decision making </li> <li>--: lack of data, competition, defensive reps </li> </ul> <br> </ol> <h2> Tier 2 (~55 FV)</h2> <ol start='5 '> <li><b><a target='_blank' href='https://www.nba.com/draft/2020/prospects/patrick-williams#/'>Patrick Williams</a></b> - <i>SF - <a target='_blank' href='https://www.sports-reference.com/cbb/players/patrick-williams-2.html'>Florida State</a></b> </i></li> <ul style='list-style-type:none'> <li>Grade: Freshman </li> <li>Age: 19.3 </li> <li>Height: 80 in </li> <li>Weight: 225 lbs </li> <li>Wingspan: 83 in </li> <li>Ape: +3 </li> <li>++: age </li> <li>+: off ball defense, free throw shooting, off ball offense </li> <li>-: turnover prone, horizontal athleticism </li> </ul> <br> <li><b><a target='_blank' href='https://www.nba.com/draft/2020/prospects/devin-vassell#/'>Devin Vassell</a></b> - <i>SF - <a target='_blank' href='https://www.sports-reference.com/cbb/players/devin-vassell-1.html'>Florida State</a></b> </i></li> <ul style='list-style-type:none'> <li>Grade: Sophomore </li> <li>Age: 20.2 </li> <li>Height: 79 in </li> <li>Weight: 194 lbs </li> <li>Wingspan: 82 in </li> <li>Ape: +3 </li> <li>++: age </li> <li>+: defensive motor, on ball defense, shot selection </li> <li>-: finishing, strength </li> </ul> <br>
A8: Killian Hayes | B8: PG | C8: =IFERROR(INDEX(actual!A:A,MATCH(A8,actual!B:B,FALSE)), "") -> 7 | D8: =IFERROR(INDEX(actual!C:C,MATCH(A8,actual!B:B,FALSE)), "") -> DET | E8: Ratiopharm (Germany) | G8: =YEARFRAC(W8, $G$1, 1) -> 19.312799 | H8: =IFERROR(LEFT(AC8,FIND("'",AC8)-1)*12+SUBSTITUTE(MID(AC8,FIND("'",AC8)+1,LEN(AC8)),"''",""), "") -> 77 | I8: =AD8 -> 215 | J8: =IFERROR(LEFT(AE8,FIND("'",AE8)-1)*12+SUBSTITUTE(MID(AE8,FIND("'",AE8)+1,LEN(AE8)),"''",""), "") -> 80.25 | K8: =IFERROR(LEFT(AF8,FIND("'",AF8)-1)*12+SUBSTITUTE(MID(AF8,FIND("'",AF8)+1,LEN(AF8)),"''",""), "") | L8: =IFERROR(IF(AND(J8-H8>= 0, J8 > 0), "+", ""),"") & IFERROR(IF(AND(J8-H8>= -5, J8 > 0), J8-H8, ""),"") -> +3.25 | M8: =IF(H8>0, IFERROR((J8-60)/(H8-60),""), "") -> 1.1911765 | N8: age | O8: size, shot creation/playmaking, shooting | P8: athleticism, driving, right hand dominance | R8: 52 | S8: 7 | T8: =IF(R8=R7,T7, MAX(T$1:T7)+1) -> 3 | U8: https://www.basketball-reference.com/international/players/killian-hayes-1.html | V8: https://www.nba.com/draft/2020/prospects/killian-hayes#/ | W8: 37099 | X8: 3 | Y8: 1 | AA8: 9 | AB8: 10 | AC8: =IFERROR(INDEX('ringer measureables'!$A:$J,MATCH($A8,'ringer measureables'!$A:$A,FALSE),7), "") -> 6'5 | AD8: =IFERROR(INDEX('ringer measureables'!$A:$J,MATCH($A8,'ringer measureables'!$A:$A,FALSE),9), "") -> 215 | AE8: =IFERROR(INDEX('ringer measureables'!$A:$J,MATCH($A8,'ringer measureables'!$A:$A,FALSE),10), "") -> 6'8.25 | AF8: =IFERROR(INDEX('ringer measureables'!$A:$J,MATCH($A8,'ringer measureables'!$A:$A,FALSE),8), "") -> 0 | AG8: =AG7 & IF(T8=T7, "", IF(T8=1, " <!-- rankings --> ", " </ol> " ) & "<h2> Tier " & T8 & " (~" & IF(MOD(R8, 5)=0, R8, FLOOR(R8, 5) & "+") & " FV)</h2> <ol start='" & S8 & " '> " ) & " <li><b><a target='_blank' href='" & V8 & "'>" & A8 & "</a></b> - <i>" & B8 & " - <a target='_blank' href='" & U8 & "'>" & E8 & "</a></b> </i></li> <ul style='list-style-type:none'>" & IF(F8 <> "", " <li>Grade: " & F8 & " </li>", "") & IF(G8 <> "", " <li>Age: " & ROUND(G8,1) & " </li>", "") & IF(H8 <> "", " <li>Height: " & H8 & " in </li>", "") & IF(I8 <> "", " <li>Weight: " & I8 & " lbs </li>", "") & IF(J8 <> "", " <li>Wingspan: " & J8 & " in </li>", "") & IF(K8 <> "", " <li>Reach: " & K8 & " in </li>", "") & IF(L8 <> "", " <li>Ape: " & L8 & " </li>", "") & IF(N8 <> "", " <li>++: " & N8 & " </li>", "") & IF(O8 <> "", " <li>+: " & O8 & " </li>", "") & IF(P8 <> "", " <li>-: " & P8 & " </li>", "") & IF(Q8 <> "", " <li>--: " & Q8 & " </li>", "") & " </ul> <br>" & IF(T9="", " </ol> <!-- # end of rankings --> ", "") -> <!-- rankings --> <h2> Tier 1 (~55+ FV)</h2> <ol start='1 '> <li><b><a target='_blank' href='https://www.nba.com/draft/2020/prospects/onyeka-okongwu#/'>Onyeka Okongwu</a></b> - <i>PF - <a target='_blank' href='https://www.sports-reference.com/cbb/players/onyeka-okongwu-1.html'>USC</a></b> </i></li> <ul style='list-style-type:none'> <li>Grade: Freshman </li> <li>Age: 19.9 </li> <li>Height: 81 in </li> <li>Weight: 245 lbs </li> <li>Wingspan: 85 in </li> <li>Ape: +4 </li> <li>++: defensive versatility </li> <li>+: finishing, playmaking as a big, motor, shooting </li> <li>-: may not be quite big enough to hang with elite Centers </li> </ul> <br> <li><b><a target='_blank' href='https://www.nba.com/draft/2020/prospects/lamelo-ball#/'>LaMelo Ball</a></b> - <i>PG - <a target='_blank' href='https://www.basketball-reference.com/international/players/lamelo-ball-1.html'>Illawarra Hawks (Australia)</a></b> </i></li> <ul style='list-style-type:none'> <li>Age: 19.2 </li> <li>Height: 79 in </li> <li>Weight: 190 lbs </li> <li>Wingspan: 82 in </li> <li>Ape: +3 </li> <li>++: age, primary ball handling, passing </li> <li>+: size, rebounding </li> <li>-: effort, decision making </li> <li>--: finishing, shot selection </li> </ul> <br> <li><b><a target='_blank' href='https://www.nba.com/draft/2020/prospects/atnhony-edwards#/'>Anthony Edwards</a></b> - <i>SG - <a target='_blank' href='https://www.sports-reference.com/cbb/players/anthony-edwards-2.html'>Georgia</a></b> </i></li> <ul style='list-style-type:none'> <li>Grade: Freshman </li> <li>Age: 19.3 </li> <li>Height: 77 in </li> <li>Weight: 225 lbs </li> <li>Wingspan: 81 in </li> <li>Ape: +4 </li> <li>++: age, strength, athleticism, frame </li> <li>+: ape, shot creation </li> <li>-: playmaking, effort, basketball IQ </li> <li>--: shot selection </li> </ul> <br> <li><b><a target='_blank' href='https://www.nba.com/draft/2020/prospects/james-wiseman#/'>James Wiseman</a></b> - <i>C - <a target='_blank' href='https://www.sports-reference.com/cbb/players/james-wiseman-1.html'>Memphis</a></b> </i></li> <ul style='list-style-type:none'> <li>Grade: Freshman </li> <li>Age: 19.6 </li> <li>Height: 85 in </li> <li>Weight: 237 lbs </li> <li>Wingspan: 90 in </li> <li>Ape: +5 </li> <li>++: frame, athleticism </li> <li>+: age, rim running, rim protection </li> <li>-: shot selection, decision making </li> <li>--: lack of data, competition, defensive reps </li> </ul> <br> </ol> <h2> Tier 2 (~55 FV)</h2> <ol start='5 '> <li><b><a target='_blank' href='https://www.nba.com/draft/2020/prospects/patrick-williams#/'>Patrick Williams</a></b> - <i>SF - <a target='_blank' href='https://www.sports-reference.com/cbb/players/patrick-williams-2.html'>Florida State</a></b> </i></li> <ul style='list-style-type:none'> <li>Grade: Freshman </li> <li>Age: 19.3 </li> <li>Height: 80 in </li> <li>Weight: 225 lbs </li> <li>Wingspan: 83 in </li> <li>Ape: +3 </li> <li>++: age </li> <li>+: off ball defense, free throw shooting, off ball offense </li> <li>-: turnover prone, horizontal athleticism </li> </ul> <br> <li><b><a target='_blank' href='https://www.nba.com/draft/2020/prospects/devin-vassell#/'>Devin Vassell</a></b> - <i>SF - <a target='_blank' href='https://www.sports-reference.com/cbb/players/devin-vassell-1.html'>Florida State</a></b> </i></li> <ul style='list-style-type:none'> <li>Grade: Sophomore </li> <li>Age: 20.2 </li> <li>Height: 79 in </li> <li>Weight: 194 lbs </li> <li>Wingspan: 82 in </li> <li>Ape: +3 </li> <li>++: age </li> <li>+: defensive motor, on ball defense, shot selection </li> <li>-: finishing, strength </li> </ul> <br> </ol> <h2> Tier 3 (~50+ FV)</h2> <ol start='7 '> <li><b><a target='_blank' href='https://www.nba.com/draft/2020/prospects/killian-hayes#/'>Killian Hayes</a></b> - <i>PG - <a target='_blank' href='https://www.basketball-reference.com/international/players/killian-hayes-1.html'>Ratiopharm (Germany)</a></b> </i></li> <ul style='list-style-type:none'> <li>Age: 19.3 </li> <li>Height: 77 in </li> <li>Weight: 215 lbs </li> <li>Wingspan: 80.25 in </li> <li>Ape: +3.25 </li> <li>++: age </li> <li>+: size, shot creation/playmaking, shooting </li> <li>-: athleticism, driving, right hand dominance </li> </ul> <br>
A9: Kira Lewis Jr. | B9: PG | C9: =IFERROR(INDEX(actual!A:A,MATCH(A9,actual!B:B,FALSE)), "") -> 13 | D9: =IFERROR(INDEX(actual!C:C,MATCH(A9,actual!B:B,FALSE)), "") -> NOP | E9: Alabama | F9: Sophomore | G9: =YEARFRAC(W9, $G$1, 1) -> 19.619439 | H9: =IFERROR(LEFT(AC9,FIND("'",AC9)-1)*12+SUBSTITUTE(MID(AC9,FIND("'",AC9)+1,LEN(AC9)),"''",""), "") -> 75 | I9: =AD9 -> 165 | J9: =IFERROR(LEFT(AE9,FIND("'",AE9)-1)*12+SUBSTITUTE(MID(AE9,FIND("'",AE9)+1,LEN(AE9)),"''",""), "") -> 78 | K9: =IFERROR(LEFT(AF9,FIND("'",AF9)-1)*12+SUBSTITUTE(MID(AF9,FIND("'",AF9)+1,LEN(AF9)),"''",""), "") | L9: =IFERROR(IF(AND(J9-H9>= 0, J9 > 0), "+", ""),"") & IFERROR(IF(AND(J9-H9>= -5, J9 > 0), J9-H9, ""),"") -> +3 | M9: =IF(H9>0, IFERROR((J9-60)/(H9-60),""), "") -> 1.2 | N9: age | O9: shooting, shot creation, pick-and-roll ability | P9: defensive versatility, playmaking, frame | R9: 52 | S9: 8 | T9: =IF(R9=R8,T8, MAX(T$1:T8)+1) -> 3 | U9: https://www.sports-reference.com/cbb/players/kira-lewisjr-1.html | V9: https://www.nba.com/draft/2020/prospects/kira-lewis#/ | W9: 36987 | X9: 3 | Y9: 14 | AA9: 12 | AB9: 20 | AC9: =IFERROR(INDEX('ringer measureables'!$A:$J,MATCH($A9,'ringer measureables'!$A:$A,FALSE),7), "") -> 6'3 | AD9: =IFERROR(INDEX('ringer measureables'!$A:$J,MATCH($A9,'ringer measureables'!$A:$A,FALSE),9), "") -> 165 | AE9: =IFERROR(INDEX('ringer measureables'!$A:$J,MATCH($A9,'ringer measureables'!$A:$A,FALSE),10), "") -> 6'6 | AF9: =IFERROR(INDEX('ringer measureables'!$A:$J,MATCH($A9,'ringer measureables'!$A:$A,FALSE),8), "") -> 0 | AG9: =AG8 & IF(T9=T8, "", IF(T9=1, " <!-- rankings --> ", " </ol> " ) & "<h2> Tier " & T9 & " (~" & IF(MOD(R9, 5)=0, R9, FLOOR(R9, 5) & "+") & " FV)</h2> <ol start='" & S9 & " '> " ) & " <li><b><a target='_blank' href='" & V9 & "'>" & A9 & "</a></b> - <i>" & B9 & " - <a target='_blank' href='" & U9 & "'>" & E9 & "</a></b> </i></li> <ul style='list-style-type:none'>" & IF(F9 <> "", " <li>Grade: " & F9 & " </li>", "") & IF(G9 <> "", " <li>Age: " & ROUND(G9,1) & " </li>", "") & IF(H9 <> "", " <li>Height: " & H9 & " in </li>", "") & IF(I9 <> "", " <li>Weight: " & I9 & " lbs </li>", "") & IF(J9 <> "", " <li>Wingspan: " & J9 & " in </li>", "") & IF(K9 <> "", " <li>Reach: " & K9 & " in </li>", "") & IF(L9 <> "", " <li>Ape: " & L9 & " </li>", "") & IF(N9 <> "", " <li>++: " & N9 & " </li>", "") & IF(O9 <> "", " <li>+: " & O9 & " </li>", "") & IF(P9 <> "", " <li>-: " & P9 & " </li>", "") & IF(Q9 <> "", " <li>--: " & Q9 & " </li>", "") & " </ul> <br>" & IF(T10="", " </ol> <!-- # end of rankings --> ", "") -> <!-- rankings --> <h2> Tier 1 (~55+ FV)</h2> <ol start='1 '> <li><b><a target='_blank' href='https://www.nba.com/draft/2020/prospects/onyeka-okongwu#/'>Onyeka Okongwu</a></b> - <i>PF - <a target='_blank' href='https://www.sports-reference.com/cbb/players/onyeka-okongwu-1.html'>USC</a></b> </i></li> <ul style='list-style-type:none'> <li>Grade: Freshman </li> <li>Age: 19.9 </li> <li>Height: 81 in </li> <li>Weight: 245 lbs </li> <li>Wingspan: 85 in </li> <li>Ape: +4 </li> <li>++: defensive versatility </li> <li>+: finishing, playmaking as a big, motor, shooting </li> <li>-: may not be quite big enough to hang with elite Centers </li> </ul> <br> <li><b><a target='_blank' href='https://www.nba.com/draft/2020/prospects/lamelo-ball#/'>LaMelo Ball</a></b> - <i>PG - <a target='_blank' href='https://www.basketball-reference.com/international/players/lamelo-ball-1.html'>Illawarra Hawks (Australia)</a></b> </i></li> <ul style='list-style-type:none'> <li>Age: 19.2 </li> <li>Height: 79 in </li> <li>Weight: 190 lbs </li> <li>Wingspan: 82 in </li> <li>Ape: +3 </li> <li>++: age, primary ball handling, passing </li> <li>+: size, rebounding </li> <li>-: effort, decision making </li> <li>--: finishing, shot selection </li> </ul> <br> <li><b><a target='_blank' href='https://www.nba.com/draft/2020/prospects/atnhony-edwards#/'>Anthony Edwards</a></b> - <i>SG - <a target='_blank' href='https://www.sports-reference.com/cbb/players/anthony-edwards-2.html'>Georgia</a></b> </i></li> <ul style='list-style-type:none'> <li>Grade: Freshman </li> <li>Age: 19.3 </li> <li>Height: 77 in </li> <li>Weight: 225 lbs </li> <li>Wingspan: 81 in </li> <li>Ape: +4 </li> <li>++: age, strength, athleticism, frame </li> <li>+: ape, shot creation </li> <li>-: playmaking, effort, basketball IQ </li> <li>--: shot selection </li> </ul> <br> <li><b><a target='_blank' href='https://www.nba.com/draft/2020/prospects/james-wiseman#/'>James Wiseman</a></b> - <i>C - <a target='_blank' href='https://www.sports-reference.com/cbb/players/james-wiseman-1.html'>Memphis</a></b> </i></li> <ul style='list-style-type:none'> <li>Grade: Freshman </li> <li>Age: 19.6 </li> <li>Height: 85 in </li> <li>Weight: 237 lbs </li> <li>Wingspan: 90 in </li> <li>Ape: +5 </li> <li>++: frame, athleticism </li> <li>+: age, rim running, rim protection </li> <li>-: shot selection, decision making </li> <li>--: lack of data, competition, defensive reps </li> </ul> <br> </ol> <h2> Tier 2 (~55 FV)</h2> <ol start='5 '> <li><b><a target='_blank' href='https://www.nba.com/draft/2020/prospects/patrick-williams#/'>Patrick Williams</a></b> - <i>SF - <a target='_blank' href='https://www.sports-reference.com/cbb/players/patrick-williams-2.html'>Florida State</a></b> </i></li> <ul style='list-style-type:none'> <li>Grade: Freshman </li> <li>Age: 19.3 </li> <li>Height: 80 in </li> <li>Weight: 225 lbs </li> <li>Wingspan: 83 in </li> <li>Ape: +3 </li> <li>++: age </li> <li>+: off ball defense, free throw shooting, off ball offense </li> <li>-: turnover prone, horizontal athleticism </li> </ul> <br> <li><b><a target='_blank' href='https://www.nba.com/draft/2020/prospects/devin-vassell#/'>Devin Vassell</a></b> - <i>SF - <a target='_blank' href='https://www.sports-reference.com/cbb/players/devin-vassell-1.html'>Florida State</a></b> </i></li> <ul style='list-style-type:none'> <li>Grade: Sophomore </li> <li>Age: 20.2 </li> <li>Height: 79 in </li> <li>Weight: 194 lbs </li> <li>Wingspan: 82 in </li> <li>Ape: +3 </li> <li>++: age </li> <li>+: defensive motor, on ball defense, shot selection </li> <li>-: finishing, strength </li> </ul> <br> </ol> <h2> Tier 3 (~50+ FV)</h2> <ol start='7 '> <li><b><a target='_blank' href='https://www.nba.com/draft/2020/prospects/killian-hayes#/'>Killian Hayes</a></b> - <i>PG - <a target='_blank' href='https://www.basketball-reference.com/international/players/killian-hayes-1.html'>Ratiopharm (Germany)</a></b> </i></li> <ul style='list-style-type:none'> <li>Age: 19.3 </li> <li>Height: 77 in </li> <li>Weight: 215 lbs </li> <li>Wingspan: 80.25 in </li> <li>Ape: +3.25 </li> <li>++: age </li> <li>+: size, shot creation/playmaking, shooting </li> <li>-: athleticism, driving, right hand dominance </li> </ul> <br> <li><b><a target='_blank' href='https://www.nba.com/draft/2020/prospects/kira-lewis#/'>Kira Lewis Jr.</a></b> - <i>PG - <a target='_blank' href='https://www.sports-reference.com/cbb/players/kira-lewisjr-1.html'>Alabama</a></b> </i></li> <ul style='list-style-type:none'> <li>Grade: Sophomore </li> <li>Age: 19.6 </li> <li>Height: 75 in </li> <li>Weight: 165 lbs </li> <li>Wingspan: 78 in </li> <li>Ape: +3 </li> <li>++: age </li> <li>+: shooting, shot creation, pick-and-roll ability </li> <li>-: defensive versatility, playmaking, frame </li> </ul> <br>
A10: Tyrese Haliburton | B10: PG | C10: =IFERROR(INDEX(actual!A:A,MATCH(A10,actual!B:B,FALSE)), "") -> 12 | D10: =IFERROR(INDEX(actual!C:C,MATCH(A10,actual!B:B,FALSE)), "") -> SAC | E10: Iowa State | F10: Sophomore | G10: =YEARFRAC(W10, $G$1, 1) -> 20.718029 | H10: =IFERROR(LEFT(AC10,FIND("'",AC10)-1)*12+SUBSTITUTE(MID(AC10,FIND("'",AC10)+1,LEN(AC10)),"''",""), "") -> 77 | I10: =AD10 -> 175 | J10: =IFERROR(LEFT(AE10,FIND("'",AE10)-1)*12+SUBSTITUTE(MID(AE10,FIND("'",AE10)+1,LEN(AE10)),"''",""), "") -> 80 | K10: =IFERROR(LEFT(AF10,FIND("'",AF10)-1)*12+SUBSTITUTE(MID(AF10,FIND("'",AF10)+1,LEN(AF10)),"''",""), "") | L10: =IFERROR(IF(AND(J10-H10>= 0, J10 > 0), "+", ""),"") & IFERROR(IF(AND(J10-H10>= -5, J10 > 0), J10-H10, ""),"") -> +3 | M10: =IF(H10>0, IFERROR((J10-60)/(H10-60),""), "") -> 1.1764706 | O10: basketball IQ, shot selection, playmaking | P10: athleticsm, shot creation, interior offense | R10: 52 | S10: 9 | T10: =IF(R10=R9,T9, MAX(T$1:T9)+1) -> 3 | U10: https://www.sports-reference.com/cbb/players/tyrese-haliburton-1.html | V10: https://www.nba.com/draft/2020/prospects/tyrese-haliburton#/ | W10: 36585 | X10: 4 | Y10: 10 | AA10: 8 | AB10: 8 | AC10: =IFERROR(INDEX('ringer measureables'!$A:$J,MATCH($A10,'ringer measureables'!$A:$A,FALSE),7), "") -> 6'5 | AD10: =IFERROR(INDEX('ringer measureables'!$A:$J,MATCH($A10,'ringer measureables'!$A:$A,FALSE),9), "") -> 175 | AE10: =IFERROR(INDEX('ringer measureables'!$A:$J,MATCH($A10,'ringer measureables'!$A:$A,FALSE),10), "") -> 6'8 | AF10: =IFERROR(INDEX('ringer measureables'!$A:$J,MATCH($A10,'ringer measureables'!$A:$A,FALSE),8), "") -> 0 | AG10: =AG9 & IF(T10=T9, "", IF(T10=1, " <!-- rankings --> ", " </ol> " ) & "<h2> Tier " & T10 & " (~" & IF(MOD(R10, 5)=0, R10, FLOOR(R10, 5) & "+") & " FV)</h2> <ol start='" & S10 & " '> " ) & " <li><b><a target='_blank' href='" & V10 & "'>" & A10 & "</a></b> - <i>" & B10 & " - <a target='_blank' href='" & U10 & "'>" & E10 & "</a></b> </i></li> <ul style='list-style-type:none'>" & IF(F10 <> "", " <li>Grade: " & F10 & " </li>", "") & IF(G10 <> "", " <li>Age: " & ROUND(G10,1) & " </li>", "") & IF(H10 <> "", " <li>Height: " & H10 & " in </li>", "") & IF(I10 <> "", " <li>Weight: " & I10 & " lbs </li>", "") & IF(J10 <> "", " <li>Wingspan: " & J10 & " in </li>", "") & IF(K10 <> "", " <li>Reach: " & K10 & " in </li>", "") & IF(L10 <> "", " <li>Ape: " & L10 & " </li>", "") & IF(N10 <> "", " <li>++: " & N10 & " </li>", "") & IF(O10 <> "", " <li>+: " & O10 & " </li>", "") & IF(P10 <> "", " <li>-: " & P10 & " </li>", "") & IF(Q10 <> "", " <li>--: " & Q10 & " </li>", "") & " </ul> <br>" & IF(T11="", " </ol> <!-- # end of rankings --> ", "") -> <!-- rankings --> <h2> Tier 1 (~55+ FV)</h2> <ol start='1 '> <li><b><a target='_blank' href='https://www.nba.com/draft/2020/prospects/onyeka-okongwu#/'>Onyeka Okongwu</a></b> - <i>PF - <a target='_blank' href='https://www.sports-reference.com/cbb/players/onyeka-okongwu-1.html'>USC</a></b> </i></li> <ul style='list-style-type:none'> <li>Grade: Freshman </li> <li>Age: 19.9 </li> <li>Height: 81 in </li> <li>Weight: 245 lbs </li> <li>Wingspan: 85 in </li> <li>Ape: +4 </li> <li>++: defensive versatility </li> <li>+: finishing, playmaking as a big, motor, shooting </li> <li>-: may not be quite big enough to hang with elite Centers </li> </ul> <br> <li><b><a target='_blank' href='https://www.nba.com/draft/2020/prospects/lamelo-ball#/'>LaMelo Ball</a></b> - <i>PG - <a target='_blank' href='https://www.basketball-reference.com/international/players/lamelo-ball-1.html'>Illawarra Hawks (Australia)</a></b> </i></li> <ul style='list-style-type:none'> <li>Age: 19.2 </li> <li>Height: 79 in </li> <li>Weight: 190 lbs </li> <li>Wingspan: 82 in </li> <li>Ape: +3 </li> <li>++: age, primary ball handling, passing </li> <li>+: size, rebounding </li> <li>-: effort, decision making </li> <li>--: finishing, shot selection </li> </ul> <br> <li><b><a target='_blank' href='https://www.nba.com/draft/2020/prospects/atnhony-edwards#/'>Anthony Edwards</a></b> - <i>SG - <a target='_blank' href='https://www.sports-reference.com/cbb/players/anthony-edwards-2.html'>Georgia</a></b> </i></li> <ul style='list-style-type:none'> <li>Grade: Freshman </li> <li>Age: 19.3 </li> <li>Height: 77 in </li> <li>Weight: 225 lbs </li> <li>Wingspan: 81 in </li> <li>Ape: +4 </li> <li>++: age, strength, athleticism, frame </li> <li>+: ape, shot creation </li> <li>-: playmaking, effort, basketball IQ </li> <li>--: shot selection </li> </ul> <br> <li><b><a target='_blank' href='https://www.nba.com/draft/2020/prospects/james-wiseman#/'>James Wiseman</a></b> - <i>C - <a target='_blank' href='https://www.sports-reference.com/cbb/players/james-wiseman-1.html'>Memphis</a></b> </i></li> <ul style='list-style-type:none'> <li>Grade: Freshman </li> <li>Age: 19.6 </li> <li>Height: 85 in </li> <li>Weight: 237 lbs </li> <li>Wingspan: 90 in </li> <li>Ape: +5 </li> <li>++: frame, athleticism </li> <li>+: age, rim running, rim protection </li> <li>-: shot selection, decision making </li> <li>--: lack of data, competition, defensive reps </li> </ul> <br> </ol> <h2> Tier 2 (~55 FV)</h2> <ol start='5 '> <li><b><a target='_blank' href='https://www.nba.com/draft/2020/prospects/patrick-williams#/'>Patrick Williams</a></b> - <i>SF - <a target='_blank' href='https://www.sports-reference.com/cbb/players/patrick-williams-2.html'>Florida State</a></b> </i></li> <ul style='list-style-type:none'> <li>Grade: Freshman </li> <li>Age: 19.3 </li> <li>Height: 80 in </li> <li>Weight: 225 lbs </li> <li>Wingspan: 83 in </li> <li>Ape: +3 </li> <li>++: age </li> <li>+: off ball defense, free throw shooting, off ball offense </li> <li>-: turnover prone, horizontal athleticism </li> </ul> <br> <li><b><a target='_blank' href='https://www.nba.com/draft/2020/prospects/devin-vassell#/'>Devin Vassell</a></b> - <i>SF - <a target='_blank' href='https://www.sports-reference.com/cbb/players/devin-vassell-1.html'>Florida State</a></b> </i></li> <ul style='list-style-type:none'> <li>Grade: Sophomore </li> <li>Age: 20.2 </li> <li>Height: 79 in </li> <li>Weight: 194 lbs </li> <li>Wingspan: 82 in </li> <li>Ape: +3 </li> <li>++: age </li> <li>+: defensive motor, on ball defense, shot selection </li> <li>-: finishing, strength </li> </ul> <br> </ol> <h2> Tier 3 (~50+ FV)</h2> <ol start='7 '> <li><b><a target='_blank' href='https://www.nba.com/draft/2020/prospects/killian-hayes#/'>Killian Hayes</a></b> - <i>PG - <a target='_blank' href='https://www.basketball-reference.com/international/players/killian-hayes-1.html'>Ratiopharm (Germany)</a></b> </i></li> <ul style='list-style-type:none'> <li>Age: 19.3 </li> <li>Height: 77 in </li> <li>Weight: 215 lbs </li> <li>Wingspan: 80.25 in </li> <li>Ape: +3.25 </li> <li>++: age </li> <li>+: size, shot creation/playmaking, shooting </li> <li>-: athleticism, driving, right hand dominance </li> </ul> <br> <li><b><a target='_blank' href='https://www.nba.com/draft/2020/prospects/kira-lewis#/'>Kira Lewis Jr.</a></b> - <i>PG - <a target='_blank' href='https://www.sports-reference.com/cbb/players/kira-lewisjr-1.html'>Alabama</a></b> </i></li> <ul style='list-style-type:none'> <li>Grade: Sophomore </li> <li>Age: 19.6 </li> <li>Height: 75 in </li> <li>Weight: 165 lbs </li> <li>Wingspan: 78 in </li> <li>Ape: +3 </li> <li>++: age </li> <li>+: shooting, shot creation, pick-and-roll ability </li> <li>-: defensive versatility, playmaking, frame </li> </ul> <br> <li><b><a target='_blank' href='https://www.nba.com/draft/2020/prospects/tyrese-haliburton#/'>Tyrese Haliburton</a></b> - <i>PG - <a target='_blank' href='https://www.sports-reference.com/cbb/players/tyrese-haliburton-1.html'>Iowa State</a></b> </i></li> <ul style='list-style-type:none'> <li>Grade: Sophomore </li> <li>Age: 20.7 </li> <li>Height: 77 in </li> <li>Weight: 175 lbs </li> <li>Wingspan: 80 in </li> <li>Ape: +3 </li> <li>+: basketball IQ, shot selection, playmaking </li> <li>-: athleticsm, shot creation, interior offense </li> </ul> <br>
A11: Aleksej Pokusevski | B11: PF | C11: =IFERROR(INDEX(actual!A:A,MATCH(A11,actual!B:B,FALSE)), "") -> 17 | D11: =IFERROR(INDEX(actual!C:C,MATCH(A11,actual!B:B,FALSE)), "") -> OKC | E11: Olympiacos B (Greece A2) | G11: =YEARFRAC(W11, $G$1, 1) -> 18.896646 | H11: =IFERROR(LEFT(AC11,FIND("'",AC11)-1)*12+SUBSTITUTE(MID(AC11,FIND("'",AC11)+1,LEN(AC11)),"''",""), "") -> 84 | I11: =AD11 -> 201 | J11: =IFERROR(LEFT(AE11,FIND("'",AE11)-1)*12+SUBSTITUTE(MID(AE11,FIND("'",AE11)+1,LEN(AE11)),"''",""), "") -> 87 | K11: =IFERROR(LEFT(AF11,FIND("'",AF11)-1)*12+SUBSTITUTE(MID(AF11,FIND("'",AF11)+1,LEN(AF11)),"''",""), "") | L11: =IFERROR(IF(AND(J11-H11>= 0, J11 > 0), "+", ""),"") & IFERROR(IF(AND(J11-H11>= -5, J11 > 0), J11-H11, ""),"") -> +3 | M11: =IF(H11>0, IFERROR((J11-60)/(H11-60),""), "") -> 1.125 | N11: age | O11: height and fluidity allows for unicorn potential | P11: height and weight allows for bust potential, quality of competition | R11: 50 | S11: 10 | T11: =IF(R11=R10,T10, MAX(T$1:T10)+1) -> 4 | U11: https://www.basketball-reference.com/international/players/aleksej-pokusevski-1.html | V11: https://www.nba.com/draft/2020/prospects/aleksej-pokusevski#/ | W11: 37251 | X11: 3 | Y11: 12 | AA11: 13 | AB11: 18 | AC11: =IFERROR(INDEX('ringer measureables'!$A:$J,MATCH($A11,'ringer measureables'!$A:$A,FALSE),7), "") -> 7'0 | AD11: =IFERROR(INDEX('ringer measureables'!$A:$J,MATCH($A11,'ringer measureables'!$A:$A,FALSE),9), "") -> 201 | AE11: =IFERROR(INDEX('ringer measureables'!$A:$J,MATCH($A11,'ringer measureables'!$A:$A,FALSE),10), "") -> 7'3 | AF11: =IFERROR(INDEX('ringer measureables'!$A:$J,MATCH($A11,'ringer measureables'!$A:$A,FALSE),8), "") -> 0 | AG11: =AG10 & IF(T11=T10, "", IF(T11=1, " <!-- rankings --> ", " </ol> " ) & "<h2> Tier " & T11 & " (~" & IF(MOD(R11, 5)=0, R11, FLOOR(R11, 5) & "+") & " FV)</h2> <ol start='" & S11 & " '> " ) & " <li><b><a target='_blank' href='" & V11 & "'>" & A11 & "</a></b> - <i>" & B11 & " - <a target='_blank' href='" & U11 & "'>" & E11 & "</a></b> </i></li> <ul style='list-style-type:none'>" & IF(F11 <> "", " <li>Grade: " & F11 & " </li>", "") & IF(G11 <> "", " <li>Age: " & ROUND(G11,1) & " </li>", "") & IF(H11 <> "", " <li>Height: " & H11 & " in </li>", "") & IF(I11 <> "", " <li>Weight: " & I11 & " lbs </li>", "") & IF(J11 <> "", " <li>Wingspan: " & J11 & " in </li>", "") & IF(K11 <> "", " <li>Reach: " & K11 & " in </li>", "") & IF(L11 <> "", " <li>Ape: " & L11 & " </li>", "") & IF(N11 <> "", " <li>++: " & N11 & " </li>", "") & IF(O11 <> "", " <li>+: " & O11 & " </li>", "") & IF(P11 <> "", " <li>-: " & P11 & " </li>", "") & IF(Q11 <> "", " <li>--: " & Q11 & " </li>", "") & " </ul> <br>" & IF(T12="", " </ol> <!-- # end of rankings --> ", "") -> <!-- rankings --> <h2> Tier 1 (~55+ FV)</h2> <ol start='1 '> <li><b><a target='_blank' href='https://www.nba.com/draft/2020/prospects/onyeka-okongwu#/'>Onyeka Okongwu</a></b> - <i>PF - <a target='_blank' href='https://www.sports-reference.com/cbb/players/onyeka-okongwu-1.html'>USC</a></b> </i></li> <ul style='list-style-type:none'> <li>Grade: Freshman </li> <li>Age: 19.9 </li> <li>Height: 81 in </li> <li>Weight: 245 lbs </li> <li>Wingspan: 85 in </li> <li>Ape: +4 </li> <li>++: defensive versatility </li> <li>+: finishing, playmaking as a big, motor, shooting </li> <li>-: may not be quite big enough to hang with elite Centers </li> </ul> <br> <li><b><a target='_blank' href='https://www.nba.com/draft/2020/prospects/lamelo-ball#/'>LaMelo Ball</a></b> - <i>PG - <a target='_blank' href='https://www.basketball-reference.com/international/players/lamelo-ball-1.html'>Illawarra Hawks (Australia)</a></b> </i></li> <ul style='list-style-type:none'> <li>Age: 19.2 </li> <li>Height: 79 in </li> <li>Weight: 190 lbs </li> <li>Wingspan: 82 in </li> <li>Ape: +3 </li> <li>++: age, primary ball handling, passing </li> <li>+: size, rebounding </li> <li>-: effort, decision making </li> <li>--: finishing, shot selection </li> </ul> <br> <li><b><a target='_blank' href='https://www.nba.com/draft/2020/prospects/atnhony-edwards#/'>Anthony Edwards</a></b> - <i>SG - <a target='_blank' href='https://www.sports-reference.com/cbb/players/anthony-edwards-2.html'>Georgia</a></b> </i></li> <ul style='list-style-type:none'> <li>Grade: Freshman </li> <li>Age: 19.3 </li> <li>Height: 77 in </li> <li>Weight: 225 lbs </li> <li>Wingspan: 81 in </li> <li>Ape: +4 </li> <li>++: age, strength, athleticism, frame </li> <li>+: ape, shot creation </li> <li>-: playmaking, effort, basketball IQ </li> <li>--: shot selection </li> </ul> <br> <li><b><a target='_blank' href='https://www.nba.com/draft/2020/prospects/james-wiseman#/'>James Wiseman</a></b> - <i>C - <a target='_blank' href='https://www.sports-reference.com/cbb/players/james-wiseman-1.html'>Memphis</a></b> </i></li> <ul style='list-style-type:none'> <li>Grade: Freshman </li> <li>Age: 19.6 </li> <li>Height: 85 in </li> <li>Weight: 237 lbs </li> <li>Wingspan: 90 in </li> <li>Ape: +5 </li> <li>++: frame, athleticism </li> <li>+: age, rim running, rim protection </li> <li>-: shot selection, decision making </li> <li>--: lack of data, competition, defensive reps </li> </ul> <br> </ol> <h2> Tier 2 (~55 FV)</h2> <ol start='5 '> <li><b><a target='_blank' href='https://www.nba.com/draft/2020/prospects/patrick-williams#/'>Patrick Williams</a></b> - <i>SF - <a target='_blank' href='https://www.sports-reference.com/cbb/players/patrick-williams-2.html'>Florida State</a></b> </i></li> <ul style='list-style-type:none'> <li>Grade: Freshman </li> <li>Age: 19.3 </li> <li>Height: 80 in </li> <li>Weight: 225 lbs </li> <li>Wingspan: 83 in </li> <li>Ape: +3 </li> <li>++: age </li> <li>+: off ball defense, free throw shooting, off ball offense </li> <li>-: turnover prone, horizontal athleticism </li> </ul> <br> <li><b><a target='_blank' href='https://www.nba.com/draft/2020/prospects/devin-vassell#/'>Devin Vassell</a></b> - <i>SF - <a target='_blank' href='https://www.sports-reference.com/cbb/players/devin-vassell-1.html'>Florida State</a></b> </i></li> <ul style='list-style-type:none'> <li>Grade: Sophomore </li> <li>Age: 20.2 </li> <li>Height: 79 in </li> <li>Weight: 194 lbs </li> <li>Wingspan: 82 in </li> <li>Ape: +3 </li> <li>++: age </li> <li>+: defensive motor, on ball defense, shot selection </li> <li>-: finishing, strength </li> </ul> <br> </ol> <h2> Tier 3 (~50+ FV)</h2> <ol start='7 '> <li><b><a target='_blank' href='https://www.nba.com/draft/2020/prospects/killian-hayes#/'>Killian Hayes</a></b> - <i>PG - <a target='_blank' href='https://www.basketball-reference.com/international/players/killian-hayes-1.html'>Ratiopharm (Germany)</a></b> </i></li> <ul style='list-style-type:none'> <li>Age: 19.3 </li> <li>Height: 77 in </li> <li>Weight: 215 lbs </li> <li>Wingspan: 80.25 in </li> <li>Ape: +3.25 </li> <li>++: age </li> <li>+: size, shot creation/playmaking, shooting </li> <li>-: athleticism, driving, right hand dominance </li> </ul> <br> <li><b><a target='_blank' href='https://www.nba.com/draft/2020/prospects/kira-lewis#/'>Kira Lewis Jr.</a></b> - <i>PG - <a target='_blank' href='https://www.sports-reference.com/cbb/players/kira-lewisjr-1.html'>Alabama</a></b> </i></li> <ul style='list-style-type:none'> <li>Grade: Sophomore </li> <li>Age: 19.6 </li> <li>Height: 75 in </li> <li>Weight: 165 lbs </li> <li>Wingspan: 78 in </li> <li>Ape: +3 </li> <li>++: age </li> <li>+: shooting, shot creation, pick-and-roll ability </li> <li>-: defensive versatility, playmaking, frame </li> </ul> <br> <li><b><a target='_blank' href='https://www.nba.com/draft/2020/prospects/tyrese-haliburton#/'>Tyrese Haliburton</a></b> - <i>PG - <a target='_blank' href='https://www.sports-reference.com/cbb/players/tyrese-haliburton-1.html'>Iowa State</a></b> </i></li> <ul style='list-style-type:none'> <li>Grade: Sophomore </li> <li>Age: 20.7 </li> <li>Height: 77 in </li> <li>Weight: 175 lbs </li> <li>Wingspan: 80 in </li> <li>Ape: +3 </li> <li>+: basketball IQ, shot selection, playmaking </li> <li>-: athleticsm, shot creation, interior offense </li> </ul> <br> </ol> <h2> Tier 4 (~50 FV)</h2> <ol start='10 '> <li><b><a target='_blank' href='https://www.nba.com/draft/2020/prospects/aleksej-pokusevski#/'>Aleksej Pokusevski</a></b> - <i>PF - <a target='_blank' href='https://www.basketball-reference.com/international/players/aleksej-pokusevski-1.html'>Olympiacos B (Greece A2) </a></b> </i></li> <ul style='list-style-type:none'> <li>Age: 18.9 </li> <li>Height: 84 in </li> <li>Weight: 201 lbs </li> <li>Wingspan: 87 in </li> <li>Ape: +3 </li> <li>++: age </li> <li>+: height and fluidity allows for unicorn potential </li> <li>-: height and weight allows for bust potential, quality of competition </li> </ul> <br>
