Workbook

Sheet board
AE1: count | AF1: =COUNTA(AF6:AF981) -> 76 | AG1: =COUNTA(AG6:AG981) -> 76 | AH1: =COUNTA(AH6:AH981) -> 50 | AI1: =COUNTA(AI6:AI981) -> 29 | AJ1: =COUNTA(AJ6:AJ981) -> 93 | AK1: =COUNTA(AK6:AK981) -> 91 | AL1: =COUNTA(AL6:AL981) -> 37 | AM1: =COUNTA(AM6:AM981) -> 0 | ... AV1: =COUNTA(AV6:AV981) -> 37
AE2: max | AF2: =IF(AF5="rcsi", 25, MAX(AF6:AF981)) -> 76 | AG2: =IF(AG5="rcsi", 25, MAX(AG6:AG981)) -> 13 | AH2: =IF(AH5="rcsi", 25, MAX(AH6:AH981)) -> 50 | AI2: =IF(AI5="rcsi", 25, MAX(AI6:AI981)) -> 30 | AJ2: =IF(AJ5="rcsi", 25, MAX(AJ6:AJ981)) -> 101 | AK2: =IF(AK5="rcsi", 25, MAX(AK6:AK981)) -> 100 | AL2: =IF(AL5="rcsi", 25, MAX(AL6:AL981)) -> 40 | AM2: =IF(AM5="rcsi", 25, MAX(AM6:AM981)) -> 0 | ... AV2: =IF(AV5="rcsi", 25, MAX(AV6:AV981)) -> 25
AE3: weight | AF3: 2 | AG3: 3 | AH3: 4 | AI3: 2 | AJ3: 3 | AK3: 1 | AL3: 1 | AM3: 1 | AN3: 2 | AO3: 4 | AP3: 2 | AQ3: 3 | AR3: 2 | AS3: 1 | AT3: 2 | AU3: 1 | AV3: 1
AE4: type | AF4: scouting | AG4: scouting | AH4: model | AI4: model | AJ4: model | AK4: model | AL4: model | AM4: model | AN4: scouting | AO4: scouting | AP4: scouting | AQ4: scouting | AR4: scouting | AS4: scouting | AT4: scouting | AU4: scouting | AV4: scouting
A5: name | B5: position | C5: school | D5: Grade | E5: 44735 | F5: height (in) | G5: weight | H5: wingspan (in) | I5: reach (in) | J5: Ape | K5: Ape Formula | L5: ++ | M5: + | N5: - | O5: -- | P5: notes | Q5: grade | R5: me | T5: pick | U5: team | V5: ref_link | W5: nbadraft_link | X5: nba_link | Y5: birthday | Z5: agg_rank | AA5: scouting_agg_rnk | AB5: models_agg_rnk | AC5: agg | AD5: scouting | AE5: model | AF5: hollinger | AG5: hol_tier | AH5: tothemean | AI5: pelton | AJ5: David Sajdak | AK5: bigwafe | AL5: evidenceforZ | AM5: craftedNBA | AN5: Dean_rank | AO5: Dean_tier | AP5: zamir_rank | AQ5: zamir_tier | AR5: ringer | AS5: vec_rank | AT5: vec_tier | AU5: espn | AV5: rcsi | AW5: height | AX5: weight | AY5: wingspan | AZ5: reach
A6: Paolo Banchero | B6: PF | C6: Duke | D6: Freshman | E6: =YEARFRAC(Y6, $E$5, 1) -> 19.611864 | F6: =IFERROR(LEFT(AW6,FIND("'",AW6)-1)*12+SUBSTITUTE(MID(AW6,FIND("'",AW6)+1,LEN(AW6)),"''",""), "") -> 82 | G6: =AX6 -> 250 | H6: =IFERROR(LEFT(AY6,FIND("'",AY6)-1)*12+SUBSTITUTE(MID(AY6,FIND("'",AY6)+1,LEN(AY6)),"''",""), "") -> 85 | I6: =IFERROR(LEFT(AZ6,FIND("'",AZ6)-1)*12+SUBSTITUTE(MID(AZ6,FIND("'",AZ6)+1,LEN(AZ6)),"''",""), "") | J6: =IFERROR(IF(AND(H6-F6>= 0, H6 > 0), "+", ""),"") & IFERROR(IF(AND(H6-F6>= -5, H6 > 0), H6-F6, ""),"") -> +3 | K6: =IF(F6>0, IFERROR((H6-60)/(F6-60),""), "") -> 1.1363636 | L6: size, offensive creation, rim attacking | M6: passing | N6: defensive impact, shooting | P6: upside of a big wing who can be a primary offensive creator (arguably the most valuable archtype in the sport) | Q6: 60.9 | R6: =IF(Q6=-1, "", IF(Q6=0,"HM.",IF(Q6="","",RANK(Q6,Q$6:Q$980)))) -> 1 | S6: =IFERROR(IF(FLOOR(Q6,1)=FLOOR(Q5,1),S5, MAX(S$5:S5)+1),1) -> 1 | T6: =IFERROR(INDEX(actual!A:A,MATCH(A6,actual!B:B,FALSE)), "") -> 1 | U6: =IFERROR(INDEX(actual!C:C,MATCH(A6,actual!B:B,FALSE)), "") -> ORL | V6: =HYPERLINK(IF(D6="", "https://www.basketball-reference.com/international", "https://www.sports-reference.com/cbb") & "/players/" & LOWER(SUBSTITUTE(A6, " ", "-") & "-1.html")) -> https://www.sports-reference.com/cbb/players/paolo-banchero-1.html | W6: =HYPERLINK("https://www.nbadraft.net/players/" & LOWER(SUBSTITUTE(A6, " ", "-") & "")) -> https://www.nbadraft.net/players/paolo-banchero | X6: =HYPERLINK("https://www.nba.com/draft/2022/prospects/" & LOWER(SUBSTITUTE(A6, " ", "-") & "")) -> https://www.nba.com/draft/2022/prospects/paolo-banchero | Y6: 37572 | Z6: =RANK(AC6,AC:AC,1) -> 3 | AA6: =RANK(AD6,AD:AD,1) -> 2 | AB6: =RANK(AE6,AE:AE,1) -> 3 | AC6: =AD6+AE6 -> 103 | AD6: =IFERROR( IF($AF$4 = AD$5, ($AF$3 * IF($AF6>0, $AF6, $AF$2)), 0) + IF($AG$4 = AD$5, ($AG$3 * IF($AG6>0, $AG6, $AG$2)), 0) + IF($AH$4 = AD$5, ($AH$3 * IF($AH6>0, $AH6, $AH$2)), 0) + IF($AI$4 = AD$5, ($AI$3 * IF($AI6>0, $AI6, $AI$2)), 0) + IF($AJ$4 = AD$5, ($AJ$3 * IF($AJ6>0, $AJ6, $AJ$2)), 0) + IF($AK$4 = AD$5, ($AK$3 * IF($AK6>0, $AK6, $AK$2)), 0) + IF($AL$4 = AD$5, ($AL$3 * IF($AL6>0, $AL6, $AL$2)), 0) + IF($AM$4 = AD$5, ($AM$3 * IF($AM6>0, $AM6, $AM$2)), 0) + IF($AN$4 = AD$5, ($AN$3 * IF($AN6>0, $AN6, $AN$2)), 0) + IF($AO$4 = AD$5, ($AO$3 * IF($AO6>0, $AO6, $AO$2)), 0) + IF($AP$4 = AD$5, ($AP$3 * IF($AP6>0, $AP6, $AP$2)), 0) + IF($AQ$4 = AD$5, ($AQ$3 * IF($AQ6>0, $AQ6, $AQ$2)), 0) + IF($AR$4 = AD$5, ($AR$3 * IF($AR6>0, $AR6, $AR$2)), 0) + IF($AS$4 = AD$5, ($AS$3 * IF($AS6>0, $AS6, $AS$2)), 0) + IF($AT$4 = AD$5, ($AT$3 * IF($AT6>0, $AT6, $AT$2)), 0) + IF($AU$4 = AD$5, ($AU$3 * IF($AU6>0, $AU6, $AU$2)), 0) + IF($AV$4 = AD$5, ($AV$3 * IF($AV6>0, IF($AV6 > $AV$2, $AV$2, $AV6), $AV$2)), 0), -1) -> 39 | AE6: =IFERROR( IF($AF$4 = AE$5, ($AF$3 * IF($AF6>0, $AF6, $AF$2)), 0) + IF($AG$4 = AE$5, ($AG$3 * IF($AG6>0, $AG6, $AG$2)), 0) + IF($AH$4 = AE$5, ($AH$3 * IF($AH6>0, $AH6, $AH$2)), 0) + IF($AI$4 = AE$5, ($AI$3 * IF($AI6>0, $AI6, $AI$2)), 0) + IF($AJ$4 = AE$5, ($AJ$3 * IF($AJ6>0, $AJ6, $AJ$2)), 0) + IF($AK$4 = AE$5, ($AK$3 * IF($AK6>0, $AK6, $AK$2)), 0) + IF($AL$4 = AE$5, ($AL$3 * IF($AL6>0, $AL6, $AL$2)), 0) + IF($AM$4 = AE$5, ($AM$3 * IF($AM6>0, $AM6, $AM$2)), 0) + IF($AN$4 = AE$5, ($AN$3 * IF($AN6>0, $AN6, $AN$2)), 0) + IF($AO$4 = AE$5, ($AO$3 * IF($AO6>0, $AO6, $AO$2)), 0) + IF($AP$4 = AE$5, ($AP$3 * IF($AP6>0, $AP6, $AP$2)), 0) + IF($AQ$4 = AE$5, ($AQ$3 * IF($AQ6>0, $AQ6, $AQ$2)), 0) + IF($AR$4 = AE$5, ($AR$3 * IF($AR6>0, $AR6, $AR$2)), 0) + IF($AS$4 = AE$5, ($AS$3 * IF($AS6>0, $AS6, $AS$2)), 0) + IF($AT$4 = AE$5, ($AT$3 * IF($AT6>0, $AT6, $AT$2)), 0) + IF($AU$4 = AE$5, ($AU$3 * IF($AU6>0, $AU6, $AU$2)), 0) + IF($AV$4 = AE$5, ($AV$3 * IF($AV6>0, IF($AV6 > $AV$2, $AV$2, $AV6), $AV$2)), 0), -1) -> 64 | AF6: 2 | AG6: 1 | AH6: 4 | AI6: 11 | AJ6: 6 | AK6: 5 | AL6: 3 | AN6: 1 | AO6: 1 | AP6: 3 | AQ6: 2 | AR6: 1 | AS6: 3 | AT6: 2 | AU6: 3 | AV6: 2 | AW6: =IFERROR(INDEX(measureables!$A:$J,MATCH($A6,measureables!$A:$A,FALSE),7), "") -> 6' 10'' | AX6: =IFERROR(INDEX(measureables!$A:$J,MATCH($A6,measureables!$A:$A,FALSE),9), "") -> 250 | AY6: =IFERROR(INDEX(measureables!$A:$J,MATCH($A6,measureables!$A:$A,FALSE),10), "") -> 7' 1'' | AZ6: =IFERROR(INDEX(measureables!$A:$J,MATCH($A6,measureables!$A:$A,FALSE),8), "") -> 0 | BA6: =IF(R6="",A6, IF(S6=S5,"",IF(S6=1," <!-- rankings --> "," </ol> " ) & "<h2> Tier " &S6 &" (~" &IF(MOD(ROUND(Q6,0),5)=0,ROUND(Q6,0),FLOOR(ROUND(Q6,0),5)&"+") &" FV)</h2> <ol start='" &R6 &" '> " ) & " <li><b><a target='_blank' href='" &X6 &"'>" &A6 &"</a></b> - <i> <a target='_blank' href='" &W6 &"'>" &B6 &" </a></b> - <a target='_blank'href='" &V6 &"'>" &C6 &"</a></b> </i></li> <ul style='list-style-type:none'>" &IF(D6<>""," <li>Grade: "&D6&" </li>","") &IF(E6<>""," <li>Age: "&ROUND(E6,1)&" </li>","") &IF(F6<>""," <li>Height: "&F6&" in </li>","") &IF(G6<>""," <li>Weight: "&G6&" lbs </li>","") &IF(H6<>""," <li>Wingspan: "&H6&" in </li>","") &IF(I6<>""," <li>Reach: "&I6&" in </li>","") &IF(J6<>""," <li>Ape: "&J6&" </li>","") &IF(L6<>""," <li>++: "&L6&" </li>","") &IF(M6<>""," <li>+: "&M6&" </li>","") &IF(N6<>""," <li>-: "&N6&" </li>","") &IF(O6<>""," <li>--: "&O6&" </li>","") &IF(P6<>""," <li>Additional Notes: "&P6&" </li>","") &" </ul> <br>" &IF(AND(R6<>"",R7="")," </ol> <!-- # end of rankings --> ","") ) -> <!-- rankings --> <h2> Tier 1 (~60+ FV)</h2> <ol start='1 '> <li><b><a target='_blank' href='https://www.nba.com/draft/2022/prospects/paolo-banchero'>Paolo Banchero</a></b> - <i> <a target='_blank' href='https://www.nbadraft.net/players/paolo-banchero'>PF </a></b> - <a target='_blank'href='https://www.sports-reference.com/cbb/players/paolo-banchero-1.html'>Duke</a></b> </i></li> <ul style='list-style-type:none'> <li>Grade: Freshman </li> <li>Age: 19.6 </li> <li>Height: 82 in </li> <li>Weight: 250 lbs </li> <li>Wingspan: 85 in </li> <li>Ape: +3 </li> <li>++: size, offensive creation, rim attacking </li> <li>+: passing </li> <li>-: defensive impact, shooting </li> <li>Additional Notes: upside of a big wing who can be a primary offensive creator (arguably the most valuable archtype in the sport) </li> </ul> <br>
A7: Jabari Smith | B7: PF | C7: Auburn | D7: Freshman | E7: =YEARFRAC(Y7, $E$5, 1) -> 19.112936 | F7: =IFERROR(LEFT(AW7,FIND("'",AW7)-1)*12+SUBSTITUTE(MID(AW7,FIND("'",AW7)+1,LEN(AW7)),"''",""), "") -> 82 | G7: =AX7 -> 210 | H7: =IFERROR(LEFT(AY7,FIND("'",AY7)-1)*12+SUBSTITUTE(MID(AY7,FIND("'",AY7)+1,LEN(AY7)),"''",""), "") | I7: =IFERROR(LEFT(AZ7,FIND("'",AZ7)-1)*12+SUBSTITUTE(MID(AZ7,FIND("'",AZ7)+1,LEN(AZ7)),"''",""), "") | J7: =IFERROR(IF(AND(H7-F7>= 0, H7 > 0), "+", ""),"") & IFERROR(IF(AND(H7-F7>= -5, H7 > 0), H7-F7, ""),"") | K7: =IF(F7>0, IFERROR((H7-60)/(F7-60),""), "") | L7: shooting | M7: age, height, perimeter and on-ball defensive given size | N7: ball handling, passing, offensive creation, interior defense | P7: probably won't be a primary creator, but his size+shooting is a great combination for a secondary threat, with defensive upside to boot | Q7: 60.8 | R7: =IF(Q7=-1, "", IF(Q7=0,"HM.",IF(Q7="","",RANK(Q7,Q$6:Q$980)))) -> 2 | S7: =IFERROR(IF(FLOOR(Q7,1)=FLOOR(Q6,1),S6, MAX(S$5:S6)+1),1) -> 1 | T7: =IFERROR(INDEX(actual!A:A,MATCH(A7,actual!B:B,FALSE)), "") -> 3 | U7: =IFERROR(INDEX(actual!C:C,MATCH(A7,actual!B:B,FALSE)), "") -> HOU | V7: https://www.sports-reference.com/cbb/players/jabari-smith-2.html | W7: =HYPERLINK("https://www.nbadraft.net/players/" & LOWER(SUBSTITUTE(A7, " ", "-") & "")) -> https://www.nbadraft.net/players/jabari-smith | X7: =HYPERLINK("https://www.nba.com/draft/2022/prospects/" & LOWER(SUBSTITUTE(A7, " ", "-") & "")) -> https://www.nba.com/draft/2022/prospects/jabari-smith | Y7: 37754 | Z7: =RANK(AC7,AC:AC,1) -> 1 | AA7: =RANK(AD7,AD:AD,1) -> 1 | AB7: =RANK(AE7,AE:AE,1) -> 1 | AC7: =AD7+AE7 -> 57 | AD7: =IFERROR( IF($AF$4 = AD$5, ($AF$3 * IF($AF7>0, $AF7, $AF$2)), 0) + IF($AG$4 = AD$5, ($AG$3 * IF($AG7>0, $AG7, $AG$2)), 0) + IF($AH$4 = AD$5, ($AH$3 * IF($AH7>0, $AH7, $AH$2)), 0) + IF($AI$4 = AD$5, ($AI$3 * IF($AI7>0, $AI7, $AI$2)), 0) + IF($AJ$4 = AD$5, ($AJ$3 * IF($AJ7>0, $AJ7, $AJ$2)), 0) + IF($AK$4 = AD$5, ($AK$3 * IF($AK7>0, $AK7, $AK$2)), 0) + IF($AL$4 = AD$5, ($AL$3 * IF($AL7>0, $AL7, $AL$2)), 0) + IF($AM$4 = AD$5, ($AM$3 * IF($AM7>0, $AM7, $AM$2)), 0) + IF($AN$4 = AD$5, ($AN$3 * IF($AN7>0, $AN7, $AN$2)), 0) + IF($AO$4 = AD$5, ($AO$3 * IF($AO7>0, $AO7, $AO$2)), 0) + IF($AP$4 = AD$5, ($AP$3 * IF($AP7>0, $AP7, $AP$2)), 0) + IF($AQ$4 = AD$5, ($AQ$3 * IF($AQ7>0, $AQ7, $AQ$2)), 0) + IF($AR$4 = AD$5, ($AR$3 * IF($AR7>0, $AR7, $AR$2)), 0) + IF($AS$4 = AD$5, ($AS$3 * IF($AS7>0, $AS7, $AS$2)), 0) + IF($AT$4 = AD$5, ($AT$3 * IF($AT7>0, $AT7, $AT$2)), 0) + IF($AU$4 = AD$5, ($AU$3 * IF($AU7>0, $AU7, $AU$2)), 0) + IF($AV$4 = AD$5, ($AV$3 * IF($AV7>0, IF($AV7 > $AV$2, $AV$2, $AV7), $AV$2)), 0), -1) -> 34 | AE7: =IFERROR( IF($AF$4 = AE$5, ($AF$3 * IF($AF7>0, $AF7, $AF$2)), 0) + IF($AG$4 = AE$5, ($AG$3 * IF($AG7>0, $AG7, $AG$2)), 0) + IF($AH$4 = AE$5, ($AH$3 * IF($AH7>0, $AH7, $AH$2)), 0) + IF($AI$4 = AE$5, ($AI$3 * IF($AI7>0, $AI7, $AI$2)), 0) + IF($AJ$4 = AE$5, ($AJ$3 * IF($AJ7>0, $AJ7, $AJ$2)), 0) + IF($AK$4 = AE$5, ($AK$3 * IF($AK7>0, $AK7, $AK$2)), 0) + IF($AL$4 = AE$5, ($AL$3 * IF($AL7>0, $AL7, $AL$2)), 0) + IF($AM$4 = AE$5, ($AM$3 * IF($AM7>0, $AM7, $AM$2)), 0) + IF($AN$4 = AE$5, ($AN$3 * IF($AN7>0, $AN7, $AN$2)), 0) + IF($AO$4 = AE$5, ($AO$3 * IF($AO7>0, $AO7, $AO$2)), 0) + IF($AP$4 = AE$5, ($AP$3 * IF($AP7>0, $AP7, $AP$2)), 0) + IF($AQ$4 = AE$5, ($AQ$3 * IF($AQ7>0, $AQ7, $AQ$2)), 0) + IF($AR$4 = AE$5, ($AR$3 * IF($AR7>0, $AR7, $AR$2)), 0) + IF($AS$4 = AE$5, ($AS$3 * IF($AS7>0, $AS7, $AS$2)), 0) + IF($AT$4 = AE$5, ($AT$3 * IF($AT7>0, $AT7, $AT$2)), 0) + IF($AU$4 = AE$5, ($AU$3 * IF($AU7>0, $AU7, $AU$2)), 0) + IF($AV$4 = AE$5, ($AV$3 * IF($AV7>0, IF($AV7 > $AV$2, $AV$2, $AV7), $AV$2)), 0), -1) -> 23 | AF7: 1 | AG7: 1 | AH7: 1 | AI7: 2 | AJ7: 3 | AK7: 4 | AL7: 2 | AN7: 2 | AO7: 1 | AP7: 1 | AQ7: 1 | AR7: 2 | AS7: 2 | AT7: 2 | AU7: 2 | AV7: 4 | AW7: =IFERROR(INDEX(measureables!$A:$J,MATCH($A7,measureables!$A:$A,FALSE),7), "") -> 6' 10'' | AX7: =IFERROR(INDEX(measureables!$A:$J,MATCH($A7,measureables!$A:$A,FALSE),9), "") -> 210 | AY7: =IFERROR(INDEX(measureables!$A:$J,MATCH($A7,measureables!$A:$A,FALSE),10), "") -> 0 | AZ7: =IFERROR(INDEX(measureables!$A:$J,MATCH($A7,measureables!$A:$A,FALSE),8), "") -> 0 | BA7: =IF(R7="",A7, IF(S7=S6,"",IF(S7=1," <!-- rankings --> "," </ol> " ) & "<h2> Tier " &S7 &" (~" &IF(MOD(ROUND(Q7,0),5)=0,ROUND(Q7,0),FLOOR(ROUND(Q7,0),5)&"+") &" FV)</h2> <ol start='" &R7 &" '> " ) & " <li><b><a target='_blank' href='" &X7 &"'>" &A7 &"</a></b> - <i> <a target='_blank' href='" &W7 &"'>" &B7 &" </a></b> - <a target='_blank'href='" &V7 &"'>" &C7 &"</a></b> </i></li> <ul style='list-style-type:none'>" &IF(D7<>""," <li>Grade: "&D7&" </li>","") &IF(E7<>""," <li>Age: "&ROUND(E7,1)&" </li>","") &IF(F7<>""," <li>Height: "&F7&" in </li>","") &IF(G7<>""," <li>Weight: "&G7&" lbs </li>","") &IF(H7<>""," <li>Wingspan: "&H7&" in </li>","") &IF(I7<>""," <li>Reach: "&I7&" in </li>","") &IF(J7<>""," <li>Ape: "&J7&" </li>","") &IF(L7<>""," <li>++: "&L7&" </li>","") &IF(M7<>""," <li>+: "&M7&" </li>","") &IF(N7<>""," <li>-: "&N7&" </li>","") &IF(O7<>""," <li>--: "&O7&" </li>","") &IF(P7<>""," <li>Additional Notes: "&P7&" </li>","") &" </ul> <br>" &IF(AND(R7<>"",R8="")," </ol> <!-- # end of rankings --> ","") ) -> <li><b><a target='_blank' href='https://www.nba.com/draft/2022/prospects/jabari-smith'>Jabari Smith</a></b> - <i> <a target='_blank' href='https://www.nbadraft.net/players/jabari-smith'>PF </a></b> - <a target='_blank'href='https://www.sports-reference.com/cbb/players/jabari-smith-2.html'>Auburn</a></b> </i></li> <ul style='list-style-type:none'> <li>Grade: Freshman </li> <li>Age: 19.1 </li> <li>Height: 82 in </li> <li>Weight: 210 lbs </li> <li>++: shooting </li> <li>+: age, height, perimeter and on-ball defensive given size </li> <li>-: ball handling, passing, offensive creation, interior defense </li> <li>Additional Notes: probably won't be a primary creator, but his size+shooting is a great combination for a secondary threat, with defensive upside to boot </li> </ul> <br>
A8: Chet Holmgren | B8: PF | C8: Gonzaga | D8: Freshman | E8: =YEARFRAC(Y8, $E$5, 1) -> 20.145763 | F8: =IFERROR(LEFT(AW8,FIND("'",AW8)-1)*12+SUBSTITUTE(MID(AW8,FIND("'",AW8)+1,LEN(AW8)),"''",""), "") -> 84 | G8: =AX8 -> 195 | H8: =IFERROR(LEFT(AY8,FIND("'",AY8)-1)*12+SUBSTITUTE(MID(AY8,FIND("'",AY8)+1,LEN(AY8)),"''",""), "") -> 89 | I8: =IFERROR(LEFT(AZ8,FIND("'",AZ8)-1)*12+SUBSTITUTE(MID(AZ8,FIND("'",AZ8)+1,LEN(AZ8)),"''",""), "") | J8: =IFERROR(IF(AND(H8-F8>= 0, H8 > 0), "+", ""),"") & IFERROR(IF(AND(H8-F8>= -5, H8 > 0), H8-F8, ""),"") -> +5 | K8: =IF(F8>0, IFERROR((H8-60)/(F8-60),""), "") -> 1.2083333 | L8: rim protection, fluidity | M8: shooting, off-ball abilities (both sides) | N8: on-ball defense | O8: age, frame | P8: for a player with such obvious strengths and weaknesses, it's difficult to determine what type of impact Holmgren will have given his uniqueness | Q8: 60.7 | R8: =IF(Q8=-1, "", IF(Q8=0,"HM.",IF(Q8="","",RANK(Q8,Q$6:Q$980)))) -> 3 | S8: =IFERROR(IF(FLOOR(Q8,1)=FLOOR(Q7,1),S7, MAX(S$5:S7)+1),1) -> 1 | T8: =IFERROR(INDEX(actual!A:A,MATCH(A8,actual!B:B,FALSE)), "") -> 2 | U8: =IFERROR(INDEX(actual!C:C,MATCH(A8,actual!B:B,FALSE)), "") -> OKC | V8: =HYPERLINK(IF(D8="", "https://www.basketball-reference.com/international", "https://www.sports-reference.com/cbb") & "/players/" & LOWER(SUBSTITUTE(A8, " ", "-") & "-1.html")) -> https://www.sports-reference.com/cbb/players/chet-holmgren-1.html | W8: =HYPERLINK("https://www.nbadraft.net/players/" & LOWER(SUBSTITUTE(A8, " ", "-") & "")) -> https://www.nbadraft.net/players/chet-holmgren | X8: =HYPERLINK("https://www.nba.com/draft/2022/prospects/" & LOWER(SUBSTITUTE(A8, " ", "-") & "")) -> https://www.nba.com/draft/2022/prospects/chet-holmgren | Y8: 37377 | Z8: =RANK(AC8,AC:AC,1) -> 2 | AA8: =RANK(AD8,AD:AD,1) -> 3 | AB8: =RANK(AE8,AE:AE,1) -> 2 | AC8: =AD8+AE8 -> 78 | AD8: =IFERROR( IF($AF$4 = AD$5, ($AF$3 * IF($AF8>0, $AF8, $AF$2)), 0) + IF($AG$4 = AD$5, ($AG$3 * IF($AG8>0, $AG8, $AG$2)), 0) + IF($AH$4 = AD$5, ($AH$3 * IF($AH8>0, $AH8, $AH$2)), 0) + IF($AI$4 = AD$5, ($AI$3 * IF($AI8>0, $AI8, $AI$2)), 0) + IF($AJ$4 = AD$5, ($AJ$3 * IF($AJ8>0, $AJ8, $AJ$2)), 0) + IF($AK$4 = AD$5, ($AK$3 * IF($AK8>0, $AK8, $AK$2)), 0) + IF($AL$4 = AD$5, ($AL$3 * IF($AL8>0, $AL8, $AL$2)), 0) + IF($AM$4 = AD$5, ($AM$3 * IF($AM8>0, $AM8, $AM$2)), 0) + IF($AN$4 = AD$5, ($AN$3 * IF($AN8>0, $AN8, $AN$2)), 0) + IF($AO$4 = AD$5, ($AO$3 * IF($AO8>0, $AO8, $AO$2)), 0) + IF($AP$4 = AD$5, ($AP$3 * IF($AP8>0, $AP8, $AP$2)), 0) + IF($AQ$4 = AD$5, ($AQ$3 * IF($AQ8>0, $AQ8, $AQ$2)), 0) + IF($AR$4 = AD$5, ($AR$3 * IF($AR8>0, $AR8, $AR$2)), 0) + IF($AS$4 = AD$5, ($AS$3 * IF($AS8>0, $AS8, $AS$2)), 0) + IF($AT$4 = AD$5, ($AT$3 * IF($AT8>0, $AT8, $AT$2)), 0) + IF($AU$4 = AD$5, ($AU$3 * IF($AU8>0, $AU8, $AU$2)), 0) + IF($AV$4 = AD$5, ($AV$3 * IF($AV8>0, IF($AV8 > $AV$2, $AV$2, $AV8), $AV$2)), 0), -1) -> 47 | AE8: =IFERROR( IF($AF$4 = AE$5, ($AF$3 * IF($AF8>0, $AF8, $AF$2)), 0) + IF($AG$4 = AE$5, ($AG$3 * IF($AG8>0, $AG8, $AG$2)), 0) + IF($AH$4 = AE$5, ($AH$3 * IF($AH8>0, $AH8, $AH$2)), 0) + IF($AI$4 = AE$5, ($AI$3 * IF($AI8>0, $AI8, $AI$2)), 0) + IF($AJ$4 = AE$5, ($AJ$3 * IF($AJ8>0, $AJ8, $AJ$2)), 0) + IF($AK$4 = AE$5, ($AK$3 * IF($AK8>0, $AK8, $AK$2)), 0) + IF($AL$4 = AE$5, ($AL$3 * IF($AL8>0, $AL8, $AL$2)), 0) + IF($AM$4 = AE$5, ($AM$3 * IF($AM8>0, $AM8, $AM$2)), 0) + IF($AN$4 = AE$5, ($AN$3 * IF($AN8>0, $AN8, $AN$2)), 0) + IF($AO$4 = AE$5, ($AO$3 * IF($AO8>0, $AO8, $AO$2)), 0) + IF($AP$4 = AE$5, ($AP$3 * IF($AP8>0, $AP8, $AP$2)), 0) + IF($AQ$4 = AE$5, ($AQ$3 * IF($AQ8>0, $AQ8, $AQ$2)), 0) + IF($AR$4 = AE$5, ($AR$3 * IF($AR8>0, $AR8, $AR$2)), 0) + IF($AS$4 = AE$5, ($AS$3 * IF($AS8>0, $AS8, $AS$2)), 0) + IF($AT$4 = AE$5, ($AT$3 * IF($AT8>0, $AT8, $AT$2)), 0) + IF($AU$4 = AE$5, ($AU$3 * IF($AU8>0, $AU8, $AU$2)), 0) + IF($AV$4 = AE$5, ($AV$3 * IF($AV8>0, IF($AV8 > $AV$2, $AV$2, $AV8), $AV$2)), 0), -1) -> 31 | AF8: 4 | AG8: 2 | AH8: 6 | AI8: 1 | AJ8: 1 | AK8: 1 | AL8: 1 | AN8: 3 | AO8: 1 | AP8: 2 | AQ8: 2 | AR8: 3 | AS8: 1 | AT8: 2 | AU8: 1 | AV8: 1 | AW8: =IFERROR(INDEX(measureables!$A:$J,MATCH($A8,measureables!$A:$A,FALSE),7), "") -> 7' 0'' | AX8: =IFERROR(INDEX(measureables!$A:$J,MATCH($A8,measureables!$A:$A,FALSE),9), "") -> 195 | AY8: =IFERROR(INDEX(measureables!$A:$J,MATCH($A8,measureables!$A:$A,FALSE),10), "") -> 7' 5'' | AZ8: =IFERROR(INDEX(measureables!$A:$J,MATCH($A8,measureables!$A:$A,FALSE),8), "") -> 0 | BA8: =IF(R8="",A8, IF(S8=S7,"",IF(S8=1," <!-- rankings --> "," </ol> " ) & "<h2> Tier " &S8 &" (~" &IF(MOD(ROUND(Q8,0),5)=0,ROUND(Q8,0),FLOOR(ROUND(Q8,0),5)&"+") &" FV)</h2> <ol start='" &R8 &" '> " ) & " <li><b><a target='_blank' href='" &X8 &"'>" &A8 &"</a></b> - <i> <a target='_blank' href='" &W8 &"'>" &B8 &" </a></b> - <a target='_blank'href='" &V8 &"'>" &C8 &"</a></b> </i></li> <ul style='list-style-type:none'>" &IF(D8<>""," <li>Grade: "&D8&" </li>","") &IF(E8<>""," <li>Age: "&ROUND(E8,1)&" </li>","") &IF(F8<>""," <li>Height: "&F8&" in </li>","") &IF(G8<>""," <li>Weight: "&G8&" lbs </li>","") &IF(H8<>""," <li>Wingspan: "&H8&" in </li>","") &IF(I8<>""," <li>Reach: "&I8&" in </li>","") &IF(J8<>""," <li>Ape: "&J8&" </li>","") &IF(L8<>""," <li>++: "&L8&" </li>","") &IF(M8<>""," <li>+: "&M8&" </li>","") &IF(N8<>""," <li>-: "&N8&" </li>","") &IF(O8<>""," <li>--: "&O8&" </li>","") &IF(P8<>""," <li>Additional Notes: "&P8&" </li>","") &" </ul> <br>" &IF(AND(R8<>"",R9="")," </ol> <!-- # end of rankings --> ","") ) -> <li><b><a target='_blank' href='https://www.nba.com/draft/2022/prospects/chet-holmgren'>Chet Holmgren</a></b> - <i> <a target='_blank' href='https://www.nbadraft.net/players/chet-holmgren'>PF </a></b> - <a target='_blank'href='https://www.sports-reference.com/cbb/players/chet-holmgren-1.html'>Gonzaga</a></b> </i></li> <ul style='list-style-type:none'> <li>Grade: Freshman </li> <li>Age: 20.1 </li> <li>Height: 84 in </li> <li>Weight: 195 lbs </li> <li>Wingspan: 89 in </li> <li>Ape: +5 </li> <li>++: rim protection, fluidity </li> <li>+: shooting, off-ball abilities (both sides) </li> <li>-: on-ball defense </li> <li>--: age, frame </li> <li>Additional Notes: for a player with such obvious strengths and weaknesses, it's difficult to determine what type of impact Holmgren will have given his uniqueness </li> </ul> <br>
A9: Dyson Daniels | B9: SG | C9: G League Ignite | E9: =YEARFRAC(Y9, $E$5, 1) -> 19.268994 | F9: =IFERROR(LEFT(AW9,FIND("'",AW9)-1)*12+SUBSTITUTE(MID(AW9,FIND("'",AW9)+1,LEN(AW9)),"''",""), "") -> 79.5 | G9: =AX9 -> 195.2 | H9: =IFERROR(LEFT(AY9,FIND("'",AY9)-1)*12+SUBSTITUTE(MID(AY9,FIND("'",AY9)+1,LEN(AY9)),"''",""), "") -> 82.5 | I9: =IFERROR(LEFT(AZ9,FIND("'",AZ9)-1)*12+SUBSTITUTE(MID(AZ9,FIND("'",AZ9)+1,LEN(AZ9)),"''",""), "") -> 105 | J9: =IFERROR(IF(AND(H9-F9>= 0, H9 > 0), "+", ""),"") & IFERROR(IF(AND(H9-F9>= -5, H9 > 0), H9-F9, ""),"") -> +3 | K9: =IF(F9>0, IFERROR((H9-60)/(F9-60),""), "") -> 1.1538462 | L9: basketball IQ, on-ball defense | M9: ball-handling, passing | N9: shooting, athleticism | P9: high floor player based on passing, defense, and feel for the game, but still has untapped upside if the shooting improves | Q9: 52.9 | R9: =IF(Q9=-1, "", IF(Q9=0,"HM.",IF(Q9="","",RANK(Q9,Q$6:Q$980)))) -> 4 | S9: =IFERROR(IF(FLOOR(Q9,1)=FLOOR(Q8,1),S8, MAX(S$5:S8)+1),1) -> 2 | T9: =IFERROR(INDEX(actual!A:A,MATCH(A9,actual!B:B,FALSE)), "") -> 8 | U9: =IFERROR(INDEX(actual!C:C,MATCH(A9,actual!B:B,FALSE)), "") -> NOP | V9: https://www.basketball-reference.com/players/d/daniedy01.html | W9: =HYPERLINK("https://www.nbadraft.net/players/" & LOWER(SUBSTITUTE(A9, " ", "-") & "")) -> https://www.nbadraft.net/players/dyson-daniels | X9: =HYPERLINK("https://www.nba.com/draft/2022/prospects/" & LOWER(SUBSTITUTE(A9, " ", "-") & "")) -> https://www.nba.com/draft/2022/prospects/dyson-daniels | Y9: 37697 | Z9: =RANK(AC9,AC:AC,1) -> 4 | AA9: =RANK(AD9,AD:AD,1) -> 8 | AB9: =RANK(AE9,AE:AE,1) -> 4 | AC9: =AD9+AE9 -> 214 | AD9: =IFERROR( IF($AF$4 = AD$5, ($AF$3 * IF($AF9>0, $AF9, $AF$2)), 0) + IF($AG$4 = AD$5, ($AG$3 * IF($AG9>0, $AG9, $AG$2)), 0) + IF($AH$4 = AD$5, ($AH$3 * IF($AH9>0, $AH9, $AH$2)), 0) + IF($AI$4 = AD$5, ($AI$3 * IF($AI9>0, $AI9, $AI$2)), 0) + IF($AJ$4 = AD$5, ($AJ$3 * IF($AJ9>0, $AJ9, $AJ$2)), 0) + IF($AK$4 = AD$5, ($AK$3 * IF($AK9>0, $AK9, $AK$2)), 0) + IF($AL$4 = AD$5, ($AL$3 * IF($AL9>0, $AL9, $AL$2)), 0) + IF($AM$4 = AD$5, ($AM$3 * IF($AM9>0, $AM9, $AM$2)), 0) + IF($AN$4 = AD$5, ($AN$3 * IF($AN9>0, $AN9, $AN$2)), 0) + IF($AO$4 = AD$5, ($AO$3 * IF($AO9>0, $AO9, $AO$2)), 0) + IF($AP$4 = AD$5, ($AP$3 * IF($AP9>0, $AP9, $AP$2)), 0) + IF($AQ$4 = AD$5, ($AQ$3 * IF($AQ9>0, $AQ9, $AQ$2)), 0) + IF($AR$4 = AD$5, ($AR$3 * IF($AR9>0, $AR9, $AR$2)), 0) + IF($AS$4 = AD$5, ($AS$3 * IF($AS9>0, $AS9, $AS$2)), 0) + IF($AT$4 = AD$5, ($AT$3 * IF($AT9>0, $AT9, $AT$2)), 0) + IF($AU$4 = AD$5, ($AU$3 * IF($AU9>0, $AU9, $AU$2)), 0) + IF($AV$4 = AD$5, ($AV$3 * IF($AV9>0, IF($AV9 > $AV$2, $AV$2, $AV9), $AV$2)), 0), -1) -> 135 | AE9: =IFERROR( IF($AF$4 = AE$5, ($AF$3 * IF($AF9>0, $AF9, $AF$2)), 0) + IF($AG$4 = AE$5, ($AG$3 * IF($AG9>0, $AG9, $AG$2)), 0) + IF($AH$4 = AE$5, ($AH$3 * IF($AH9>0, $AH9, $AH$2)), 0) + IF($AI$4 = AE$5, ($AI$3 * IF($AI9>0, $AI9, $AI$2)), 0) + IF($AJ$4 = AE$5, ($AJ$3 * IF($AJ9>0, $AJ9, $AJ$2)), 0) + IF($AK$4 = AE$5, ($AK$3 * IF($AK9>0, $AK9, $AK$2)), 0) + IF($AL$4 = AE$5, ($AL$3 * IF($AL9>0, $AL9, $AL$2)), 0) + IF($AM$4 = AE$5, ($AM$3 * IF($AM9>0, $AM9, $AM$2)), 0) + IF($AN$4 = AE$5, ($AN$3 * IF($AN9>0, $AN9, $AN$2)), 0) + IF($AO$4 = AE$5, ($AO$3 * IF($AO9>0, $AO9, $AO$2)), 0) + IF($AP$4 = AE$5, ($AP$3 * IF($AP9>0, $AP9, $AP$2)), 0) + IF($AQ$4 = AE$5, ($AQ$3 * IF($AQ9>0, $AQ9, $AQ$2)), 0) + IF($AR$4 = AE$5, ($AR$3 * IF($AR9>0, $AR9, $AR$2)), 0) + IF($AS$4 = AE$5, ($AS$3 * IF($AS9>0, $AS9, $AS$2)), 0) + IF($AT$4 = AE$5, ($AT$3 * IF($AT9>0, $AT9, $AT$2)), 0) + IF($AU$4 = AE$5, ($AU$3 * IF($AU9>0, $AU9, $AU$2)), 0) + IF($AV$4 = AE$5, ($AV$3 * IF($AV9>0, IF($AV9 > $AV$2, $AV$2, $AV9), $AV$2)), 0), -1) -> 79 | AF9: 9 | AG9: 4 | AH9: 12 | AI9: 5 | AJ9: 2 | AK9: 8 | AL9: 7 | AN9: 4 | AO9: 2 | AP9: 11 | AQ9: 3 | AR9: 7 | AS9: 7 | AT9: 3 | AU9: 6 | AW9: =IFERROR(INDEX(measureables!$A:$J,MATCH($A9,measureables!$A:$A,FALSE),7), "") -> 6' 7.50'' | AX9: =IFERROR(INDEX(measureables!$A:$J,MATCH($A9,measureables!$A:$A,FALSE),9), "") -> 195.2 | AY9: =IFERROR(INDEX(measureables!$A:$J,MATCH($A9,measureables!$A:$A,FALSE),10), "") -> 6' 10.50'' | AZ9: =IFERROR(INDEX(measureables!$A:$J,MATCH($A9,measureables!$A:$A,FALSE),8), "") -> 8' 9.00'' | BA9: =IF(R9="",A9, IF(S9=S8,"",IF(S9=1," <!-- rankings --> "," </ol> " ) & "<h2> Tier " &S9 &" (~" &IF(MOD(ROUND(Q9,0),5)=0,ROUND(Q9,0),FLOOR(ROUND(Q9,0),5)&"+") &" FV)</h2> <ol start='" &R9 &" '> " ) & " <li><b><a target='_blank' href='" &X9 &"'>" &A9 &"</a></b> - <i> <a target='_blank' href='" &W9 &"'>" &B9 &" </a></b> - <a target='_blank'href='" &V9 &"'>" &C9 &"</a></b> </i></li> <ul style='list-style-type:none'>" &IF(D9<>""," <li>Grade: "&D9&" </li>","") &IF(E9<>""," <li>Age: "&ROUND(E9,1)&" </li>","") &IF(F9<>""," <li>Height: "&F9&" in </li>","") &IF(G9<>""," <li>Weight: "&G9&" lbs </li>","") &IF(H9<>""," <li>Wingspan: "&H9&" in </li>","") &IF(I9<>""," <li>Reach: "&I9&" in </li>","") &IF(J9<>""," <li>Ape: "&J9&" </li>","") &IF(L9<>""," <li>++: "&L9&" </li>","") &IF(M9<>""," <li>+: "&M9&" </li>","") &IF(N9<>""," <li>-: "&N9&" </li>","") &IF(O9<>""," <li>--: "&O9&" </li>","") &IF(P9<>""," <li>Additional Notes: "&P9&" </li>","") &" </ul> <br>" &IF(AND(R9<>"",R10="")," </ol> <!-- # end of rankings --> ","") ) -> </ol> <h2> Tier 2 (~50+ FV)</h2> <ol start='4 '> <li><b><a target='_blank' href='https://www.nba.com/draft/2022/prospects/dyson-daniels'>Dyson Daniels</a></b> - <i> <a target='_blank' href='https://www.nbadraft.net/players/dyson-daniels'>SG </a></b> - <a target='_blank'href='https://www.basketball-reference.com/players/d/daniedy01.html'>G League Ignite</a></b> </i></li> <ul style='list-style-type:none'> <li>Age: 19.3 </li> <li>Height: 79.5 in </li> <li>Weight: 195.2 lbs </li> <li>Wingspan: 82.5 in </li> <li>Reach: 105 in </li> <li>Ape: +3 </li> <li>++: basketball IQ, on-ball defense </li> <li>+: ball-handling, passing </li> <li>-: shooting, athleticism </li> <li>Additional Notes: high floor player based on passing, defense, and feel for the game, but still has untapped upside if the shooting improves </li> </ul> <br>
A10: Jeremy Sochan | B10: PF | C10: Baylor | D10: Freshman | E10: =YEARFRAC(Y10, $E$5, 1) -> 19.093771 | F10: =IFERROR(LEFT(AW10,FIND("'",AW10)-1)*12+SUBSTITUTE(MID(AW10,FIND("'",AW10)+1,LEN(AW10)),"''",""), "") -> 81 | G10: =AX10 -> 230 | H10: =IFERROR(LEFT(AY10,FIND("'",AY10)-1)*12+SUBSTITUTE(MID(AY10,FIND("'",AY10)+1,LEN(AY10)),"''",""), "") | I10: =IFERROR(LEFT(AZ10,FIND("'",AZ10)-1)*12+SUBSTITUTE(MID(AZ10,FIND("'",AZ10)+1,LEN(AZ10)),"''",""), "") | J10: =IFERROR(IF(AND(H10-F10>= 0, H10 > 0), "+", ""),"") & IFERROR(IF(AND(H10-F10>= -5, H10 > 0), H10-F10, ""),"") | K10: =IF(F10>0, IFERROR((H10-60)/(F10-60),""), "") | L10: defensive versatility | M10: age, size, motor | N10: playmaking | O10: shooting | P10: best defensive wing in the draft, but a dicey offensive projection | Q10: 52.8 | R10: =IF(Q10=-1, "", IF(Q10=0,"HM.",IF(Q10="","",RANK(Q10,Q$6:Q$980)))) -> 5 | S10: =IFERROR(IF(FLOOR(Q10,1)=FLOOR(Q9,1),S9, MAX(S$5:S9)+1),1) -> 2 | T10: =IFERROR(INDEX(actual!A:A,MATCH(A10,actual!B:B,FALSE)), "") -> 9 | U10: =IFERROR(INDEX(actual!C:C,MATCH(A10,actual!B:B,FALSE)), "") -> SAS | V10: =HYPERLINK(IF(D10="", "https://www.basketball-reference.com/international", "https://www.sports-reference.com/cbb") & "/players/" & LOWER(SUBSTITUTE(A10, " ", "-") & "-1.html")) -> https://www.sports-reference.com/cbb/players/jeremy-sochan-1.html | W10: =HYPERLINK("https://www.nbadraft.net/players/" & LOWER(SUBSTITUTE(A10, " ", "-") & "")) -> https://www.nbadraft.net/players/jeremy-sochan | X10: =HYPERLINK("https://www.nba.com/draft/2022/prospects/" & LOWER(SUBSTITUTE(A10, " ", "-") & "")) -> https://www.nba.com/draft/2022/prospects/jeremy-sochan | Y10: 37761 | Z10: =RANK(AC10,AC:AC,1) -> 7 | AA10: =RANK(AD10,AD:AD,1) -> 10 | AB10: =RANK(AE10,AE:AE,1) -> 6 | AC10: =AD10+AE10 -> 268 | AD10: =IFERROR( IF($AF$4 = AD$5, ($AF$3 * IF($AF10>0, $AF10, $AF$2)), 0) + IF($AG$4 = AD$5, ($AG$3 * IF($AG10>0, $AG10, $AG$2)), 0) + IF($AH$4 = AD$5, ($AH$3 * IF($AH10>0, $AH10, $AH$2)), 0) + IF($AI$4 = AD$5, ($AI$3 * IF($AI10>0, $AI10, $AI$2)), 0) + IF($AJ$4 = AD$5, ($AJ$3 * IF($AJ10>0, $AJ10, $AJ$2)), 0) + IF($AK$4 = AD$5, ($AK$3 * IF($AK10>0, $AK10, $AK$2)), 0) + IF($AL$4 = AD$5, ($AL$3 * IF($AL10>0, $AL10, $AL$2)), 0) + IF($AM$4 = AD$5, ($AM$3 * IF($AM10>0, $AM10, $AM$2)), 0) + IF($AN$4 = AD$5, ($AN$3 * IF($AN10>0, $AN10, $AN$2)), 0) + IF($AO$4 = AD$5, ($AO$3 * IF($AO10>0, $AO10, $AO$2)), 0) + IF($AP$4 = AD$5, ($AP$3 * IF($AP10>0, $AP10, $AP$2)), 0) + IF($AQ$4 = AD$5, ($AQ$3 * IF($AQ10>0, $AQ10, $AQ$2)), 0) + IF($AR$4 = AD$5, ($AR$3 * IF($AR10>0, $AR10, $AR$2)), 0) + IF($AS$4 = AD$5, ($AS$3 * IF($AS10>0, $AS10, $AS$2)), 0) + IF($AT$4 = AD$5, ($AT$3 * IF($AT10>0, $AT10, $AT$2)), 0) + IF($AU$4 = AD$5, ($AU$3 * IF($AU10>0, $AU10, $AU$2)), 0) + IF($AV$4 = AD$5, ($AV$3 * IF($AV10>0, IF($AV10 > $AV$2, $AV$2, $AV10), $AV$2)), 0), -1) -> 157 | AE10: =IFERROR( IF($AF$4 = AE$5, ($AF$3 * IF($AF10>0, $AF10, $AF$2)), 0) + IF($AG$4 = AE$5, ($AG$3 * IF($AG10>0, $AG10, $AG$2)), 0) + IF($AH$4 = AE$5, ($AH$3 * IF($AH10>0, $AH10, $AH$2)), 0) + IF($AI$4 = AE$5, ($AI$3 * IF($AI10>0, $AI10, $AI$2)), 0) + IF($AJ$4 = AE$5, ($AJ$3 * IF($AJ10>0, $AJ10, $AJ$2)), 0) + IF($AK$4 = AE$5, ($AK$3 * IF($AK10>0, $AK10, $AK$2)), 0) + IF($AL$4 = AE$5, ($AL$3 * IF($AL10>0, $AL10, $AL$2)), 0) + IF($AM$4 = AE$5, ($AM$3 * IF($AM10>0, $AM10, $AM$2)), 0) + IF($AN$4 = AE$5, ($AN$3 * IF($AN10>0, $AN10, $AN$2)), 0) + IF($AO$4 = AE$5, ($AO$3 * IF($AO10>0, $AO10, $AO$2)), 0) + IF($AP$4 = AE$5, ($AP$3 * IF($AP10>0, $AP10, $AP$2)), 0) + IF($AQ$4 = AE$5, ($AQ$3 * IF($AQ10>0, $AQ10, $AQ$2)), 0) + IF($AR$4 = AE$5, ($AR$3 * IF($AR10>0, $AR10, $AR$2)), 0) + IF($AS$4 = AE$5, ($AS$3 * IF($AS10>0, $AS10, $AS$2)), 0) + IF($AT$4 = AE$5, ($AT$3 * IF($AT10>0, $AT10, $AT$2)), 0) + IF($AU$4 = AE$5, ($AU$3 * IF($AU10>0, $AU10, $AU$2)), 0) + IF($AV$4 = AE$5, ($AV$3 * IF($AV10>0, IF($AV10 > $AV$2, $AV$2, $AV10), $AV$2)), 0), -1) -> 111 | AF10: 8 | AG10: 4 | AH10: 2 | AI10: 9 | AJ10: 12 | AK10: 9 | AN10: 5 | AO10: 2 | AP10: 12 | AQ10: 3 | AR10: 13 | AS10: 6 | AT10: 3 | AU10: 15 | AV10: 90 | AW10: =IFERROR(INDEX(measureables!$A:$J,MATCH($A10,measureables!$A:$A,FALSE),7), "") -> 6' 9'' | AX10: =IFERROR(INDEX(measureables!$A:$J,MATCH($A10,measureables!$A:$A,FALSE),9), "") -> 230 | AY10: =IFERROR(INDEX(measureables!$A:$J,MATCH($A10,measureables!$A:$A,FALSE),10), "") -> 0 | AZ10: =IFERROR(INDEX(measureables!$A:$J,MATCH($A10,measureables!$A:$A,FALSE),8), "") -> 0 | BA10: =IF(R10="",A10, IF(S10=S9,"",IF(S10=1," <!-- rankings --> "," </ol> " ) & "<h2> Tier " &S10 &" (~" &IF(MOD(ROUND(Q10,0),5)=0,ROUND(Q10,0),FLOOR(ROUND(Q10,0),5)&"+") &" FV)</h2> <ol start='" &R10 &" '> " ) & " <li><b><a target='_blank' href='" &X10 &"'>" &A10 &"</a></b> - <i> <a target='_blank' href='" &W10 &"'>" &B10 &" </a></b> - <a target='_blank'href='" &V10 &"'>" &C10 &"</a></b> </i></li> <ul style='list-style-type:none'>" &IF(D10<>""," <li>Grade: "&D10&" </li>","") &IF(E10<>""," <li>Age: "&ROUND(E10,1)&" </li>","") &IF(F10<>""," <li>Height: "&F10&" in </li>","") &IF(G10<>""," <li>Weight: "&G10&" lbs </li>","") &IF(H10<>""," <li>Wingspan: "&H10&" in </li>","") &IF(I10<>""," <li>Reach: "&I10&" in </li>","") &IF(J10<>""," <li>Ape: "&J10&" </li>","") &IF(L10<>""," <li>++: "&L10&" </li>","") &IF(M10<>""," <li>+: "&M10&" </li>","") &IF(N10<>""," <li>-: "&N10&" </li>","") &IF(O10<>""," <li>--: "&O10&" </li>","") &IF(P10<>""," <li>Additional Notes: "&P10&" </li>","") &" </ul> <br>" &IF(AND(R10<>"",R11="")," </ol> <!-- # end of rankings --> ","") ) -> <li><b><a target='_blank' href='https://www.nba.com/draft/2022/prospects/jeremy-sochan'>Jeremy Sochan</a></b> - <i> <a target='_blank' href='https://www.nbadraft.net/players/jeremy-sochan'>PF </a></b> - <a target='_blank'href='https://www.sports-reference.com/cbb/players/jeremy-sochan-1.html'>Baylor</a></b> </i></li> <ul style='list-style-type:none'> <li>Grade: Freshman </li> <li>Age: 19.1 </li> <li>Height: 81 in </li> <li>Weight: 230 lbs </li> <li>++: defensive versatility </li> <li>+: age, size, motor </li> <li>-: playmaking </li> <li>--: shooting </li> <li>Additional Notes: best defensive wing in the draft, but a dicey offensive projection </li> </ul> <br>
A11: Bennedict Mathurin | B11: SG | C11: Arizona | D11: Sophomore | E11: =YEARFRAC(Y11, $E$5, 1) -> 20.011604 | F11: =IFERROR(LEFT(AW11,FIND("'",AW11)-1)*12+SUBSTITUTE(MID(AW11,FIND("'",AW11)+1,LEN(AW11)),"''",""), "") -> 78 | G11: =AX11 -> 204.6 | H11: =IFERROR(LEFT(AY11,FIND("'",AY11)-1)*12+SUBSTITUTE(MID(AY11,FIND("'",AY11)+1,LEN(AY11)),"''",""), "") -> 81 | I11: =IFERROR(LEFT(AZ11,FIND("'",AZ11)-1)*12+SUBSTITUTE(MID(AZ11,FIND("'",AZ11)+1,LEN(AZ11)),"''",""), "") -> 104 | J11: =IFERROR(IF(AND(H11-F11>= 0, H11 > 0), "+", ""),"") & IFERROR(IF(AND(H11-F11>= -5, H11 > 0), H11-F11, ""),"") -> +3 | K11: =IF(F11>0, IFERROR((H11-60)/(F11-60),""), "") -> 1.1666667 | M11: age, shooting, size, athleticism | N11: defensive (not a true negative, but not enough of a positive to be an ideal 3+D guy), offensive creation | P11: safe bet to be an NBA contributor, but may fit better as a secondary wing on both sides of the ball | Q11: 52.7 | R11: =IF(Q11=-1, "", IF(Q11=0,"HM.",IF(Q11="","",RANK(Q11,Q$6:Q$980)))) -> 6 | S11: =IFERROR(IF(FLOOR(Q11,1)=FLOOR(Q10,1),S10, MAX(S$5:S10)+1),1) -> 2 | T11: =IFERROR(INDEX(actual!A:A,MATCH(A11,actual!B:B,FALSE)), "") -> 6 | U11: =IFERROR(INDEX(actual!C:C,MATCH(A11,actual!B:B,FALSE)), "") -> IND | V11: =HYPERLINK(IF(D11="", "https://www.basketball-reference.com/international", "https://www.sports-reference.com/cbb") & "/players/" & LOWER(SUBSTITUTE(A11, " ", "-") & "-1.html")) -> https://www.sports-reference.com/cbb/players/bennedict-mathurin-1.html | W11: =HYPERLINK("https://www.nbadraft.net/players/" & LOWER(SUBSTITUTE(A11, " ", "-") & "")) -> https://www.nbadraft.net/players/bennedict-mathurin | X11: =HYPERLINK("https://www.nba.com/draft/2022/prospects/" & LOWER(SUBSTITUTE(A11, " ", "-") & "")) -> https://www.nba.com/draft/2022/prospects/bennedict-mathurin | Y11: 37426 | Z11: =RANK(AC11,AC:AC,1) -> 5 | AA11: =RANK(AD11,AD:AD,1) -> 6 | AB11: =RANK(AE11,AE:AE,1) -> 5 | AC11: =AD11+AE11 -> 221 | AD11: =IFERROR( IF($AF$4 = AD$5, ($AF$3 * IF($AF11>0, $AF11, $AF$2)), 0) + IF($AG$4 = AD$5, ($AG$3 * IF($AG11>0, $AG11, $AG$2)), 0) + IF($AH$4 = AD$5, ($AH$3 * IF($AH11>0, $AH11, $AH$2)), 0) + IF($AI$4 = AD$5, ($AI$3 * IF($AI11>0, $AI11, $AI$2)), 0) + IF($AJ$4 = AD$5, ($AJ$3 * IF($AJ11>0, $AJ11, $AJ$2)), 0) + IF($AK$4 = AD$5, ($AK$3 * IF($AK11>0, $AK11, $AK$2)), 0) + IF($AL$4 = AD$5, ($AL$3 * IF($AL11>0, $AL11, $AL$2)), 0) + IF($AM$4 = AD$5, ($AM$3 * IF($AM11>0, $AM11, $AM$2)), 0) + IF($AN$4 = AD$5, ($AN$3 * IF($AN11>0, $AN11, $AN$2)), 0) + IF($AO$4 = AD$5, ($AO$3 * IF($AO11>0, $AO11, $AO$2)), 0) + IF($AP$4 = AD$5, ($AP$3 * IF($AP11>0, $AP11, $AP$2)), 0) + IF($AQ$4 = AD$5, ($AQ$3 * IF($AQ11>0, $AQ11, $AQ$2)), 0) + IF($AR$4 = AD$5, ($AR$3 * IF($AR11>0, $AR11, $AR$2)), 0) + IF($AS$4 = AD$5, ($AS$3 * IF($AS11>0, $AS11, $AS$2)), 0) + IF($AT$4 = AD$5, ($AT$3 * IF($AT11>0, $AT11, $AT$2)), 0) + IF($AU$4 = AD$5, ($AU$3 * IF($AU11>0, $AU11, $AU$2)), 0) + IF($AV$4 = AD$5, ($AV$3 * IF($AV11>0, IF($AV11 > $AV$2, $AV$2, $AV11), $AV$2)), 0), -1) -> 122 | AE11: =IFERROR( IF($AF$4 = AE$5, ($AF$3 * IF($AF11>0, $AF11, $AF$2)), 0) + IF($AG$4 = AE$5, ($AG$3 * IF($AG11>0, $AG11, $AG$2)), 0) + IF($AH$4 = AE$5, ($AH$3 * IF($AH11>0, $AH11, $AH$2)), 0) + IF($AI$4 = AE$5, ($AI$3 * IF($AI11>0, $AI11, $AI$2)), 0) + IF($AJ$4 = AE$5, ($AJ$3 * IF($AJ11>0, $AJ11, $AJ$2)), 0) + IF($AK$4 = AE$5, ($AK$3 * IF($AK11>0, $AK11, $AK$2)), 0) + IF($AL$4 = AE$5, ($AL$3 * IF($AL11>0, $AL11, $AL$2)), 0) + IF($AM$4 = AE$5, ($AM$3 * IF($AM11>0, $AM11, $AM$2)), 0) + IF($AN$4 = AE$5, ($AN$3 * IF($AN11>0, $AN11, $AN$2)), 0) + IF($AO$4 = AE$5, ($AO$3 * IF($AO11>0, $AO11, $AO$2)), 0) + IF($AP$4 = AE$5, ($AP$3 * IF($AP11>0, $AP11, $AP$2)), 0) + IF($AQ$4 = AE$5, ($AQ$3 * IF($AQ11>0, $AQ11, $AQ$2)), 0) + IF($AR$4 = AE$5, ($AR$3 * IF($AR11>0, $AR11, $AR$2)), 0) + IF($AS$4 = AE$5, ($AS$3 * IF($AS11>0, $AS11, $AS$2)), 0) + IF($AT$4 = AE$5, ($AT$3 * IF($AT11>0, $AT11, $AT$2)), 0) + IF($AU$4 = AE$5, ($AU$3 * IF($AU11>0, $AU11, $AU$2)), 0) + IF($AV$4 = AE$5, ($AV$3 * IF($AV11>0, IF($AV11 > $AV$2, $AV$2, $AV11), $AV$2)), 0), -1) -> 99 | AF11: 5 | AG11: 3 | AH11: 9 | AI11: 7 | AJ11: 7 | AK11: 14 | AL11: 14 | AN11: 7 | AO11: 2 | AP11: 6 | AQ11: 3 | AR11: 8 | AS11: 5 | AT11: 3 | AU11: 8 | AV11: 91 | AW11: =IFERROR(INDEX(measureables!$A:$J,MATCH($A11,measureables!$A:$A,FALSE),7), "") -> 6' 6.00'' | AX11: =IFERROR(INDEX(measureables!$A:$J,MATCH($A11,measureables!$A:$A,FALSE),9), "") -> 204.6 | AY11: =IFERROR(INDEX(measureables!$A:$J,MATCH($A11,measureables!$A:$A,FALSE),10), "") -> 6' 9.00'' | AZ11: =IFERROR(INDEX(measureables!$A:$J,MATCH($A11,measureables!$A:$A,FALSE),8), "") -> 8' 8.00'' | BA11: =IF(R11="",A11, IF(S11=S10,"",IF(S11=1," <!-- rankings --> "," </ol> " ) & "<h2> Tier " &S11 &" (~" &IF(MOD(ROUND(Q11,0),5)=0,ROUND(Q11,0),FLOOR(ROUND(Q11,0),5)&"+") &" FV)</h2> <ol start='" &R11 &" '> " ) & " <li><b><a target='_blank' href='" &X11 &"'>" &A11 &"</a></b> - <i> <a target='_blank' href='" &W11 &"'>" &B11 &" </a></b> - <a target='_blank'href='" &V11 &"'>" &C11 &"</a></b> </i></li> <ul style='list-style-type:none'>" &IF(D11<>""," <li>Grade: "&D11&" </li>","") &IF(E11<>""," <li>Age: "&ROUND(E11,1)&" </li>","") &IF(F11<>""," <li>Height: "&F11&" in </li>","") &IF(G11<>""," <li>Weight: "&G11&" lbs </li>","") &IF(H11<>""," <li>Wingspan: "&H11&" in </li>","") &IF(I11<>""," <li>Reach: "&I11&" in </li>","") &IF(J11<>""," <li>Ape: "&J11&" </li>","") &IF(L11<>""," <li>++: "&L11&" </li>","") &IF(M11<>""," <li>+: "&M11&" </li>","") &IF(N11<>""," <li>-: "&N11&" </li>","") &IF(O11<>""," <li>--: "&O11&" </li>","") &IF(P11<>""," <li>Additional Notes: "&P11&" </li>","") &" </ul> <br>" &IF(AND(R11<>"",R12="")," </ol> <!-- # end of rankings --> ","") ) -> <li><b><a target='_blank' href='https://www.nba.com/draft/2022/prospects/bennedict-mathurin'>Bennedict Mathurin</a></b> - <i> <a target='_blank' href='https://www.nbadraft.net/players/bennedict-mathurin'>SG </a></b> - <a target='_blank'href='https://www.sports-reference.com/cbb/players/bennedict-mathurin-1.html'>Arizona</a></b> </i></li> <ul style='list-style-type:none'> <li>Grade: Sophomore </li> <li>Age: 20 </li> <li>Height: 78 in </li> <li>Weight: 204.6 lbs </li> <li>Wingspan: 81 in </li> <li>Reach: 104 in </li> <li>Ape: +3 </li> <li>+: age, shooting, size, athleticism </li> <li>-: defensive (not a true negative, but not enough of a positive to be an ideal 3+D guy), offensive creation </li> <li>Additional Notes: safe bet to be an NBA contributor, but may fit better as a secondary wing on both sides of the ball </li> </ul> <br>
A12: Jaden Ivey | B12: PG | C12: Purdue | D12: Sophomore | E12: =YEARFRAC(Y12, $E$5, 1) -> 20.356584 | F12: =IFERROR(LEFT(AW12,FIND("'",AW12)-1)*12+SUBSTITUTE(MID(AW12,FIND("'",AW12)+1,LEN(AW12)),"''",""), "") -> 76 | G12: =AX12 -> 195 | H12: =IFERROR(LEFT(AY12,FIND("'",AY12)-1)*12+SUBSTITUTE(MID(AY12,FIND("'",AY12)+1,LEN(AY12)),"''",""), "") | I12: =IFERROR(LEFT(AZ12,FIND("'",AZ12)-1)*12+SUBSTITUTE(MID(AZ12,FIND("'",AZ12)+1,LEN(AZ12)),"''",""), "") | J12: =IFERROR(IF(AND(H12-F12>= 0, H12 > 0), "+", ""),"") & IFERROR(IF(AND(H12-F12>= -5, H12 > 0), H12-F12, ""),"") | K12: =IF(F12>0, IFERROR((H12-60)/(F12-60),""), "") | L12: athleticism, shot creation | M12: dribble penetration | N12: decision making, defensive motor, offensive creation | P12: phreak athlete, but best role is likely a volume scoring 6th man, which isn't a great archtype to chase. That said, his 99th percentile upside of a primary offensive engine is one of the highest in the draft | Q12: 52.6 | R12: =IF(Q12=-1, "", IF(Q12=0,"HM.",IF(Q12="","",RANK(Q12,Q$6:Q$980)))) -> 7 | S12: =IFERROR(IF(FLOOR(Q12,1)=FLOOR(Q11,1),S11, MAX(S$5:S11)+1),1) -> 2 | T12: =IFERROR(INDEX(actual!A:A,MATCH(A12,actual!B:B,FALSE)), "") -> 5 | U12: =IFERROR(INDEX(actual!C:C,MATCH(A12,actual!B:B,FALSE)), "") -> DET | V12: =HYPERLINK(IF(D12="", "https://www.basketball-reference.com/international", "https://www.sports-reference.com/cbb") & "/players/" & LOWER(SUBSTITUTE(A12, " ", "-") & "-1.html")) -> https://www.sports-reference.com/cbb/players/jaden-ivey-1.html | W12: =HYPERLINK("https://www.nbadraft.net/players/" & LOWER(SUBSTITUTE(A12, " ", "-") & "")) -> https://www.nbadraft.net/players/jaden-ivey | X12: =HYPERLINK("https://www.nba.com/draft/2022/prospects/" & LOWER(SUBSTITUTE(A12, " ", "-") & "")) -> https://www.nba.com/draft/2022/prospects/jaden-ivey | Y12: 37300 | Z12: =RANK(AC12,AC:AC,1) -> 11 | AA12: =RANK(AD12,AD:AD,1) -> 4 | AB12: =RANK(AE12,AE:AE,1) -> 23 | AC12: =AD12+AE12 -> 392 | AD12: =IFERROR( IF($AF$4 = AD$5, ($AF$3 * IF($AF12>0, $AF12, $AF$2)), 0) + IF($AG$4 = AD$5, ($AG$3 * IF($AG12>0, $AG12, $AG$2)), 0) + IF($AH$4 = AD$5, ($AH$3 * IF($AH12>0, $AH12, $AH$2)), 0) + IF($AI$4 = AD$5, ($AI$3 * IF($AI12>0, $AI12, $AI$2)), 0) + IF($AJ$4 = AD$5, ($AJ$3 * IF($AJ12>0, $AJ12, $AJ$2)), 0) + IF($AK$4 = AD$5, ($AK$3 * IF($AK12>0, $AK12, $AK$2)), 0) + IF($AL$4 = AD$5, ($AL$3 * IF($AL12>0, $AL12, $AL$2)), 0) + IF($AM$4 = AD$5, ($AM$3 * IF($AM12>0, $AM12, $AM$2)), 0) + IF($AN$4 = AD$5, ($AN$3 * IF($AN12>0, $AN12, $AN$2)), 0) + IF($AO$4 = AD$5, ($AO$3 * IF($AO12>0, $AO12, $AO$2)), 0) + IF($AP$4 = AD$5, ($AP$3 * IF($AP12>0, $AP12, $AP$2)), 0) + IF($AQ$4 = AD$5, ($AQ$3 * IF($AQ12>0, $AQ12, $AQ$2)), 0) + IF($AR$4 = AD$5, ($AR$3 * IF($AR12>0, $AR12, $AR$2)), 0) + IF($AS$4 = AD$5, ($AS$3 * IF($AS12>0, $AS12, $AS$2)), 0) + IF($AT$4 = AD$5, ($AT$3 * IF($AT12>0, $AT12, $AT$2)), 0) + IF($AU$4 = AD$5, ($AU$3 * IF($AU12>0, $AU12, $AU$2)), 0) + IF($AV$4 = AD$5, ($AV$3 * IF($AV12>0, IF($AV12 > $AV$2, $AV$2, $AV12), $AV$2)), 0), -1) -> 97 | AE12: =IFERROR( IF($AF$4 = AE$5, ($AF$3 * IF($AF12>0, $AF12, $AF$2)), 0) + IF($AG$4 = AE$5, ($AG$3 * IF($AG12>0, $AG12, $AG$2)), 0) + IF($AH$4 = AE$5, ($AH$3 * IF($AH12>0, $AH12, $AH$2)), 0) + IF($AI$4 = AE$5, ($AI$3 * IF($AI12>0, $AI12, $AI$2)), 0) + IF($AJ$4 = AE$5, ($AJ$3 * IF($AJ12>0, $AJ12, $AJ$2)), 0) + IF($AK$4 = AE$5, ($AK$3 * IF($AK12>0, $AK12, $AK$2)), 0) + IF($AL$4 = AE$5, ($AL$3 * IF($AL12>0, $AL12, $AL$2)), 0) + IF($AM$4 = AE$5, ($AM$3 * IF($AM12>0, $AM12, $AM$2)), 0) + IF($AN$4 = AE$5, ($AN$3 * IF($AN12>0, $AN12, $AN$2)), 0) + IF($AO$4 = AE$5, ($AO$3 * IF($AO12>0, $AO12, $AO$2)), 0) + IF($AP$4 = AE$5, ($AP$3 * IF($AP12>0, $AP12, $AP$2)), 0) + IF($AQ$4 = AE$5, ($AQ$3 * IF($AQ12>0, $AQ12, $AQ$2)), 0) + IF($AR$4 = AE$5, ($AR$3 * IF($AR12>0, $AR12, $AR$2)), 0) + IF($AS$4 = AE$5, ($AS$3 * IF($AS12>0, $AS12, $AS$2)), 0) + IF($AT$4 = AE$5, ($AT$3 * IF($AT12>0, $AT12, $AT$2)), 0) + IF($AU$4 = AE$5, ($AU$3 * IF($AU12>0, $AU12, $AU$2)), 0) + IF($AV$4 = AE$5, ($AV$3 * IF($AV12>0, IF($AV12 > $AV$2, $AV$2, $AV12), $AV$2)), 0), -1) -> 295 | AF12: 3 | AG12: 2 | AH12: 46 | AI12: 12 | AJ12: 13 | AK12: 15 | AL12: 33 | AN12: 8 | AO12: 2 | AP12: 4 | AQ12: 2 | AR12: 5 | AS12: 4 | AT12: 2 | AU12: 4 | AV12: 87 | AW12: =IFERROR(INDEX(measureables!$A:$J,MATCH($A12,measureables!$A:$A,FALSE),7), "") -> 6' 4'' | AX12: =IFERROR(INDEX(measureables!$A:$J,MATCH($A12,measureables!$A:$A,FALSE),9), "") -> 195 | AY12: =IFERROR(INDEX(measureables!$A:$J,MATCH($A12,measureables!$A:$A,FALSE),10), "") -> 0 | AZ12: =IFERROR(INDEX(measureables!$A:$J,MATCH($A12,measureables!$A:$A,FALSE),8), "") -> 0 | BA12: =IF(R12="",A12, IF(S12=S11,"",IF(S12=1," <!-- rankings --> "," </ol> " ) & "<h2> Tier " &S12 &" (~" &IF(MOD(ROUND(Q12,0),5)=0,ROUND(Q12,0),FLOOR(ROUND(Q12,0),5)&"+") &" FV)</h2> <ol start='" &R12 &" '> " ) & " <li><b><a target='_blank' href='" &X12 &"'>" &A12 &"</a></b> - <i> <a target='_blank' href='" &W12 &"'>" &B12 &" </a></b> - <a target='_blank'href='" &V12 &"'>" &C12 &"</a></b> </i></li> <ul style='list-style-type:none'>" &IF(D12<>""," <li>Grade: "&D12&" </li>","") &IF(E12<>""," <li>Age: "&ROUND(E12,1)&" </li>","") &IF(F12<>""," <li>Height: "&F12&" in </li>","") &IF(G12<>""," <li>Weight: "&G12&" lbs </li>","") &IF(H12<>""," <li>Wingspan: "&H12&" in </li>","") &IF(I12<>""," <li>Reach: "&I12&" in </li>","") &IF(J12<>""," <li>Ape: "&J12&" </li>","") &IF(L12<>""," <li>++: "&L12&" </li>","") &IF(M12<>""," <li>+: "&M12&" </li>","") &IF(N12<>""," <li>-: "&N12&" </li>","") &IF(O12<>""," <li>--: "&O12&" </li>","") &IF(P12<>""," <li>Additional Notes: "&P12&" </li>","") &" </ul> <br>" &IF(AND(R12<>"",R13="")," </ol> <!-- # end of rankings --> ","") ) -> <li><b><a target='_blank' href='https://www.nba.com/draft/2022/prospects/jaden-ivey'>Jaden Ivey</a></b> - <i> <a target='_blank' href='https://www.nbadraft.net/players/jaden-ivey'>PG </a></b> - <a target='_blank'href='https://www.sports-reference.com/cbb/players/jaden-ivey-1.html'>Purdue</a></b> </i></li> <ul style='list-style-type:none'> <li>Grade: Sophomore </li> <li>Age: 20.4 </li> <li>Height: 76 in </li> <li>Weight: 195 lbs </li> <li>++: athleticism, shot creation </li> <li>+: dribble penetration </li> <li>-: decision making, defensive motor, offensive creation </li> <li>Additional Notes: phreak athlete, but best role is likely a volume scoring 6th man, which isn't a great archtype to chase. That said, his 99th percentile upside of a primary offensive engine is one of the highest in the draft </li> </ul> <br>
A13: Keegan Murray | B13: PF | C13: Iowa | D13: Sophomore | E13: =YEARFRAC(Y13, $E$5, 1) -> 21.841924 | F13: =IFERROR(LEFT(AW13,FIND("'",AW13)-1)*12+SUBSTITUTE(MID(AW13,FIND("'",AW13)+1,LEN(AW13)),"''",""), "") -> 80 | G13: =AX13 -> 215 | H13: =IFERROR(LEFT(AY13,FIND("'",AY13)-1)*12+SUBSTITUTE(MID(AY13,FIND("'",AY13)+1,LEN(AY13)),"''",""), "") -> 83 | I13: =IFERROR(LEFT(AZ13,FIND("'",AZ13)-1)*12+SUBSTITUTE(MID(AZ13,FIND("'",AZ13)+1,LEN(AZ13)),"''",""), "") | J13: =IFERROR(IF(AND(H13-F13>= 0, H13 > 0), "+", ""),"") & IFERROR(IF(AND(H13-F13>= -5, H13 > 0), H13-F13, ""),"") -> +3 | K13: =IF(F13>0, IFERROR((H13-60)/(F13-60),""), "") -> 1.15 | L13: offensive production | M13: motor, positioning | N13: athleticism | O13: age | P13: high level scorer against non-elite competition. High floor as rotational player who should be able to score against second units at the very least. Also he looks a lot like Brandon Clarke, and maybe plays a little like him | Q13: 52.5 | R13: =IF(Q13=-1, "", IF(Q13=0,"HM.",IF(Q13="","",RANK(Q13,Q$6:Q$980)))) -> 8 | S13: =IFERROR(IF(FLOOR(Q13,1)=FLOOR(Q12,1),S12, MAX(S$5:S12)+1),1) -> 2 | T13: =IFERROR(INDEX(actual!A:A,MATCH(A13,actual!B:B,FALSE)), "") -> 4 | U13: =IFERROR(INDEX(actual!C:C,MATCH(A13,actual!B:B,FALSE)), "") -> SAC | V13: =HYPERLINK(IF(D13="", "https://www.basketball-reference.com/international", "https://www.sports-reference.com/cbb") & "/players/" & LOWER(SUBSTITUTE(A13, " ", "-") & "-1.html")) -> https://www.sports-reference.com/cbb/players/keegan-murray-1.html | W13: =HYPERLINK("https://www.nbadraft.net/players/" & LOWER(SUBSTITUTE(A13, " ", "-") & "")) -> https://www.nbadraft.net/players/keegan-murray | X13: =HYPERLINK("https://www.nba.com/draft/2022/prospects/" & LOWER(SUBSTITUTE(A13, " ", "-") & "")) -> https://www.nba.com/draft/2022/prospects/keegan-murray | Y13: 36757 | Z13: =RANK(AC13,AC:AC,1) -> 8 | AA13: =RANK(AD13,AD:AD,1) -> 9 | AB13: =RANK(AE13,AE:AE,1) -> 9 | AC13: =AD13+AE13 -> 290 | AD13: =IFERROR( IF($AF$4 = AD$5, ($AF$3 * IF($AF13>0, $AF13, $AF$2)), 0) + IF($AG$4 = AD$5, ($AG$3 * IF($AG13>0, $AG13, $AG$2)), 0) + IF($AH$4 = AD$5, ($AH$3 * IF($AH13>0, $AH13, $AH$2)), 0) + IF($AI$4 = AD$5, ($AI$3 * IF($AI13>0, $AI13, $AI$2)), 0) + IF($AJ$4 = AD$5, ($AJ$3 * IF($AJ13>0, $AJ13, $AJ$2)), 0) + IF($AK$4 = AD$5, ($AK$3 * IF($AK13>0, $AK13, $AK$2)), 0) + IF($AL$4 = AD$5, ($AL$3 * IF($AL13>0, $AL13, $AL$2)), 0) + IF($AM$4 = AD$5, ($AM$3 * IF($AM13>0, $AM13, $AM$2)), 0) + IF($AN$4 = AD$5, ($AN$3 * IF($AN13>0, $AN13, $AN$2)), 0) + IF($AO$4 = AD$5, ($AO$3 * IF($AO13>0, $AO13, $AO$2)), 0) + IF($AP$4 = AD$5, ($AP$3 * IF($AP13>0, $AP13, $AP$2)), 0) + IF($AQ$4 = AD$5, ($AQ$3 * IF($AQ13>0, $AQ13, $AQ$2)), 0) + IF($AR$4 = AD$5, ($AR$3 * IF($AR13>0, $AR13, $AR$2)), 0) + IF($AS$4 = AD$5, ($AS$3 * IF($AS13>0, $AS13, $AS$2)), 0) + IF($AT$4 = AD$5, ($AT$3 * IF($AT13>0, $AT13, $AT$2)), 0) + IF($AU$4 = AD$5, ($AU$3 * IF($AU13>0, $AU13, $AU$2)), 0) + IF($AV$4 = AD$5, ($AV$3 * IF($AV13>0, IF($AV13 > $AV$2, $AV$2, $AV13), $AV$2)), 0), -1) -> 138 | AE13: =IFERROR( IF($AF$4 = AE$5, ($AF$3 * IF($AF13>0, $AF13, $AF$2)), 0) + IF($AG$4 = AE$5, ($AG$3 * IF($AG13>0, $AG13, $AG$2)), 0) + IF($AH$4 = AE$5, ($AH$3 * IF($AH13>0, $AH13, $AH$2)), 0) + IF($AI$4 = AE$5, ($AI$3 * IF($AI13>0, $AI13, $AI$2)), 0) + IF($AJ$4 = AE$5, ($AJ$3 * IF($AJ13>0, $AJ13, $AJ$2)), 0) + IF($AK$4 = AE$5, ($AK$3 * IF($AK13>0, $AK13, $AK$2)), 0) + IF($AL$4 = AE$5, ($AL$3 * IF($AL13>0, $AL13, $AL$2)), 0) + IF($AM$4 = AE$5, ($AM$3 * IF($AM13>0, $AM13, $AM$2)), 0) + IF($AN$4 = AE$5, ($AN$3 * IF($AN13>0, $AN13, $AN$2)), 0) + IF($AO$4 = AE$5, ($AO$3 * IF($AO13>0, $AO13, $AO$2)), 0) + IF($AP$4 = AE$5, ($AP$3 * IF($AP13>0, $AP13, $AP$2)), 0) + IF($AQ$4 = AE$5, ($AQ$3 * IF($AQ13>0, $AQ13, $AQ$2)), 0) + IF($AR$4 = AE$5, ($AR$3 * IF($AR13>0, $AR13, $AR$2)), 0) + IF($AS$4 = AE$5, ($AS$3 * IF($AS13>0, $AS13, $AS$2)), 0) + IF($AT$4 = AE$5, ($AT$3 * IF($AT13>0, $AT13, $AT$2)), 0) + IF($AU$4 = AE$5, ($AU$3 * IF($AU13>0, $AU13, $AU$2)), 0) + IF($AV$4 = AE$5, ($AV$3 * IF($AV13>0, IF($AV13 > $AV$2, $AV$2, $AV13), $AV$2)), 0), -1) -> 152 | AF13: 7 | AG13: 3 | AH13: 13 | AI13: 3 | AJ13: 28 | AK13: 6 | AL13: 4 | AN13: 12 | AO13: 2 | AP13: 9 | AQ13: 3 | AR13: 6 | AS13: 8 | AT13: 3 | AU13: 5 | AW13: =IFERROR(INDEX(measureables!$A:$J,MATCH($A13,measureables!$A:$A,FALSE),7), "") -> 6' 8'' | AX13: =IFERROR(INDEX(measureables!$A:$J,MATCH($A13,measureables!$A:$A,FALSE),9), "") -> 215 | AY13: =IFERROR(INDEX(measureables!$A:$J,MATCH($A13,measureables!$A:$A,FALSE),10), "") -> 6' 11'' | AZ13: =IFERROR(INDEX(measureables!$A:$J,MATCH($A13,measureables!$A:$A,FALSE),8), "") -> 0 | BA13: =IF(R13="",A13, IF(S13=S12,"",IF(S13=1," <!-- rankings --> "," </ol> " ) & "<h2> Tier " &S13 &" (~" &IF(MOD(ROUND(Q13,0),5)=0,ROUND(Q13,0),FLOOR(ROUND(Q13,0),5)&"+") &" FV)</h2> <ol start='" &R13 &" '> " ) & " <li><b><a target='_blank' href='" &X13 &"'>" &A13 &"</a></b> - <i> <a target='_blank' href='" &W13 &"'>" &B13 &" </a></b> - <a target='_blank'href='" &V13 &"'>" &C13 &"</a></b> </i></li> <ul style='list-style-type:none'>" &IF(D13<>""," <li>Grade: "&D13&" </li>","") &IF(E13<>""," <li>Age: "&ROUND(E13,1)&" </li>","") &IF(F13<>""," <li>Height: "&F13&" in </li>","") &IF(G13<>""," <li>Weight: "&G13&" lbs </li>","") &IF(H13<>""," <li>Wingspan: "&H13&" in </li>","") &IF(I13<>""," <li>Reach: "&I13&" in </li>","") &IF(J13<>""," <li>Ape: "&J13&" </li>","") &IF(L13<>""," <li>++: "&L13&" </li>","") &IF(M13<>""," <li>+: "&M13&" </li>","") &IF(N13<>""," <li>-: "&N13&" </li>","") &IF(O13<>""," <li>--: "&O13&" </li>","") &IF(P13<>""," <li>Additional Notes: "&P13&" </li>","") &" </ul> <br>" &IF(AND(R13<>"",R14="")," </ol> <!-- # end of rankings --> ","") ) -> <li><b><a target='_blank' href='https://www.nba.com/draft/2022/prospects/keegan-murray'>Keegan Murray</a></b> - <i> <a target='_blank' href='https://www.nbadraft.net/players/keegan-murray'>PF </a></b> - <a target='_blank'href='https://www.sports-reference.com/cbb/players/keegan-murray-1.html'>Iowa</a></b> </i></li> <ul style='list-style-type:none'> <li>Grade: Sophomore </li> <li>Age: 21.8 </li> <li>Height: 80 in </li> <li>Weight: 215 lbs </li> <li>Wingspan: 83 in </li> <li>Ape: +3 </li> <li>++: offensive production </li> <li>+: motor, positioning </li> <li>-: athleticism </li> <li>--: age </li> <li>Additional Notes: high level scorer against non-elite competition. High floor as rotational player who should be able to score against second units at the very least. Also he looks a lot like Brandon Clarke, and maybe plays a little like him </li> </ul> <br>
A14: Tari Eason | B14: PF | C14: LSU | D14: Sophomore | E14: =YEARFRAC(Y14, $E$5, 1) -> 21.121095 | F14: =IFERROR(LEFT(AW14,FIND("'",AW14)-1)*12+SUBSTITUTE(MID(AW14,FIND("'",AW14)+1,LEN(AW14)),"''",""), "") -> 80 | G14: =AX14 -> 217.4 | H14: =IFERROR(LEFT(AY14,FIND("'",AY14)-1)*12+SUBSTITUTE(MID(AY14,FIND("'",AY14)+1,LEN(AY14)),"''",""), "") -> 86 | I14: =IFERROR(LEFT(AZ14,FIND("'",AZ14)-1)*12+SUBSTITUTE(MID(AZ14,FIND("'",AZ14)+1,LEN(AZ14)),"''",""), "") -> 107.5 | J14: =IFERROR(IF(AND(H14-F14>= 0, H14 > 0), "+", ""),"") & IFERROR(IF(AND(H14-F14>= -5, H14 > 0), H14-F14, ""),"") -> +6 | K14: =IF(F14>0, IFERROR((H14-60)/(F14-60),""), "") -> 1.3 | L14: enegy, defense | M14: rim attacking | N14: wildness, fouling, shooting, age | P14: high energy wing with a defense first mindset, but plays a little out of control and is older than the other wings in this tier | Q14: 52.4 | R14: =IF(Q14=-1, "", IF(Q14=0,"HM.",IF(Q14="","",RANK(Q14,Q$6:Q$980)))) -> 9 | S14: =IFERROR(IF(FLOOR(Q14,1)=FLOOR(Q13,1),S13, MAX(S$5:S13)+1),1) -> 2 | T14: =IFERROR(INDEX(actual!A:A,MATCH(A14,actual!B:B,FALSE)), "") -> 17 | U14: =IFERROR(INDEX(actual!C:C,MATCH(A14,actual!B:B,FALSE)), "") -> HOU | V14: =HYPERLINK(IF(D14="", "https://www.basketball-reference.com/international", "https://www.sports-reference.com/cbb") & "/players/" & LOWER(SUBSTITUTE(A14, " ", "-") & "-1.html")) -> https://www.sports-reference.com/cbb/players/tari-eason-1.html | W14: =HYPERLINK("https://www.nbadraft.net/players/" & LOWER(SUBSTITUTE(A14, " ", "-") & "")) -> https://www.nbadraft.net/players/tari-eason | X14: =HYPERLINK("https://www.nba.com/draft/2022/prospects/" & LOWER(SUBSTITUTE(A14, " ", "-") & "")) -> https://www.nba.com/draft/2022/prospects/tari-eason | Y14: 37021 | Z14: =RANK(AC14,AC:AC,1) -> 12 | AA14: =RANK(AD14,AD:AD,1) -> 12 | AB14: =RANK(AE14,AE:AE,1) -> 15 | AC14: =AD14+AE14 -> 415 | AD14: =IFERROR( IF($AF$4 = AD$5, ($AF$3 * IF($AF14>0, $AF14, $AF$2)), 0) + IF($AG$4 = AD$5, ($AG$3 * IF($AG14>0, $AG14, $AG$2)), 0) + IF($AH$4 = AD$5, ($AH$3 * IF($AH14>0, $AH14, $AH$2)), 0) + IF($AI$4 = AD$5, ($AI$3 * IF($AI14>0, $AI14, $AI$2)), 0) + IF($AJ$4 = AD$5, ($AJ$3 * IF($AJ14>0, $AJ14, $AJ$2)), 0) + IF($AK$4 = AD$5, ($AK$3 * IF($AK14>0, $AK14, $AK$2)), 0) + IF($AL$4 = AD$5, ($AL$3 * IF($AL14>0, $AL14, $AL$2)), 0) + IF($AM$4 = AD$5, ($AM$3 * IF($AM14>0, $AM14, $AM$2)), 0) + IF($AN$4 = AD$5, ($AN$3 * IF($AN14>0, $AN14, $AN$2)), 0) + IF($AO$4 = AD$5, ($AO$3 * IF($AO14>0, $AO14, $AO$2)), 0) + IF($AP$4 = AD$5, ($AP$3 * IF($AP14>0, $AP14, $AP$2)), 0) + IF($AQ$4 = AD$5, ($AQ$3 * IF($AQ14>0, $AQ14, $AQ$2)), 0) + IF($AR$4 = AD$5, ($AR$3 * IF($AR14>0, $AR14, $AR$2)), 0) + IF($AS$4 = AD$5, ($AS$3 * IF($AS14>0, $AS14, $AS$2)), 0) + IF($AT$4 = AD$5, ($AT$3 * IF($AT14>0, $AT14, $AT$2)), 0) + IF($AU$4 = AD$5, ($AU$3 * IF($AU14>0, $AU14, $AU$2)), 0) + IF($AV$4 = AD$5, ($AV$3 * IF($AV14>0, IF($AV14 > $AV$2, $AV$2, $AV14), $AV$2)), 0), -1) -> 197 | AE14: =IFERROR( IF($AF$4 = AE$5, ($AF$3 * IF($AF14>0, $AF14, $AF$2)), 0) + IF($AG$4 = AE$5, ($AG$3 * IF($AG14>0, $AG14, $AG$2)), 0) + IF($AH$4 = AE$5, ($AH$3 * IF($AH14>0, $AH14, $AH$2)), 0) + IF($AI$4 = AE$5, ($AI$3 * IF($AI14>0, $AI14, $AI$2)), 0) + IF($AJ$4 = AE$5, ($AJ$3 * IF($AJ14>0, $AJ14, $AJ$2)), 0) + IF($AK$4 = AE$5, ($AK$3 * IF($AK14>0, $AK14, $AK$2)), 0) + IF($AL$4 = AE$5, ($AL$3 * IF($AL14>0, $AL14, $AL$2)), 0) + IF($AM$4 = AE$5, ($AM$3 * IF($AM14>0, $AM14, $AM$2)), 0) + IF($AN$4 = AE$5, ($AN$3 * IF($AN14>0, $AN14, $AN$2)), 0) + IF($AO$4 = AE$5, ($AO$3 * IF($AO14>0, $AO14, $AO$2)), 0) + IF($AP$4 = AE$5, ($AP$3 * IF($AP14>0, $AP14, $AP$2)), 0) + IF($AQ$4 = AE$5, ($AQ$3 * IF($AQ14>0, $AQ14, $AQ$2)), 0) + IF($AR$4 = AE$5, ($AR$3 * IF($AR14>0, $AR14, $AR$2)), 0) + IF($AS$4 = AE$5, ($AS$3 * IF($AS14>0, $AS14, $AS$2)), 0) + IF($AT$4 = AE$5, ($AT$3 * IF($AT14>0, $AT14, $AT$2)), 0) + IF($AU$4 = AE$5, ($AU$3 * IF($AU14>0, $AU14, $AU$2)), 0) + IF($AV$4 = AE$5, ($AV$3 * IF($AV14>0, IF($AV14 > $AV$2, $AV$2, $AV14), $AV$2)), 0), -1) -> 218 | AF14: 16 | AG14: 5 | AH14: 7 | AI14: 8 | AJ14: 41 | AK14: 11 | AL14: 40 | AN14: 9 | AO14: 2 | AP14: 10 | AQ14: 3 | AR14: 16 | AS14: 13 | AT14: 4 | AU14: 17 | AV14: 93 | AW14: =IFERROR(INDEX(measureables!$A:$J,MATCH($A14,measureables!$A:$A,FALSE),7), "") -> 6' 8.00'' | AX14: =IFERROR(INDEX(measureables!$A:$J,MATCH($A14,measureables!$A:$A,FALSE),9), "") -> 217.4 | AY14: =IFERROR(INDEX(measureables!$A:$J,MATCH($A14,measureables!$A:$A,FALSE),10), "") -> 7' 2.00'' | AZ14: =IFERROR(INDEX(measureables!$A:$J,MATCH($A14,measureables!$A:$A,FALSE),8), "") -> 8' 11.50'' | BA14: =IF(R14="",A14, IF(S14=S13,"",IF(S14=1," <!-- rankings --> "," </ol> " ) & "<h2> Tier " &S14 &" (~" &IF(MOD(ROUND(Q14,0),5)=0,ROUND(Q14,0),FLOOR(ROUND(Q14,0),5)&"+") &" FV)</h2> <ol start='" &R14 &" '> " ) & " <li><b><a target='_blank' href='" &X14 &"'>" &A14 &"</a></b> - <i> <a target='_blank' href='" &W14 &"'>" &B14 &" </a></b> - <a target='_blank'href='" &V14 &"'>" &C14 &"</a></b> </i></li> <ul style='list-style-type:none'>" &IF(D14<>""," <li>Grade: "&D14&" </li>","") &IF(E14<>""," <li>Age: "&ROUND(E14,1)&" </li>","") &IF(F14<>""," <li>Height: "&F14&" in </li>","") &IF(G14<>""," <li>Weight: "&G14&" lbs </li>","") &IF(H14<>""," <li>Wingspan: "&H14&" in </li>","") &IF(I14<>""," <li>Reach: "&I14&" in </li>","") &IF(J14<>""," <li>Ape: "&J14&" </li>","") &IF(L14<>""," <li>++: "&L14&" </li>","") &IF(M14<>""," <li>+: "&M14&" </li>","") &IF(N14<>""," <li>-: "&N14&" </li>","") &IF(O14<>""," <li>--: "&O14&" </li>","") &IF(P14<>""," <li>Additional Notes: "&P14&" </li>","") &" </ul> <br>" &IF(AND(R14<>"",R15="")," </ol> <!-- # end of rankings --> ","") ) -> <li><b><a target='_blank' href='https://www.nba.com/draft/2022/prospects/tari-eason'>Tari Eason</a></b> - <i> <a target='_blank' href='https://www.nbadraft.net/players/tari-eason'>PF </a></b> - <a target='_blank'href='https://www.sports-reference.com/cbb/players/tari-eason-1.html'>LSU</a></b> </i></li> <ul style='list-style-type:none'> <li>Grade: Sophomore </li> <li>Age: 21.1 </li> <li>Height: 80 in </li> <li>Weight: 217.4 lbs </li> <li>Wingspan: 86 in </li> <li>Reach: 107.5 in </li> <li>Ape: +6 </li> <li>++: enegy, defense </li> <li>+: rim attacking </li> <li>-: wildness, fouling, shooting, age </li> <li>Additional Notes: high energy wing with a defense first mindset, but plays a little out of control and is older than the other wings in this tier </li> </ul> <br>
